Invalid HTTP_HOST header: 'sambegkhatiwada.com'. You may need to add 'sambegkhatiwada.com' to ALLOWED_HOSTS.
Traceback (most recent call last):
  File "/home3/sambegkhatiwada/virtualenv/Django-portfolio/webportfolio/3.12/lib/python3.12/site-packages/django/core/handlers/exception.py", line 55, in inner
    response = get_response(request)
               ^^^^^^^^^^^^^^^^^^^^^
  File "/home3/sambegkhatiwada/virtualenv/Django-portfolio/webportfolio/3.12/lib/python3.12/site-packages/django/utils/deprecation.py", line 119, in __call__
    response = self.process_request(request)
               ^^^^^^^^^^^^^^^^^^^^^^^^^^^^^
  File "/home3/sambegkhatiwada/virtualenv/Django-portfolio/webportfolio/3.12/lib/python3.12/site-packages/django/middleware/common.py", line 48, in process_request
    host = request.get_host()
           ^^^^^^^^^^^^^^^^^^
  File "/home3/sambegkhatiwada/virtualenv/Django-portfolio/webportfolio/3.12/lib/python3.12/site-packages/django/http/request.py", line 191, in get_host
    raise DisallowedHost(msg)
django.core.exceptions.DisallowedHost: Invalid HTTP_HOST header: 'sambegkhatiwada.com'. You may need to add 'sambegkhatiwada.com' to ALLOWED_HOSTS.
Bad Request: /
Invalid HTTP_HOST header: 'sambegkhatiwada.com'. You may need to add 'sambegkhatiwada.com' to ALLOWED_HOSTS.
Traceback (most recent call last):
  File "/home3/sambegkhatiwada/virtualenv/Django-portfolio/webportfolio/3.12/lib/python3.12/site-packages/django/core/handlers/exception.py", line 55, in inner
    response = get_response(request)
               ^^^^^^^^^^^^^^^^^^^^^
  File "/home3/sambegkhatiwada/virtualenv/Django-portfolio/webportfolio/3.12/lib/python3.12/site-packages/django/utils/deprecation.py", line 119, in __call__
    response = self.process_request(request)
               ^^^^^^^^^^^^^^^^^^^^^^^^^^^^^
  File "/home3/sambegkhatiwada/virtualenv/Django-portfolio/webportfolio/3.12/lib/python3.12/site-packages/django/middleware/common.py", line 48, in process_request
    host = request.get_host()
           ^^^^^^^^^^^^^^^^^^
  File "/home3/sambegkhatiwada/virtualenv/Django-portfolio/webportfolio/3.12/lib/python3.12/site-packages/django/http/request.py", line 191, in get_host
    raise DisallowedHost(msg)
django.core.exceptions.DisallowedHost: Invalid HTTP_HOST header: 'sambegkhatiwada.com'. You may need to add 'sambegkhatiwada.com' to ALLOWED_HOSTS.
Bad Request: /
Traceback (most recent call last):
  File "/home3/sambegkhatiwada/Django-portfolio/webportfolio/passenger_wsgi.py", line 11, in <module>
    from webportfolio.wsgi import application
  File "/home3/sambegkhatiwada/Django-portfolio/webportfolio/webportfolio/wsgi.py", line 16, in <module>
    application = get_wsgi_application()
                  ^^^^^^^^^^^^^^^^^^^^^^
  File "/home3/sambegkhatiwada/virtualenv/Django-portfolio/webportfolio/3.12/lib/python3.12/site-packages/django/core/wsgi.py", line 12, in get_wsgi_application
    django.setup(set_prefix=False)
  File "/home3/sambegkhatiwada/virtualenv/Django-portfolio/webportfolio/3.12/lib/python3.12/site-packages/django/__init__.py", line 19, in setup
    configure_logging(settings.LOGGING_CONFIG, settings.LOGGING)
                      ^^^^^^^^^^^^^^^^^^^^^^^
  File "/home3/sambegkhatiwada/virtualenv/Django-portfolio/webportfolio/3.12/lib/python3.12/site-packages/django/conf/__init__.py", line 81, in __getattr__
    self._setup(name)
  File "/home3/sambegkhatiwada/virtualenv/Django-portfolio/webportfolio/3.12/lib/python3.12/site-packages/django/conf/__init__.py", line 68, in _setup
    self._wrapped = Settings(settings_module)
                    ^^^^^^^^^^^^^^^^^^^^^^^^^
  File "/home3/sambegkhatiwada/virtualenv/Django-portfolio/webportfolio/3.12/lib/python3.12/site-packages/django/conf/__init__.py", line 166, in __init__
    mod = importlib.import_module(self.SETTINGS_MODULE)
          ^^^^^^^^^^^^^^^^^^^^^^^^^^^^^^^^^^^^^^^^^^^^^
  File "/opt/alt/python312/lib64/python3.12/importlib/__init__.py", line 90, in import_module
    return _bootstrap._gcd_import(name[level:], package, level)
           ^^^^^^^^^^^^^^^^^^^^^^^^^^^^^^^^^^^^^^^^^^^^^^^^^^^^
  File "/home3/sambegkhatiwada/Django-portfolio/webportfolio/webportfolio/settings.py", line 10
    ALLOWED_HOSTS = [*]
                      ^
SyntaxError: Invalid star expression
Traceback (most recent call last):
  File "/home3/sambegkhatiwada/Django-portfolio/webportfolio/passenger_wsgi.py", line 11, in <module>
    from webportfolio.wsgi import application
  File "/home3/sambegkhatiwada/Django-portfolio/webportfolio/webportfolio/wsgi.py", line 16, in <module>
    application = get_wsgi_application()
                  ^^^^^^^^^^^^^^^^^^^^^^
  File "/home3/sambegkhatiwada/virtualenv/Django-portfolio/webportfolio/3.12/lib/python3.12/site-packages/django/core/wsgi.py", line 12, in get_wsgi_application
    django.setup(set_prefix=False)
  File "/home3/sambegkhatiwada/virtualenv/Django-portfolio/webportfolio/3.12/lib/python3.12/site-packages/django/__init__.py", line 19, in setup
    configure_logging(settings.LOGGING_CONFIG, settings.LOGGING)
                      ^^^^^^^^^^^^^^^^^^^^^^^
  File "/home3/sambegkhatiwada/virtualenv/Django-portfolio/webportfolio/3.12/lib/python3.12/site-packages/django/conf/__init__.py", line 81, in __getattr__
    self._setup(name)
  File "/home3/sambegkhatiwada/virtualenv/Django-portfolio/webportfolio/3.12/lib/python3.12/site-packages/django/conf/__init__.py", line 68, in _setup
    self._wrapped = Settings(settings_module)
                    ^^^^^^^^^^^^^^^^^^^^^^^^^
  File "/home3/sambegkhatiwada/virtualenv/Django-portfolio/webportfolio/3.12/lib/python3.12/site-packages/django/conf/__init__.py", line 166, in __init__
    mod = importlib.import_module(self.SETTINGS_MODULE)
          ^^^^^^^^^^^^^^^^^^^^^^^^^^^^^^^^^^^^^^^^^^^^^
  File "/opt/alt/python312/lib64/python3.12/importlib/__init__.py", line 90, in import_module
    return _bootstrap._gcd_import(name[level:], package, level)
           ^^^^^^^^^^^^^^^^^^^^^^^^^^^^^^^^^^^^^^^^^^^^^^^^^^^^
  File "/home3/sambegkhatiwada/Django-portfolio/webportfolio/webportfolio/settings.py", line 10
    ALLOWED_HOSTS = [*]
                      ^
SyntaxError: Invalid star expression
[UID:1370][1004145] Child process with pid: 1004366 was killed by signal: 15, core dumped: no
Traceback (most recent call last):
  File "/home3/sambegkhatiwada/Django-portfolio/webportfolio/passenger_wsgi.py", line 11, in <module>
    from webportfolio.wsgi import application
  File "/home3/sambegkhatiwada/Django-portfolio/webportfolio/webportfolio/wsgi.py", line 16, in <module>
    application = get_wsgi_application()
                  ^^^^^^^^^^^^^^^^^^^^^^
  File "/home3/sambegkhatiwada/virtualenv/Django-portfolio/webportfolio/3.12/lib/python3.12/site-packages/django/core/wsgi.py", line 12, in get_wsgi_application
    django.setup(set_prefix=False)
  File "/home3/sambegkhatiwada/virtualenv/Django-portfolio/webportfolio/3.12/lib/python3.12/site-packages/django/__init__.py", line 19, in setup
    configure_logging(settings.LOGGING_CONFIG, settings.LOGGING)
                      ^^^^^^^^^^^^^^^^^^^^^^^
  File "/home3/sambegkhatiwada/virtualenv/Django-portfolio/webportfolio/3.12/lib/python3.12/site-packages/django/conf/__init__.py", line 81, in __getattr__
    self._setup(name)
  File "/home3/sambegkhatiwada/virtualenv/Django-portfolio/webportfolio/3.12/lib/python3.12/site-packages/django/conf/__init__.py", line 68, in _setup
    self._wrapped = Settings(settings_module)
                    ^^^^^^^^^^^^^^^^^^^^^^^^^
  File "/home3/sambegkhatiwada/virtualenv/Django-portfolio/webportfolio/3.12/lib/python3.12/site-packages/django/conf/__init__.py", line 166, in __init__
    mod = importlib.import_module(self.SETTINGS_MODULE)
          ^^^^^^^^^^^^^^^^^^^^^^^^^^^^^^^^^^^^^^^^^^^^^
  File "/opt/alt/python312/lib64/python3.12/importlib/__init__.py", line 90, in import_module
    return _bootstrap._gcd_import(name[level:], package, level)
           ^^^^^^^^^^^^^^^^^^^^^^^^^^^^^^^^^^^^^^^^^^^^^^^^^^^^
  File "/home3/sambegkhatiwada/Django-portfolio/webportfolio/webportfolio/settings.py", line 10
    ALLOWED_HOSTS = [*]
                      ^
SyntaxError: Invalid star expression
[UID:1370][1004145] Child process with pid: 1005394 was killed by signal: 15, core dumped: no
Not Found: /static/admin/css/base.css
Not Found: /static/admin/css/nav_sidebar.css
Not Found: /static/admin/js/theme.js
Not Found: /static/admin/css/login.css
Not Found: /static/admin/css/dark_mode.css
Not Found: /static/admin/css/responsive.css
Not Found: /static/admin/js/nav_sidebar.js
Not Found: /static/admin/css/login.css
Not Found: /static/admin/css/nav_sidebar.css
Not Found: /static/admin/css/responsive.css
Not Found: /static/admin/css/base.css
Not Found: /static/admin/css/nav_sidebar.css
Not Found: /static/admin/js/theme.js
Not Found: /static/admin/css/responsive.css
Not Found: /static/admin/css/dark_mode.css
Not Found: /static/admin/css/login.css
Not Found: /static/admin/js/nav_sidebar.js
Not Found: /static/admin/css/responsive.css
Not Found: /static/admin/css/nav_sidebar.css
Not Found: /static/admin/css/base.css
Not Found: /static/admin/css/responsive.css
Not Found: /static/admin/js/theme.js
Not Found: /static/admin/css/dark_mode.css
Not Found: /static/admin/css/nav_sidebar.css
Not Found: /static/admin/css/dashboard.css
Not Found: /static/admin/css/nav_sidebar.css
Not Found: /static/admin/css/dashboard.css
Not Found: /static/admin/css/responsive.css
Not Found: /static/admin/js/nav_sidebar.js
Not Found: /static/admin/css/base.css
Not Found: /static/admin/css/dark_mode.css
Not Found: /static/admin/css/nav_sidebar.css
Not Found: /static/admin/js/theme.js
Not Found: /static/admin/css/dashboard.css
Not Found: /static/admin/css/responsive.css
Not Found: /static/admin/css/nav_sidebar.css
Not Found: /static/admin/js/nav_sidebar.js
Not Found: /static/admin/css/base.css
Not Found: /static/admin/js/theme.js
Not Found: /static/admin/css/nav_sidebar.css
Not Found: /static/admin/css/dashboard.css
Not Found: /static/admin/css/responsive.css
Not Found: /static/admin/css/dark_mode.css
Not Found: /static/admin/css/nav_sidebar.css
Not Found: /static/admin/css/dashboard.css
Not Found: /static/admin/css/responsive.css
Not Found: /static/admin/js/nav_sidebar.js
Not Found: /static/admin/css/base.css
[UID:1370][1233644] Child process with pid: 1233981 was killed by signal: 15, core dumped: no
[ERROR] [UID:1370][1233980] wsgiAppHandler pApp->start_response() return NULL.
Traceback (most recent call last):
  File "/home3/sambegkhatiwada/virtualenv/Django-portfolio/webportfolio/3.12/lib/python3.12/site-packages/django/core/handlers/exception.py", line 55, in inner
    response = get_response(request)
               ^^^^^^^^^^^^^^^^^^^^^
  File "/home3/sambegkhatiwada/virtualenv/Django-portfolio/webportfolio/3.12/lib/python3.12/site-packages/django/core/handlers/base.py", line 181, in _get_response
    callback, callback_args, callback_kwargs = self.resolve_request(request)
                                               ^^^^^^^^^^^^^^^^^^^^^^^^^^^^^
  File "/home3/sambegkhatiwada/virtualenv/Django-portfolio/webportfolio/3.12/lib/python3.12/site-packages/django/core/handlers/base.py", line 313, in resolve_request
    resolver_match = resolver.resolve(request.path_info)
                     ^^^^^^^^^^^^^^^^^^^^^^^^^^^^^^^^^^^
  File "/home3/sambegkhatiwada/virtualenv/Django-portfolio/webportfolio/3.12/lib/python3.12/site-packages/django/urls/resolvers.py", line 666, in resolve
    for pattern in self.url_patterns:
                   ^^^^^^^^^^^^^^^^^
  File "/home3/sambegkhatiwada/virtualenv/Django-portfolio/webportfolio/3.12/lib/python3.12/site-packages/django/utils/functional.py", line 47, in __get__
    res = instance.__dict__[self.name] = self.func(instance)
                                         ^^^^^^^^^^^^^^^^^^^
  File "/home3/sambegkhatiwada/virtualenv/Django-portfolio/webportfolio/3.12/lib/python3.12/site-packages/django/urls/resolvers.py", line 718, in url_patterns
    patterns = getattr(self.urlconf_module, "urlpatterns", self.urlconf_module)
                       ^^^^^^^^^^^^^^^^^^^
  File "/home3/sambegkhatiwada/virtualenv/Django-portfolio/webportfolio/3.12/lib/python3.12/site-packages/django/utils/functional.py", line 47, in __get__
    res = instance.__dict__[self.name] = self.func(instance)
                                         ^^^^^^^^^^^^^^^^^^^
  File "/home3/sambegkhatiwada/virtualenv/Django-portfolio/webportfolio/3.12/lib/python3.12/site-packages/django/urls/resolvers.py", line 711, in urlconf_module
    return import_module(self.urlconf_name)
           ^^^^^^^^^^^^^^^^^^^^^^^^^^^^^^^^
  File "/opt/alt/python312/lib64/python3.12/importlib/__init__.py", line 90, in import_module
    return _bootstrap._gcd_import(name[level:], package, level)
           ^^^^^^^^^^^^^^^^^^^^^^^^^^^^^^^^^^^^^^^^^^^^^^^^^^^^
  File "<frozen importlib._bootstrap>", line 1387, in _gcd_import
  File "<frozen importlib._bootstrap>", line 1360, in _find_and_load
  File "<frozen importlib._bootstrap>", line 1331, in _find_and_load_unlocked
  File "<frozen importlib._bootstrap>", line 935, in _load_unlocked
  File "<frozen importlib._bootstrap_external>", line 999, in exec_module
  File "<frozen importlib._bootstrap>", line 488, in _call_with_frames_removed
  File "/home3/sambegkhatiwada/Django-portfolio/webportfolio/webportfolio/urls.py", line 5, in <module>
    urlpatterns += static(settings.MEDIA_URL, document_root=settings.MEDIA_ROOT)
    ^^^^^^^^^^^
NameError: name 'urlpatterns' is not defined

During handling of the above exception, another exception occurred:

Traceback (most recent call last):
  File "/home3/sambegkhatiwada/virtualenv/Django-portfolio/webportfolio/3.12/lib/python3.12/site-packages/django/core/handlers/exception.py", line 55, in inner
    response = get_response(request)
               ^^^^^^^^^^^^^^^^^^^^^
  File "/home3/sambegkhatiwada/virtualenv/Django-portfolio/webportfolio/3.12/lib/python3.12/site-packages/django/utils/deprecation.py", line 120, in __call__
    response = response or self.get_response(request)
                           ^^^^^^^^^^^^^^^^^^^^^^^^^^
  File "/home3/sambegkhatiwada/virtualenv/Django-portfolio/webportfolio/3.12/lib/python3.12/site-packages/django/core/handlers/exception.py", line 57, in inner
    response = response_for_exception(request, exc)
               ^^^^^^^^^^^^^^^^^^^^^^^^^^^^^^^^^^^^
  File "/home3/sambegkhatiwada/virtualenv/Django-portfolio/webportfolio/3.12/lib/python3.12/site-packages/django/core/handlers/exception.py", line 140, in response_for_exception
    response = handle_uncaught_exception(
               ^^^^^^^^^^^^^^^^^^^^^^^^^^
  File "/home3/sambegkhatiwada/virtualenv/Django-portfolio/webportfolio/3.12/lib/python3.12/site-packages/django/core/handlers/exception.py", line 181, in handle_uncaught_exception
    return debug.technical_500_response(request, *exc_info)
           ^^^^^^^^^^^^^^^^^^^^^^^^^^^^^^^^^^^^^^^^^^^^^^^^
  File "/home3/sambegkhatiwada/virtualenv/Django-portfolio/webportfolio/3.12/lib/python3.12/site-packages/django/views/debug.py", line 69, in technical_500_response
    html = reporter.get_traceback_html()
           ^^^^^^^^^^^^^^^^^^^^^^^^^^^^^
  File "/home3/sambegkhatiwada/virtualenv/Django-portfolio/webportfolio/3.12/lib/python3.12/site-packages/django/views/debug.py", line 428, in get_traceback_html
    c = Context(self.get_traceback_data(), use_l10n=False)
                ^^^^^^^^^^^^^^^^^^^^^^^^^
  File "/home3/sambegkhatiwada/virtualenv/Django-portfolio/webportfolio/3.12/lib/python3.12/site-packages/django/views/debug.py", line 411, in get_traceback_data
    c["raising_view_name"] = get_caller(self.request)
                             ^^^^^^^^^^^^^^^^^^^^^^^^
  File "/home3/sambegkhatiwada/virtualenv/Django-portfolio/webportfolio/3.12/lib/python3.12/site-packages/django/views/debug.py", line 102, in get_caller
    resolver_match = resolve(request.path)
                     ^^^^^^^^^^^^^^^^^^^^^
  File "/home3/sambegkhatiwada/virtualenv/Django-portfolio/webportfolio/3.12/lib/python3.12/site-packages/django/urls/base.py", line 25, in resolve
    return get_resolver(urlconf).resolve(path)
           ^^^^^^^^^^^^^^^^^^^^^^^^^^^^^^^^^^^
  File "/home3/sambegkhatiwada/virtualenv/Django-portfolio/webportfolio/3.12/lib/python3.12/site-packages/django/urls/resolvers.py", line 666, in resolve
    for pattern in self.url_patterns:
                   ^^^^^^^^^^^^^^^^^
  File "/home3/sambegkhatiwada/virtualenv/Django-portfolio/webportfolio/3.12/lib/python3.12/site-packages/django/utils/functional.py", line 47, in __get__
    res = instance.__dict__[self.name] = self.func(instance)
                                         ^^^^^^^^^^^^^^^^^^^
  File "/home3/sambegkhatiwada/virtualenv/Django-portfolio/webportfolio/3.12/lib/python3.12/site-packages/django/urls/resolvers.py", line 718, in url_patterns
    patterns = getattr(self.urlconf_module, "urlpatterns", self.urlconf_module)
                       ^^^^^^^^^^^^^^^^^^^
  File "/home3/sambegkhatiwada/virtualenv/Django-portfolio/webportfolio/3.12/lib/python3.12/site-packages/django/utils/functional.py", line 47, in __get__
    res = instance.__dict__[self.name] = self.func(instance)
                                         ^^^^^^^^^^^^^^^^^^^
  File "/home3/sambegkhatiwada/virtualenv/Django-portfolio/webportfolio/3.12/lib/python3.12/site-packages/django/urls/resolvers.py", line 711, in urlconf_module
    return import_module(self.urlconf_name)
           ^^^^^^^^^^^^^^^^^^^^^^^^^^^^^^^^
  File "/opt/alt/python312/lib64/python3.12/importlib/__init__.py", line 90, in import_module
    return _bootstrap._gcd_import(name[level:], package, level)
           ^^^^^^^^^^^^^^^^^^^^^^^^^^^^^^^^^^^^^^^^^^^^^^^^^^^^
  File "<frozen importlib._bootstrap>", line 1387, in _gcd_import
  File "<frozen importlib._bootstrap>", line 1360, in _find_and_load
  File "<frozen importlib._bootstrap>", line 1331, in _find_and_load_unlocked
  File "<frozen importlib._bootstrap>", line 935, in _load_unlocked
  File "<frozen importlib._bootstrap_external>", line 999, in exec_module
  File "<frozen importlib._bootstrap>", line 488, in _call_with_frames_removed
  File "/home3/sambegkhatiwada/Django-portfolio/webportfolio/webportfolio/urls.py", line 5, in <module>
    urlpatterns += static(settings.MEDIA_URL, document_root=settings.MEDIA_ROOT)
    ^^^^^^^^^^^
NameError: name 'urlpatterns' is not defined

During handling of the above exception, another exception occurred:

Traceback (most recent call last):
  File "/home3/sambegkhatiwada/virtualenv/Django-portfolio/webportfolio/3.12/lib/python3.12/site-packages/django/core/handlers/exception.py", line 55, in inner
    response = get_response(request)
               ^^^^^^^^^^^^^^^^^^^^^
  File "/home3/sambegkhatiwada/virtualenv/Django-portfolio/webportfolio/3.12/lib/python3.12/site-packages/django/utils/deprecation.py", line 120, in __call__
    response = response or self.get_response(request)
                           ^^^^^^^^^^^^^^^^^^^^^^^^^^
  File "/home3/sambegkhatiwada/virtualenv/Django-portfolio/webportfolio/3.12/lib/python3.12/site-packages/django/core/handlers/exception.py", line 57, in inner
    response = response_for_exception(request, exc)
               ^^^^^^^^^^^^^^^^^^^^^^^^^^^^^^^^^^^^
  File "/home3/sambegkhatiwada/virtualenv/Django-portfolio/webportfolio/3.12/lib/python3.12/site-packages/django/core/handlers/exception.py", line 140, in response_for_exception
    response = handle_uncaught_exception(
               ^^^^^^^^^^^^^^^^^^^^^^^^^^
  File "/home3/sambegkhatiwada/virtualenv/Django-portfolio/webportfolio/3.12/lib/python3.12/site-packages/django/core/handlers/exception.py", line 181, in handle_uncaught_exception
    return debug.technical_500_response(request, *exc_info)
           ^^^^^^^^^^^^^^^^^^^^^^^^^^^^^^^^^^^^^^^^^^^^^^^^
  File "/home3/sambegkhatiwada/virtualenv/Django-portfolio/webportfolio/3.12/lib/python3.12/site-packages/django/views/debug.py", line 69, in technical_500_response
    html = reporter.get_traceback_html()
           ^^^^^^^^^^^^^^^^^^^^^^^^^^^^^
  File "/home3/sambegkhatiwada/virtualenv/Django-portfolio/webportfolio/3.12/lib/python3.12/site-packages/django/views/debug.py", line 428, in get_traceback_html
    c = Context(self.get_traceback_data(), use_l10n=False)
                ^^^^^^^^^^^^^^^^^^^^^^^^^
  File "/home3/sambegkhatiwada/virtualenv/Django-portfolio/webportfolio/3.12/lib/python3.12/site-packages/django/views/debug.py", line 411, in get_traceback_data
    c["raising_view_name"] = get_caller(self.request)
                             ^^^^^^^^^^^^^^^^^^^^^^^^
  File "/home3/sambegkhatiwada/virtualenv/Django-portfolio/webportfolio/3.12/lib/python3.12/site-packages/django/views/debug.py", line 102, in get_caller
    resolver_match = resolve(request.path)
                     ^^^^^^^^^^^^^^^^^^^^^
  File "/home3/sambegkhatiwada/virtualenv/Django-portfolio/webportfolio/3.12/lib/python3.12/site-packages/django/urls/base.py", line 25, in resolve
    return get_resolver(urlconf).resolve(path)
           ^^^^^^^^^^^^^^^^^^^^^^^^^^^^^^^^^^^
  File "/home3/sambegkhatiwada/virtualenv/Django-portfolio/webportfolio/3.12/lib/python3.12/site-packages/django/urls/resolvers.py", line 666, in resolve
    for pattern in self.url_patterns:
                   ^^^^^^^^^^^^^^^^^
  File "/home3/sambegkhatiwada/virtualenv/Django-portfolio/webportfolio/3.12/lib/python3.12/site-packages/django/utils/functional.py", line 47, in __get__
    res = instance.__dict__[self.name] = self.func(instance)
                                         ^^^^^^^^^^^^^^^^^^^
  File "/home3/sambegkhatiwada/virtualenv/Django-portfolio/webportfolio/3.12/lib/python3.12/site-packages/django/urls/resolvers.py", line 718, in url_patterns
    patterns = getattr(self.urlconf_module, "urlpatterns", self.urlconf_module)
                       ^^^^^^^^^^^^^^^^^^^
  File "/home3/sambegkhatiwada/virtualenv/Django-portfolio/webportfolio/3.12/lib/python3.12/site-packages/django/utils/functional.py", line 47, in __get__
    res = instance.__dict__[self.name] = self.func(instance)
                                         ^^^^^^^^^^^^^^^^^^^
  File "/home3/sambegkhatiwada/virtualenv/Django-portfolio/webportfolio/3.12/lib/python3.12/site-packages/django/urls/resolvers.py", line 711, in urlconf_module
    return import_module(self.urlconf_name)
           ^^^^^^^^^^^^^^^^^^^^^^^^^^^^^^^^
  File "/opt/alt/python312/lib64/python3.12/importlib/__init__.py", line 90, in import_module
    return _bootstrap._gcd_import(name[level:], package, level)
           ^^^^^^^^^^^^^^^^^^^^^^^^^^^^^^^^^^^^^^^^^^^^^^^^^^^^
  File "<frozen importlib._bootstrap>", line 1387, in _gcd_import
  File "<frozen importlib._bootstrap>", line 1360, in _find_and_load
  File "<frozen importlib._bootstrap>", line 1331, in _find_and_load_unlocked
  File "<frozen importlib._bootstrap>", line 935, in _load_unlocked
  File "<frozen importlib._bootstrap_external>", line 999, in exec_module
  File "<frozen importlib._bootstrap>", line 488, in _call_with_frames_removed
  File "/home3/sambegkhatiwada/Django-portfolio/webportfolio/webportfolio/urls.py", line 5, in <module>
    urlpatterns += static(settings.MEDIA_URL, document_root=settings.MEDIA_ROOT)
    ^^^^^^^^^^^
NameError: name 'urlpatterns' is not defined

During handling of the above exception, another exception occurred:

Traceback (most recent call last):
  File "/home3/sambegkhatiwada/virtualenv/Django-portfolio/webportfolio/3.12/lib/python3.12/site-packages/django/core/handlers/exception.py", line 55, in inner
    response = get_response(request)
               ^^^^^^^^^^^^^^^^^^^^^
  File "/home3/sambegkhatiwada/virtualenv/Django-portfolio/webportfolio/3.12/lib/python3.12/site-packages/django/utils/deprecation.py", line 120, in __call__
    response = response or self.get_response(request)
                           ^^^^^^^^^^^^^^^^^^^^^^^^^^
  File "/home3/sambegkhatiwada/virtualenv/Django-portfolio/webportfolio/3.12/lib/python3.12/site-packages/django/core/handlers/exception.py", line 57, in inner
    response = response_for_exception(request, exc)
               ^^^^^^^^^^^^^^^^^^^^^^^^^^^^^^^^^^^^
  File "/home3/sambegkhatiwada/virtualenv/Django-portfolio/webportfolio/3.12/lib/python3.12/site-packages/django/core/handlers/exception.py", line 140, in response_for_exception
    response = handle_uncaught_exception(
               ^^^^^^^^^^^^^^^^^^^^^^^^^^
  File "/home3/sambegkhatiwada/virtualenv/Django-portfolio/webportfolio/3.12/lib/python3.12/site-packages/django/core/handlers/exception.py", line 181, in handle_uncaught_exception
    return debug.technical_500_response(request, *exc_info)
           ^^^^^^^^^^^^^^^^^^^^^^^^^^^^^^^^^^^^^^^^^^^^^^^^
  File "/home3/sambegkhatiwada/virtualenv/Django-portfolio/webportfolio/3.12/lib/python3.12/site-packages/django/views/debug.py", line 69, in technical_500_response
    html = reporter.get_traceback_html()
           ^^^^^^^^^^^^^^^^^^^^^^^^^^^^^
  File "/home3/sambegkhatiwada/virtualenv/Django-portfolio/webportfolio/3.12/lib/python3.12/site-packages/django/views/debug.py", line 428, in get_traceback_html
    c = Context(self.get_traceback_data(), use_l10n=False)
                ^^^^^^^^^^^^^^^^^^^^^^^^^
  File "/home3/sambegkhatiwada/virtualenv/Django-portfolio/webportfolio/3.12/lib/python3.12/site-packages/django/views/debug.py", line 411, in get_traceback_data
    c["raising_view_name"] = get_caller(self.request)
                             ^^^^^^^^^^^^^^^^^^^^^^^^
  File "/home3/sambegkhatiwada/virtualenv/Django-portfolio/webportfolio/3.12/lib/python3.12/site-packages/django/views/debug.py", line 102, in get_caller
    resolver_match = resolve(request.path)
                     ^^^^^^^^^^^^^^^^^^^^^
  File "/home3/sambegkhatiwada/virtualenv/Django-portfolio/webportfolio/3.12/lib/python3.12/site-packages/django/urls/base.py", line 25, in resolve
    return get_resolver(urlconf).resolve(path)
           ^^^^^^^^^^^^^^^^^^^^^^^^^^^^^^^^^^^
  File "/home3/sambegkhatiwada/virtualenv/Django-portfolio/webportfolio/3.12/lib/python3.12/site-packages/django/urls/resolvers.py", line 666, in resolve
    for pattern in self.url_patterns:
                   ^^^^^^^^^^^^^^^^^
  File "/home3/sambegkhatiwada/virtualenv/Django-portfolio/webportfolio/3.12/lib/python3.12/site-packages/django/utils/functional.py", line 47, in __get__
    res = instance.__dict__[self.name] = self.func(instance)
                                         ^^^^^^^^^^^^^^^^^^^
  File "/home3/sambegkhatiwada/virtualenv/Django-portfolio/webportfolio/3.12/lib/python3.12/site-packages/django/urls/resolvers.py", line 718, in url_patterns
    patterns = getattr(self.urlconf_module, "urlpatterns", self.urlconf_module)
                       ^^^^^^^^^^^^^^^^^^^
  File "/home3/sambegkhatiwada/virtualenv/Django-portfolio/webportfolio/3.12/lib/python3.12/site-packages/django/utils/functional.py", line 47, in __get__
    res = instance.__dict__[self.name] = self.func(instance)
                                         ^^^^^^^^^^^^^^^^^^^
  File "/home3/sambegkhatiwada/virtualenv/Django-portfolio/webportfolio/3.12/lib/python3.12/site-packages/django/urls/resolvers.py", line 711, in urlconf_module
    return import_module(self.urlconf_name)
           ^^^^^^^^^^^^^^^^^^^^^^^^^^^^^^^^
  File "/opt/alt/python312/lib64/python3.12/importlib/__init__.py", line 90, in import_module
    return _bootstrap._gcd_import(name[level:], package, level)
           ^^^^^^^^^^^^^^^^^^^^^^^^^^^^^^^^^^^^^^^^^^^^^^^^^^^^
  File "<frozen importlib._bootstrap>", line 1387, in _gcd_import
  File "<frozen importlib._bootstrap>", line 1360, in _find_and_load
  File "<frozen importlib._bootstrap>", line 1331, in _find_and_load_unlocked
  File "<frozen importlib._bootstrap>", line 935, in _load_unlocked
  File "<frozen importlib._bootstrap_external>", line 999, in exec_module
  File "<frozen importlib._bootstrap>", line 488, in _call_with_frames_removed
  File "/home3/sambegkhatiwada/Django-portfolio/webportfolio/webportfolio/urls.py", line 5, in <module>
    urlpatterns += static(settings.MEDIA_URL, document_root=settings.MEDIA_ROOT)
    ^^^^^^^^^^^
NameError: name 'urlpatterns' is not defined

During handling of the above exception, another exception occurred:

Traceback (most recent call last):
  File "/home3/sambegkhatiwada/virtualenv/Django-portfolio/webportfolio/3.12/lib/python3.12/site-packages/django/core/handlers/exception.py", line 55, in inner
    response = get_response(request)
               ^^^^^^^^^^^^^^^^^^^^^
  File "/home3/sambegkhatiwada/virtualenv/Django-portfolio/webportfolio/3.12/lib/python3.12/site-packages/django/utils/deprecation.py", line 120, in __call__
    response = response or self.get_response(request)
                           ^^^^^^^^^^^^^^^^^^^^^^^^^^
  File "/home3/sambegkhatiwada/virtualenv/Django-portfolio/webportfolio/3.12/lib/python3.12/site-packages/django/core/handlers/exception.py", line 57, in inner
    response = response_for_exception(request, exc)
               ^^^^^^^^^^^^^^^^^^^^^^^^^^^^^^^^^^^^
  File "/home3/sambegkhatiwada/virtualenv/Django-portfolio/webportfolio/3.12/lib/python3.12/site-packages/django/core/handlers/exception.py", line 140, in response_for_exception
    response = handle_uncaught_exception(
               ^^^^^^^^^^^^^^^^^^^^^^^^^^
  File "/home3/sambegkhatiwada/virtualenv/Django-portfolio/webportfolio/3.12/lib/python3.12/site-packages/django/core/handlers/exception.py", line 181, in handle_uncaught_exception
    return debug.technical_500_response(request, *exc_info)
           ^^^^^^^^^^^^^^^^^^^^^^^^^^^^^^^^^^^^^^^^^^^^^^^^
  File "/home3/sambegkhatiwada/virtualenv/Django-portfolio/webportfolio/3.12/lib/python3.12/site-packages/django/views/debug.py", line 69, in technical_500_response
    html = reporter.get_traceback_html()
           ^^^^^^^^^^^^^^^^^^^^^^^^^^^^^
  File "/home3/sambegkhatiwada/virtualenv/Django-portfolio/webportfolio/3.12/lib/python3.12/site-packages/django/views/debug.py", line 428, in get_traceback_html
    c = Context(self.get_traceback_data(), use_l10n=False)
                ^^^^^^^^^^^^^^^^^^^^^^^^^
  File "/home3/sambegkhatiwada/virtualenv/Django-portfolio/webportfolio/3.12/lib/python3.12/site-packages/django/views/debug.py", line 411, in get_traceback_data
    c["raising_view_name"] = get_caller(self.request)
                             ^^^^^^^^^^^^^^^^^^^^^^^^
  File "/home3/sambegkhatiwada/virtualenv/Django-portfolio/webportfolio/3.12/lib/python3.12/site-packages/django/views/debug.py", line 102, in get_caller
    resolver_match = resolve(request.path)
                     ^^^^^^^^^^^^^^^^^^^^^
  File "/home3/sambegkhatiwada/virtualenv/Django-portfolio/webportfolio/3.12/lib/python3.12/site-packages/django/urls/base.py", line 25, in resolve
    return get_resolver(urlconf).resolve(path)
           ^^^^^^^^^^^^^^^^^^^^^^^^^^^^^^^^^^^
  File "/home3/sambegkhatiwada/virtualenv/Django-portfolio/webportfolio/3.12/lib/python3.12/site-packages/django/urls/resolvers.py", line 666, in resolve
    for pattern in self.url_patterns:
                   ^^^^^^^^^^^^^^^^^
  File "/home3/sambegkhatiwada/virtualenv/Django-portfolio/webportfolio/3.12/lib/python3.12/site-packages/django/utils/functional.py", line 47, in __get__
    res = instance.__dict__[self.name] = self.func(instance)
                                         ^^^^^^^^^^^^^^^^^^^
  File "/home3/sambegkhatiwada/virtualenv/Django-portfolio/webportfolio/3.12/lib/python3.12/site-packages/django/urls/resolvers.py", line 718, in url_patterns
    patterns = getattr(self.urlconf_module, "urlpatterns", self.urlconf_module)
                       ^^^^^^^^^^^^^^^^^^^
  File "/home3/sambegkhatiwada/virtualenv/Django-portfolio/webportfolio/3.12/lib/python3.12/site-packages/django/utils/functional.py", line 47, in __get__
    res = instance.__dict__[self.name] = self.func(instance)
                                         ^^^^^^^^^^^^^^^^^^^
  File "/home3/sambegkhatiwada/virtualenv/Django-portfolio/webportfolio/3.12/lib/python3.12/site-packages/django/urls/resolvers.py", line 711, in urlconf_module
    return import_module(self.urlconf_name)
           ^^^^^^^^^^^^^^^^^^^^^^^^^^^^^^^^
  File "/opt/alt/python312/lib64/python3.12/importlib/__init__.py", line 90, in import_module
    return _bootstrap._gcd_import(name[level:], package, level)
           ^^^^^^^^^^^^^^^^^^^^^^^^^^^^^^^^^^^^^^^^^^^^^^^^^^^^
  File "<frozen importlib._bootstrap>", line 1387, in _gcd_import
  File "<frozen importlib._bootstrap>", line 1360, in _find_and_load
  File "<frozen importlib._bootstrap>", line 1331, in _find_and_load_unlocked
  File "<frozen importlib._bootstrap>", line 935, in _load_unlocked
  File "<frozen importlib._bootstrap_external>", line 999, in exec_module
  File "<frozen importlib._bootstrap>", line 488, in _call_with_frames_removed
  File "/home3/sambegkhatiwada/Django-portfolio/webportfolio/webportfolio/urls.py", line 5, in <module>
    urlpatterns += static(settings.MEDIA_URL, document_root=settings.MEDIA_ROOT)
    ^^^^^^^^^^^
NameError: name 'urlpatterns' is not defined

During handling of the above exception, another exception occurred:

Traceback (most recent call last):
  File "/home3/sambegkhatiwada/virtualenv/Django-portfolio/webportfolio/3.12/lib/python3.12/site-packages/django/core/handlers/exception.py", line 55, in inner
    response = get_response(request)
               ^^^^^^^^^^^^^^^^^^^^^
  File "/home3/sambegkhatiwada/virtualenv/Django-portfolio/webportfolio/3.12/lib/python3.12/site-packages/django/utils/deprecation.py", line 120, in __call__
    response = response or self.get_response(request)
                           ^^^^^^^^^^^^^^^^^^^^^^^^^^
  File "/home3/sambegkhatiwada/virtualenv/Django-portfolio/webportfolio/3.12/lib/python3.12/site-packages/django/core/handlers/exception.py", line 57, in inner
    response = response_for_exception(request, exc)
               ^^^^^^^^^^^^^^^^^^^^^^^^^^^^^^^^^^^^
  File "/home3/sambegkhatiwada/virtualenv/Django-portfolio/webportfolio/3.12/lib/python3.12/site-packages/django/core/handlers/exception.py", line 140, in response_for_exception
    response = handle_uncaught_exception(
               ^^^^^^^^^^^^^^^^^^^^^^^^^^
  File "/home3/sambegkhatiwada/virtualenv/Django-portfolio/webportfolio/3.12/lib/python3.12/site-packages/django/core/handlers/exception.py", line 181, in handle_uncaught_exception
    return debug.technical_500_response(request, *exc_info)
           ^^^^^^^^^^^^^^^^^^^^^^^^^^^^^^^^^^^^^^^^^^^^^^^^
  File "/home3/sambegkhatiwada/virtualenv/Django-portfolio/webportfolio/3.12/lib/python3.12/site-packages/django/views/debug.py", line 69, in technical_500_response
    html = reporter.get_traceback_html()
           ^^^^^^^^^^^^^^^^^^^^^^^^^^^^^
  File "/home3/sambegkhatiwada/virtualenv/Django-portfolio/webportfolio/3.12/lib/python3.12/site-packages/django/views/debug.py", line 428, in get_traceback_html
    c = Context(self.get_traceback_data(), use_l10n=False)
                ^^^^^^^^^^^^^^^^^^^^^^^^^
  File "/home3/sambegkhatiwada/virtualenv/Django-portfolio/webportfolio/3.12/lib/python3.12/site-packages/django/views/debug.py", line 411, in get_traceback_data
    c["raising_view_name"] = get_caller(self.request)
                             ^^^^^^^^^^^^^^^^^^^^^^^^
  File "/home3/sambegkhatiwada/virtualenv/Django-portfolio/webportfolio/3.12/lib/python3.12/site-packages/django/views/debug.py", line 102, in get_caller
    resolver_match = resolve(request.path)
                     ^^^^^^^^^^^^^^^^^^^^^
  File "/home3/sambegkhatiwada/virtualenv/Django-portfolio/webportfolio/3.12/lib/python3.12/site-packages/django/urls/base.py", line 25, in resolve
    return get_resolver(urlconf).resolve(path)
           ^^^^^^^^^^^^^^^^^^^^^^^^^^^^^^^^^^^
  File "/home3/sambegkhatiwada/virtualenv/Django-portfolio/webportfolio/3.12/lib/python3.12/site-packages/django/urls/resolvers.py", line 666, in resolve
    for pattern in self.url_patterns:
                   ^^^^^^^^^^^^^^^^^
  File "/home3/sambegkhatiwada/virtualenv/Django-portfolio/webportfolio/3.12/lib/python3.12/site-packages/django/utils/functional.py", line 47, in __get__
    res = instance.__dict__[self.name] = self.func(instance)
                                         ^^^^^^^^^^^^^^^^^^^
  File "/home3/sambegkhatiwada/virtualenv/Django-portfolio/webportfolio/3.12/lib/python3.12/site-packages/django/urls/resolvers.py", line 718, in url_patterns
    patterns = getattr(self.urlconf_module, "urlpatterns", self.urlconf_module)
                       ^^^^^^^^^^^^^^^^^^^
  File "/home3/sambegkhatiwada/virtualenv/Django-portfolio/webportfolio/3.12/lib/python3.12/site-packages/django/utils/functional.py", line 47, in __get__
    res = instance.__dict__[self.name] = self.func(instance)
                                         ^^^^^^^^^^^^^^^^^^^
  File "/home3/sambegkhatiwada/virtualenv/Django-portfolio/webportfolio/3.12/lib/python3.12/site-packages/django/urls/resolvers.py", line 711, in urlconf_module
    return import_module(self.urlconf_name)
           ^^^^^^^^^^^^^^^^^^^^^^^^^^^^^^^^
  File "/opt/alt/python312/lib64/python3.12/importlib/__init__.py", line 90, in import_module
    return _bootstrap._gcd_import(name[level:], package, level)
           ^^^^^^^^^^^^^^^^^^^^^^^^^^^^^^^^^^^^^^^^^^^^^^^^^^^^
  File "<frozen importlib._bootstrap>", line 1387, in _gcd_import
  File "<frozen importlib._bootstrap>", line 1360, in _find_and_load
  File "<frozen importlib._bootstrap>", line 1331, in _find_and_load_unlocked
  File "<frozen importlib._bootstrap>", line 935, in _load_unlocked
  File "<frozen importlib._bootstrap_external>", line 999, in exec_module
  File "<frozen importlib._bootstrap>", line 488, in _call_with_frames_removed
  File "/home3/sambegkhatiwada/Django-portfolio/webportfolio/webportfolio/urls.py", line 5, in <module>
    urlpatterns += static(settings.MEDIA_URL, document_root=settings.MEDIA_ROOT)
    ^^^^^^^^^^^
NameError: name 'urlpatterns' is not defined

During handling of the above exception, another exception occurred:

Traceback (most recent call last):
  File "/home3/sambegkhatiwada/virtualenv/Django-portfolio/webportfolio/3.12/lib/python3.12/site-packages/django/core/handlers/exception.py", line 55, in inner
    response = get_response(request)
               ^^^^^^^^^^^^^^^^^^^^^
  File "/home3/sambegkhatiwada/virtualenv/Django-portfolio/webportfolio/3.12/lib/python3.12/site-packages/django/utils/deprecation.py", line 120, in __call__
    response = response or self.get_response(request)
                           ^^^^^^^^^^^^^^^^^^^^^^^^^^
  File "/home3/sambegkhatiwada/virtualenv/Django-portfolio/webportfolio/3.12/lib/python3.12/site-packages/django/core/handlers/exception.py", line 57, in inner
    response = response_for_exception(request, exc)
               ^^^^^^^^^^^^^^^^^^^^^^^^^^^^^^^^^^^^
  File "/home3/sambegkhatiwada/virtualenv/Django-portfolio/webportfolio/3.12/lib/python3.12/site-packages/django/core/handlers/exception.py", line 140, in response_for_exception
    response = handle_uncaught_exception(
               ^^^^^^^^^^^^^^^^^^^^^^^^^^
  File "/home3/sambegkhatiwada/virtualenv/Django-portfolio/webportfolio/3.12/lib/python3.12/site-packages/django/core/handlers/exception.py", line 181, in handle_uncaught_exception
    return debug.technical_500_response(request, *exc_info)
           ^^^^^^^^^^^^^^^^^^^^^^^^^^^^^^^^^^^^^^^^^^^^^^^^
  File "/home3/sambegkhatiwada/virtualenv/Django-portfolio/webportfolio/3.12/lib/python3.12/site-packages/django/views/debug.py", line 69, in technical_500_response
    html = reporter.get_traceback_html()
           ^^^^^^^^^^^^^^^^^^^^^^^^^^^^^
  File "/home3/sambegkhatiwada/virtualenv/Django-portfolio/webportfolio/3.12/lib/python3.12/site-packages/django/views/debug.py", line 428, in get_traceback_html
    c = Context(self.get_traceback_data(), use_l10n=False)
                ^^^^^^^^^^^^^^^^^^^^^^^^^
  File "/home3/sambegkhatiwada/virtualenv/Django-portfolio/webportfolio/3.12/lib/python3.12/site-packages/django/views/debug.py", line 411, in get_traceback_data
    c["raising_view_name"] = get_caller(self.request)
                             ^^^^^^^^^^^^^^^^^^^^^^^^
  File "/home3/sambegkhatiwada/virtualenv/Django-portfolio/webportfolio/3.12/lib/python3.12/site-packages/django/views/debug.py", line 102, in get_caller
    resolver_match = resolve(request.path)
                     ^^^^^^^^^^^^^^^^^^^^^
  File "/home3/sambegkhatiwada/virtualenv/Django-portfolio/webportfolio/3.12/lib/python3.12/site-packages/django/urls/base.py", line 25, in resolve
    return get_resolver(urlconf).resolve(path)
           ^^^^^^^^^^^^^^^^^^^^^^^^^^^^^^^^^^^
  File "/home3/sambegkhatiwada/virtualenv/Django-portfolio/webportfolio/3.12/lib/python3.12/site-packages/django/urls/resolvers.py", line 666, in resolve
    for pattern in self.url_patterns:
                   ^^^^^^^^^^^^^^^^^
  File "/home3/sambegkhatiwada/virtualenv/Django-portfolio/webportfolio/3.12/lib/python3.12/site-packages/django/utils/functional.py", line 47, in __get__
    res = instance.__dict__[self.name] = self.func(instance)
                                         ^^^^^^^^^^^^^^^^^^^
  File "/home3/sambegkhatiwada/virtualenv/Django-portfolio/webportfolio/3.12/lib/python3.12/site-packages/django/urls/resolvers.py", line 718, in url_patterns
    patterns = getattr(self.urlconf_module, "urlpatterns", self.urlconf_module)
                       ^^^^^^^^^^^^^^^^^^^
  File "/home3/sambegkhatiwada/virtualenv/Django-portfolio/webportfolio/3.12/lib/python3.12/site-packages/django/utils/functional.py", line 47, in __get__
    res = instance.__dict__[self.name] = self.func(instance)
                                         ^^^^^^^^^^^^^^^^^^^
  File "/home3/sambegkhatiwada/virtualenv/Django-portfolio/webportfolio/3.12/lib/python3.12/site-packages/django/urls/resolvers.py", line 711, in urlconf_module
    return import_module(self.urlconf_name)
           ^^^^^^^^^^^^^^^^^^^^^^^^^^^^^^^^
  File "/opt/alt/python312/lib64/python3.12/importlib/__init__.py", line 90, in import_module
    return _bootstrap._gcd_import(name[level:], package, level)
           ^^^^^^^^^^^^^^^^^^^^^^^^^^^^^^^^^^^^^^^^^^^^^^^^^^^^
  File "<frozen importlib._bootstrap>", line 1387, in _gcd_import
  File "<frozen importlib._bootstrap>", line 1360, in _find_and_load
  File "<frozen importlib._bootstrap>", line 1331, in _find_and_load_unlocked
  File "<frozen importlib._bootstrap>", line 935, in _load_unlocked
  File "<frozen importlib._bootstrap_external>", line 999, in exec_module
  File "<frozen importlib._bootstrap>", line 488, in _call_with_frames_removed
  File "/home3/sambegkhatiwada/Django-portfolio/webportfolio/webportfolio/urls.py", line 5, in <module>
    urlpatterns += static(settings.MEDIA_URL, document_root=settings.MEDIA_ROOT)
    ^^^^^^^^^^^
NameError: name 'urlpatterns' is not defined

During handling of the above exception, another exception occurred:

Traceback (most recent call last):
  File "/home3/sambegkhatiwada/virtualenv/Django-portfolio/webportfolio/3.12/lib/python3.12/site-packages/django/core/handlers/exception.py", line 55, in inner
    response = get_response(request)
               ^^^^^^^^^^^^^^^^^^^^^
  File "/home3/sambegkhatiwada/virtualenv/Django-portfolio/webportfolio/3.12/lib/python3.12/site-packages/django/utils/deprecation.py", line 120, in __call__
    response = response or self.get_response(request)
                           ^^^^^^^^^^^^^^^^^^^^^^^^^^
  File "/home3/sambegkhatiwada/virtualenv/Django-portfolio/webportfolio/3.12/lib/python3.12/site-packages/django/core/handlers/exception.py", line 57, in inner
    response = response_for_exception(request, exc)
               ^^^^^^^^^^^^^^^^^^^^^^^^^^^^^^^^^^^^
  File "/home3/sambegkhatiwada/virtualenv/Django-portfolio/webportfolio/3.12/lib/python3.12/site-packages/django/core/handlers/exception.py", line 140, in response_for_exception
    response = handle_uncaught_exception(
               ^^^^^^^^^^^^^^^^^^^^^^^^^^
  File "/home3/sambegkhatiwada/virtualenv/Django-portfolio/webportfolio/3.12/lib/python3.12/site-packages/django/core/handlers/exception.py", line 181, in handle_uncaught_exception
    return debug.technical_500_response(request, *exc_info)
           ^^^^^^^^^^^^^^^^^^^^^^^^^^^^^^^^^^^^^^^^^^^^^^^^
  File "/home3/sambegkhatiwada/virtualenv/Django-portfolio/webportfolio/3.12/lib/python3.12/site-packages/django/views/debug.py", line 69, in technical_500_response
    html = reporter.get_traceback_html()
           ^^^^^^^^^^^^^^^^^^^^^^^^^^^^^
  File "/home3/sambegkhatiwada/virtualenv/Django-portfolio/webportfolio/3.12/lib/python3.12/site-packages/django/views/debug.py", line 428, in get_traceback_html
    c = Context(self.get_traceback_data(), use_l10n=False)
                ^^^^^^^^^^^^^^^^^^^^^^^^^
  File "/home3/sambegkhatiwada/virtualenv/Django-portfolio/webportfolio/3.12/lib/python3.12/site-packages/django/views/debug.py", line 411, in get_traceback_data
    c["raising_view_name"] = get_caller(self.request)
                             ^^^^^^^^^^^^^^^^^^^^^^^^
  File "/home3/sambegkhatiwada/virtualenv/Django-portfolio/webportfolio/3.12/lib/python3.12/site-packages/django/views/debug.py", line 102, in get_caller
    resolver_match = resolve(request.path)
                     ^^^^^^^^^^^^^^^^^^^^^
  File "/home3/sambegkhatiwada/virtualenv/Django-portfolio/webportfolio/3.12/lib/python3.12/site-packages/django/urls/base.py", line 25, in resolve
    return get_resolver(urlconf).resolve(path)
           ^^^^^^^^^^^^^^^^^^^^^^^^^^^^^^^^^^^
  File "/home3/sambegkhatiwada/virtualenv/Django-portfolio/webportfolio/3.12/lib/python3.12/site-packages/django/urls/resolvers.py", line 666, in resolve
    for pattern in self.url_patterns:
                   ^^^^^^^^^^^^^^^^^
  File "/home3/sambegkhatiwada/virtualenv/Django-portfolio/webportfolio/3.12/lib/python3.12/site-packages/django/utils/functional.py", line 47, in __get__
    res = instance.__dict__[self.name] = self.func(instance)
                                         ^^^^^^^^^^^^^^^^^^^
  File "/home3/sambegkhatiwada/virtualenv/Django-portfolio/webportfolio/3.12/lib/python3.12/site-packages/django/urls/resolvers.py", line 718, in url_patterns
    patterns = getattr(self.urlconf_module, "urlpatterns", self.urlconf_module)
                       ^^^^^^^^^^^^^^^^^^^
  File "/home3/sambegkhatiwada/virtualenv/Django-portfolio/webportfolio/3.12/lib/python3.12/site-packages/django/utils/functional.py", line 47, in __get__
    res = instance.__dict__[self.name] = self.func(instance)
                                         ^^^^^^^^^^^^^^^^^^^
  File "/home3/sambegkhatiwada/virtualenv/Django-portfolio/webportfolio/3.12/lib/python3.12/site-packages/django/urls/resolvers.py", line 711, in urlconf_module
    return import_module(self.urlconf_name)
           ^^^^^^^^^^^^^^^^^^^^^^^^^^^^^^^^
  File "/opt/alt/python312/lib64/python3.12/importlib/__init__.py", line 90, in import_module
    return _bootstrap._gcd_import(name[level:], package, level)
           ^^^^^^^^^^^^^^^^^^^^^^^^^^^^^^^^^^^^^^^^^^^^^^^^^^^^
  File "<frozen importlib._bootstrap>", line 1387, in _gcd_import
  File "<frozen importlib._bootstrap>", line 1360, in _find_and_load
  File "<frozen importlib._bootstrap>", line 1331, in _find_and_load_unlocked
  File "<frozen importlib._bootstrap>", line 935, in _load_unlocked
  File "<frozen importlib._bootstrap_external>", line 999, in exec_module
  File "<frozen importlib._bootstrap>", line 488, in _call_with_frames_removed
  File "/home3/sambegkhatiwada/Django-portfolio/webportfolio/webportfolio/urls.py", line 5, in <module>
    urlpatterns += static(settings.MEDIA_URL, document_root=settings.MEDIA_ROOT)
    ^^^^^^^^^^^
NameError: name 'urlpatterns' is not defined

During handling of the above exception, another exception occurred:

Traceback (most recent call last):
  File "/home3/sambegkhatiwada/virtualenv/Django-portfolio/webportfolio/3.12/lib/python3.12/site-packages/django/core/handlers/wsgi.py", line 124, in __call__
    response = self.get_response(request)
               ^^^^^^^^^^^^^^^^^^^^^^^^^^
  File "/home3/sambegkhatiwada/virtualenv/Django-portfolio/webportfolio/3.12/lib/python3.12/site-packages/django/core/handlers/base.py", line 140, in get_response
    response = self._middleware_chain(request)
               ^^^^^^^^^^^^^^^^^^^^^^^^^^^^^^^
  File "/home3/sambegkhatiwada/virtualenv/Django-portfolio/webportfolio/3.12/lib/python3.12/site-packages/django/core/handlers/exception.py", line 57, in inner
    response = response_for_exception(request, exc)
               ^^^^^^^^^^^^^^^^^^^^^^^^^^^^^^^^^^^^
  File "/home3/sambegkhatiwada/virtualenv/Django-portfolio/webportfolio/3.12/lib/python3.12/site-packages/django/core/handlers/exception.py", line 140, in response_for_exception
    response = handle_uncaught_exception(
               ^^^^^^^^^^^^^^^^^^^^^^^^^^
  File "/home3/sambegkhatiwada/virtualenv/Django-portfolio/webportfolio/3.12/lib/python3.12/site-packages/django/core/handlers/exception.py", line 181, in handle_uncaught_exception
    return debug.technical_500_response(request, *exc_info)
           ^^^^^^^^^^^^^^^^^^^^^^^^^^^^^^^^^^^^^^^^^^^^^^^^
  File "/home3/sambegkhatiwada/virtualenv/Django-portfolio/webportfolio/3.12/lib/python3.12/site-packages/django/views/debug.py", line 69, in technical_500_response
    html = reporter.get_traceback_html()
           ^^^^^^^^^^^^^^^^^^^^^^^^^^^^^
  File "/home3/sambegkhatiwada/virtualenv/Django-portfolio/webportfolio/3.12/lib/python3.12/site-packages/django/views/debug.py", line 428, in get_traceback_html
    c = Context(self.get_traceback_data(), use_l10n=False)
                ^^^^^^^^^^^^^^^^^^^^^^^^^
  File "/home3/sambegkhatiwada/virtualenv/Django-portfolio/webportfolio/3.12/lib/python3.12/site-packages/django/views/debug.py", line 411, in get_traceback_data
    c["raising_view_name"] = get_caller(self.request)
                             ^^^^^^^^^^^^^^^^^^^^^^^^
  File "/home3/sambegkhatiwada/virtualenv/Django-portfolio/webportfolio/3.12/lib/python3.12/site-packages/django/views/debug.py", line 102, in get_caller
    resolver_match = resolve(request.path)
                     ^^^^^^^^^^^^^^^^^^^^^
  File "/home3/sambegkhatiwada/virtualenv/Django-portfolio/webportfolio/3.12/lib/python3.12/site-packages/django/urls/base.py", line 25, in resolve
    return get_resolver(urlconf).resolve(path)
           ^^^^^^^^^^^^^^^^^^^^^^^^^^^^^^^^^^^
  File "/home3/sambegkhatiwada/virtualenv/Django-portfolio/webportfolio/3.12/lib/python3.12/site-packages/django/urls/resolvers.py", line 666, in resolve
    for pattern in self.url_patterns:
                   ^^^^^^^^^^^^^^^^^
  File "/home3/sambegkhatiwada/virtualenv/Django-portfolio/webportfolio/3.12/lib/python3.12/site-packages/django/utils/functional.py", line 47, in __get__
    res = instance.__dict__[self.name] = self.func(instance)
                                         ^^^^^^^^^^^^^^^^^^^
  File "/home3/sambegkhatiwada/virtualenv/Django-portfolio/webportfolio/3.12/lib/python3.12/site-packages/django/urls/resolvers.py", line 718, in url_patterns
    patterns = getattr(self.urlconf_module, "urlpatterns", self.urlconf_module)
                       ^^^^^^^^^^^^^^^^^^^
  File "/home3/sambegkhatiwada/virtualenv/Django-portfolio/webportfolio/3.12/lib/python3.12/site-packages/django/utils/functional.py", line 47, in __get__
    res = instance.__dict__[self.name] = self.func(instance)
                                         ^^^^^^^^^^^^^^^^^^^
  File "/home3/sambegkhatiwada/virtualenv/Django-portfolio/webportfolio/3.12/lib/python3.12/site-packages/django/urls/resolvers.py", line 711, in urlconf_module
    return import_module(self.urlconf_name)
           ^^^^^^^^^^^^^^^^^^^^^^^^^^^^^^^^
  File "/opt/alt/python312/lib64/python3.12/importlib/__init__.py", line 90, in import_module
    return _bootstrap._gcd_import(name[level:], package, level)
           ^^^^^^^^^^^^^^^^^^^^^^^^^^^^^^^^^^^^^^^^^^^^^^^^^^^^
  File "<frozen importlib._bootstrap>", line 1387, in _gcd_import
  File "<frozen importlib._bootstrap>", line 1360, in _find_and_load
  File "<frozen importlib._bootstrap>", line 1331, in _find_and_load_unlocked
  File "<frozen importlib._bootstrap>", line 935, in _load_unlocked
  File "<frozen importlib._bootstrap_external>", line 999, in exec_module
  File "<frozen importlib._bootstrap>", line 488, in _call_with_frames_removed
  File "/home3/sambegkhatiwada/Django-portfolio/webportfolio/webportfolio/urls.py", line 5, in <module>
    urlpatterns += static(settings.MEDIA_URL, document_root=settings.MEDIA_ROOT)
    ^^^^^^^^^^^
NameError: name 'urlpatterns' is not defined
[ERROR] [UID:1370][1234422] wsgiAppHandler pApp->start_response() return NULL.
Traceback (most recent call last):
  File "/home3/sambegkhatiwada/virtualenv/Django-portfolio/webportfolio/3.12/lib/python3.12/site-packages/django/core/handlers/exception.py", line 55, in inner
    response = get_response(request)
               ^^^^^^^^^^^^^^^^^^^^^
  File "/home3/sambegkhatiwada/virtualenv/Django-portfolio/webportfolio/3.12/lib/python3.12/site-packages/django/core/handlers/base.py", line 181, in _get_response
    callback, callback_args, callback_kwargs = self.resolve_request(request)
                                               ^^^^^^^^^^^^^^^^^^^^^^^^^^^^^
  File "/home3/sambegkhatiwada/virtualenv/Django-portfolio/webportfolio/3.12/lib/python3.12/site-packages/django/core/handlers/base.py", line 313, in resolve_request
    resolver_match = resolver.resolve(request.path_info)
                     ^^^^^^^^^^^^^^^^^^^^^^^^^^^^^^^^^^^
  File "/home3/sambegkhatiwada/virtualenv/Django-portfolio/webportfolio/3.12/lib/python3.12/site-packages/django/urls/resolvers.py", line 666, in resolve
    for pattern in self.url_patterns:
                   ^^^^^^^^^^^^^^^^^
  File "/home3/sambegkhatiwada/virtualenv/Django-portfolio/webportfolio/3.12/lib/python3.12/site-packages/django/utils/functional.py", line 47, in __get__
    res = instance.__dict__[self.name] = self.func(instance)
                                         ^^^^^^^^^^^^^^^^^^^
  File "/home3/sambegkhatiwada/virtualenv/Django-portfolio/webportfolio/3.12/lib/python3.12/site-packages/django/urls/resolvers.py", line 718, in url_patterns
    patterns = getattr(self.urlconf_module, "urlpatterns", self.urlconf_module)
                       ^^^^^^^^^^^^^^^^^^^
  File "/home3/sambegkhatiwada/virtualenv/Django-portfolio/webportfolio/3.12/lib/python3.12/site-packages/django/utils/functional.py", line 47, in __get__
    res = instance.__dict__[self.name] = self.func(instance)
                                         ^^^^^^^^^^^^^^^^^^^
  File "/home3/sambegkhatiwada/virtualenv/Django-portfolio/webportfolio/3.12/lib/python3.12/site-packages/django/urls/resolvers.py", line 711, in urlconf_module
    return import_module(self.urlconf_name)
           ^^^^^^^^^^^^^^^^^^^^^^^^^^^^^^^^
  File "/opt/alt/python312/lib64/python3.12/importlib/__init__.py", line 90, in import_module
    return _bootstrap._gcd_import(name[level:], package, level)
           ^^^^^^^^^^^^^^^^^^^^^^^^^^^^^^^^^^^^^^^^^^^^^^^^^^^^
  File "<frozen importlib._bootstrap>", line 1387, in _gcd_import
  File "<frozen importlib._bootstrap>", line 1360, in _find_and_load
  File "<frozen importlib._bootstrap>", line 1331, in _find_and_load_unlocked
  File "<frozen importlib._bootstrap>", line 935, in _load_unlocked
  File "<frozen importlib._bootstrap_external>", line 999, in exec_module
  File "<frozen importlib._bootstrap>", line 488, in _call_with_frames_removed
  File "/home3/sambegkhatiwada/Django-portfolio/webportfolio/webportfolio/urls.py", line 5, in <module>
    urlpatterns += static(settings.MEDIA_URL, document_root=settings.MEDIA_ROOT)
    ^^^^^^^^^^^
NameError: name 'urlpatterns' is not defined

During handling of the above exception, another exception occurred:

Traceback (most recent call last):
  File "/home3/sambegkhatiwada/virtualenv/Django-portfolio/webportfolio/3.12/lib/python3.12/site-packages/django/core/handlers/exception.py", line 55, in inner
    response = get_response(request)
               ^^^^^^^^^^^^^^^^^^^^^
  File "/home3/sambegkhatiwada/virtualenv/Django-portfolio/webportfolio/3.12/lib/python3.12/site-packages/django/utils/deprecation.py", line 120, in __call__
    response = response or self.get_response(request)
                           ^^^^^^^^^^^^^^^^^^^^^^^^^^
  File "/home3/sambegkhatiwada/virtualenv/Django-portfolio/webportfolio/3.12/lib/python3.12/site-packages/django/core/handlers/exception.py", line 57, in inner
    response = response_for_exception(request, exc)
               ^^^^^^^^^^^^^^^^^^^^^^^^^^^^^^^^^^^^
  File "/home3/sambegkhatiwada/virtualenv/Django-portfolio/webportfolio/3.12/lib/python3.12/site-packages/django/core/handlers/exception.py", line 140, in response_for_exception
    response = handle_uncaught_exception(
               ^^^^^^^^^^^^^^^^^^^^^^^^^^
  File "/home3/sambegkhatiwada/virtualenv/Django-portfolio/webportfolio/3.12/lib/python3.12/site-packages/django/core/handlers/exception.py", line 181, in handle_uncaught_exception
    return debug.technical_500_response(request, *exc_info)
           ^^^^^^^^^^^^^^^^^^^^^^^^^^^^^^^^^^^^^^^^^^^^^^^^
  File "/home3/sambegkhatiwada/virtualenv/Django-portfolio/webportfolio/3.12/lib/python3.12/site-packages/django/views/debug.py", line 69, in technical_500_response
    html = reporter.get_traceback_html()
           ^^^^^^^^^^^^^^^^^^^^^^^^^^^^^
  File "/home3/sambegkhatiwada/virtualenv/Django-portfolio/webportfolio/3.12/lib/python3.12/site-packages/django/views/debug.py", line 428, in get_traceback_html
    c = Context(self.get_traceback_data(), use_l10n=False)
                ^^^^^^^^^^^^^^^^^^^^^^^^^
  File "/home3/sambegkhatiwada/virtualenv/Django-portfolio/webportfolio/3.12/lib/python3.12/site-packages/django/views/debug.py", line 411, in get_traceback_data
    c["raising_view_name"] = get_caller(self.request)
                             ^^^^^^^^^^^^^^^^^^^^^^^^
  File "/home3/sambegkhatiwada/virtualenv/Django-portfolio/webportfolio/3.12/lib/python3.12/site-packages/django/views/debug.py", line 102, in get_caller
    resolver_match = resolve(request.path)
                     ^^^^^^^^^^^^^^^^^^^^^
  File "/home3/sambegkhatiwada/virtualenv/Django-portfolio/webportfolio/3.12/lib/python3.12/site-packages/django/urls/base.py", line 25, in resolve
    return get_resolver(urlconf).resolve(path)
           ^^^^^^^^^^^^^^^^^^^^^^^^^^^^^^^^^^^
  File "/home3/sambegkhatiwada/virtualenv/Django-portfolio/webportfolio/3.12/lib/python3.12/site-packages/django/urls/resolvers.py", line 666, in resolve
    for pattern in self.url_patterns:
                   ^^^^^^^^^^^^^^^^^
  File "/home3/sambegkhatiwada/virtualenv/Django-portfolio/webportfolio/3.12/lib/python3.12/site-packages/django/utils/functional.py", line 47, in __get__
    res = instance.__dict__[self.name] = self.func(instance)
                                         ^^^^^^^^^^^^^^^^^^^
  File "/home3/sambegkhatiwada/virtualenv/Django-portfolio/webportfolio/3.12/lib/python3.12/site-packages/django/urls/resolvers.py", line 718, in url_patterns
    patterns = getattr(self.urlconf_module, "urlpatterns", self.urlconf_module)
                       ^^^^^^^^^^^^^^^^^^^
  File "/home3/sambegkhatiwada/virtualenv/Django-portfolio/webportfolio/3.12/lib/python3.12/site-packages/django/utils/functional.py", line 47, in __get__
    res = instance.__dict__[self.name] = self.func(instance)
                                         ^^^^^^^^^^^^^^^^^^^
  File "/home3/sambegkhatiwada/virtualenv/Django-portfolio/webportfolio/3.12/lib/python3.12/site-packages/django/urls/resolvers.py", line 711, in urlconf_module
    return import_module(self.urlconf_name)
           ^^^^^^^^^^^^^^^^^^^^^^^^^^^^^^^^
  File "/opt/alt/python312/lib64/python3.12/importlib/__init__.py", line 90, in import_module
    return _bootstrap._gcd_import(name[level:], package, level)
           ^^^^^^^^^^^^^^^^^^^^^^^^^^^^^^^^^^^^^^^^^^^^^^^^^^^^
  File "<frozen importlib._bootstrap>", line 1387, in _gcd_import
  File "<frozen importlib._bootstrap>", line 1360, in _find_and_load
  File "<frozen importlib._bootstrap>", line 1331, in _find_and_load_unlocked
  File "<frozen importlib._bootstrap>", line 935, in _load_unlocked
  File "<frozen importlib._bootstrap_external>", line 999, in exec_module
  File "<frozen importlib._bootstrap>", line 488, in _call_with_frames_removed
  File "/home3/sambegkhatiwada/Django-portfolio/webportfolio/webportfolio/urls.py", line 5, in <module>
    urlpatterns += static(settings.MEDIA_URL, document_root=settings.MEDIA_ROOT)
    ^^^^^^^^^^^
NameError: name 'urlpatterns' is not defined

During handling of the above exception, another exception occurred:

Traceback (most recent call last):
  File "/home3/sambegkhatiwada/virtualenv/Django-portfolio/webportfolio/3.12/lib/python3.12/site-packages/django/core/handlers/exception.py", line 55, in inner
    response = get_response(request)
               ^^^^^^^^^^^^^^^^^^^^^
  File "/home3/sambegkhatiwada/virtualenv/Django-portfolio/webportfolio/3.12/lib/python3.12/site-packages/django/utils/deprecation.py", line 120, in __call__
    response = response or self.get_response(request)
                           ^^^^^^^^^^^^^^^^^^^^^^^^^^
  File "/home3/sambegkhatiwada/virtualenv/Django-portfolio/webportfolio/3.12/lib/python3.12/site-packages/django/core/handlers/exception.py", line 57, in inner
    response = response_for_exception(request, exc)
               ^^^^^^^^^^^^^^^^^^^^^^^^^^^^^^^^^^^^
  File "/home3/sambegkhatiwada/virtualenv/Django-portfolio/webportfolio/3.12/lib/python3.12/site-packages/django/core/handlers/exception.py", line 140, in response_for_exception
    response = handle_uncaught_exception(
               ^^^^^^^^^^^^^^^^^^^^^^^^^^
  File "/home3/sambegkhatiwada/virtualenv/Django-portfolio/webportfolio/3.12/lib/python3.12/site-packages/django/core/handlers/exception.py", line 181, in handle_uncaught_exception
    return debug.technical_500_response(request, *exc_info)
           ^^^^^^^^^^^^^^^^^^^^^^^^^^^^^^^^^^^^^^^^^^^^^^^^
  File "/home3/sambegkhatiwada/virtualenv/Django-portfolio/webportfolio/3.12/lib/python3.12/site-packages/django/views/debug.py", line 69, in technical_500_response
    html = reporter.get_traceback_html()
           ^^^^^^^^^^^^^^^^^^^^^^^^^^^^^
  File "/home3/sambegkhatiwada/virtualenv/Django-portfolio/webportfolio/3.12/lib/python3.12/site-packages/django/views/debug.py", line 428, in get_traceback_html
    c = Context(self.get_traceback_data(), use_l10n=False)
                ^^^^^^^^^^^^^^^^^^^^^^^^^
  File "/home3/sambegkhatiwada/virtualenv/Django-portfolio/webportfolio/3.12/lib/python3.12/site-packages/django/views/debug.py", line 411, in get_traceback_data
    c["raising_view_name"] = get_caller(self.request)
                             ^^^^^^^^^^^^^^^^^^^^^^^^
  File "/home3/sambegkhatiwada/virtualenv/Django-portfolio/webportfolio/3.12/lib/python3.12/site-packages/django/views/debug.py", line 102, in get_caller
    resolver_match = resolve(request.path)
                     ^^^^^^^^^^^^^^^^^^^^^
  File "/home3/sambegkhatiwada/virtualenv/Django-portfolio/webportfolio/3.12/lib/python3.12/site-packages/django/urls/base.py", line 25, in resolve
    return get_resolver(urlconf).resolve(path)
           ^^^^^^^^^^^^^^^^^^^^^^^^^^^^^^^^^^^
  File "/home3/sambegkhatiwada/virtualenv/Django-portfolio/webportfolio/3.12/lib/python3.12/site-packages/django/urls/resolvers.py", line 666, in resolve
    for pattern in self.url_patterns:
                   ^^^^^^^^^^^^^^^^^
  File "/home3/sambegkhatiwada/virtualenv/Django-portfolio/webportfolio/3.12/lib/python3.12/site-packages/django/utils/functional.py", line 47, in __get__
    res = instance.__dict__[self.name] = self.func(instance)
                                         ^^^^^^^^^^^^^^^^^^^
  File "/home3/sambegkhatiwada/virtualenv/Django-portfolio/webportfolio/3.12/lib/python3.12/site-packages/django/urls/resolvers.py", line 718, in url_patterns
    patterns = getattr(self.urlconf_module, "urlpatterns", self.urlconf_module)
                       ^^^^^^^^^^^^^^^^^^^
  File "/home3/sambegkhatiwada/virtualenv/Django-portfolio/webportfolio/3.12/lib/python3.12/site-packages/django/utils/functional.py", line 47, in __get__
    res = instance.__dict__[self.name] = self.func(instance)
                                         ^^^^^^^^^^^^^^^^^^^
  File "/home3/sambegkhatiwada/virtualenv/Django-portfolio/webportfolio/3.12/lib/python3.12/site-packages/django/urls/resolvers.py", line 711, in urlconf_module
    return import_module(self.urlconf_name)
           ^^^^^^^^^^^^^^^^^^^^^^^^^^^^^^^^
  File "/opt/alt/python312/lib64/python3.12/importlib/__init__.py", line 90, in import_module
    return _bootstrap._gcd_import(name[level:], package, level)
           ^^^^^^^^^^^^^^^^^^^^^^^^^^^^^^^^^^^^^^^^^^^^^^^^^^^^
  File "<frozen importlib._bootstrap>", line 1387, in _gcd_import
  File "<frozen importlib._bootstrap>", line 1360, in _find_and_load
  File "<frozen importlib._bootstrap>", line 1331, in _find_and_load_unlocked
  File "<frozen importlib._bootstrap>", line 935, in _load_unlocked
  File "<frozen importlib._bootstrap_external>", line 999, in exec_module
  File "<frozen importlib._bootstrap>", line 488, in _call_with_frames_removed
  File "/home3/sambegkhatiwada/Django-portfolio/webportfolio/webportfolio/urls.py", line 5, in <module>
    urlpatterns += static(settings.MEDIA_URL, document_root=settings.MEDIA_ROOT)
    ^^^^^^^^^^^
NameError: name 'urlpatterns' is not defined

During handling of the above exception, another exception occurred:

Traceback (most recent call last):
  File "/home3/sambegkhatiwada/virtualenv/Django-portfolio/webportfolio/3.12/lib/python3.12/site-packages/django/core/handlers/exception.py", line 55, in inner
    response = get_response(request)
               ^^^^^^^^^^^^^^^^^^^^^
  File "/home3/sambegkhatiwada/virtualenv/Django-portfolio/webportfolio/3.12/lib/python3.12/site-packages/django/utils/deprecation.py", line 120, in __call__
    response = response or self.get_response(request)
                           ^^^^^^^^^^^^^^^^^^^^^^^^^^
  File "/home3/sambegkhatiwada/virtualenv/Django-portfolio/webportfolio/3.12/lib/python3.12/site-packages/django/core/handlers/exception.py", line 57, in inner
    response = response_for_exception(request, exc)
               ^^^^^^^^^^^^^^^^^^^^^^^^^^^^^^^^^^^^
  File "/home3/sambegkhatiwada/virtualenv/Django-portfolio/webportfolio/3.12/lib/python3.12/site-packages/django/core/handlers/exception.py", line 140, in response_for_exception
    response = handle_uncaught_exception(
               ^^^^^^^^^^^^^^^^^^^^^^^^^^
  File "/home3/sambegkhatiwada/virtualenv/Django-portfolio/webportfolio/3.12/lib/python3.12/site-packages/django/core/handlers/exception.py", line 181, in handle_uncaught_exception
    return debug.technical_500_response(request, *exc_info)
           ^^^^^^^^^^^^^^^^^^^^^^^^^^^^^^^^^^^^^^^^^^^^^^^^
  File "/home3/sambegkhatiwada/virtualenv/Django-portfolio/webportfolio/3.12/lib/python3.12/site-packages/django/views/debug.py", line 69, in technical_500_response
    html = reporter.get_traceback_html()
           ^^^^^^^^^^^^^^^^^^^^^^^^^^^^^
  File "/home3/sambegkhatiwada/virtualenv/Django-portfolio/webportfolio/3.12/lib/python3.12/site-packages/django/views/debug.py", line 428, in get_traceback_html
    c = Context(self.get_traceback_data(), use_l10n=False)
                ^^^^^^^^^^^^^^^^^^^^^^^^^
  File "/home3/sambegkhatiwada/virtualenv/Django-portfolio/webportfolio/3.12/lib/python3.12/site-packages/django/views/debug.py", line 411, in get_traceback_data
    c["raising_view_name"] = get_caller(self.request)
                             ^^^^^^^^^^^^^^^^^^^^^^^^
  File "/home3/sambegkhatiwada/virtualenv/Django-portfolio/webportfolio/3.12/lib/python3.12/site-packages/django/views/debug.py", line 102, in get_caller
    resolver_match = resolve(request.path)
                     ^^^^^^^^^^^^^^^^^^^^^
  File "/home3/sambegkhatiwada/virtualenv/Django-portfolio/webportfolio/3.12/lib/python3.12/site-packages/django/urls/base.py", line 25, in resolve
    return get_resolver(urlconf).resolve(path)
           ^^^^^^^^^^^^^^^^^^^^^^^^^^^^^^^^^^^
  File "/home3/sambegkhatiwada/virtualenv/Django-portfolio/webportfolio/3.12/lib/python3.12/site-packages/django/urls/resolvers.py", line 666, in resolve
    for pattern in self.url_patterns:
                   ^^^^^^^^^^^^^^^^^
  File "/home3/sambegkhatiwada/virtualenv/Django-portfolio/webportfolio/3.12/lib/python3.12/site-packages/django/utils/functional.py", line 47, in __get__
    res = instance.__dict__[self.name] = self.func(instance)
                                         ^^^^^^^^^^^^^^^^^^^
  File "/home3/sambegkhatiwada/virtualenv/Django-portfolio/webportfolio/3.12/lib/python3.12/site-packages/django/urls/resolvers.py", line 718, in url_patterns
    patterns = getattr(self.urlconf_module, "urlpatterns", self.urlconf_module)
                       ^^^^^^^^^^^^^^^^^^^
  File "/home3/sambegkhatiwada/virtualenv/Django-portfolio/webportfolio/3.12/lib/python3.12/site-packages/django/utils/functional.py", line 47, in __get__
    res = instance.__dict__[self.name] = self.func(instance)
                                         ^^^^^^^^^^^^^^^^^^^
  File "/home3/sambegkhatiwada/virtualenv/Django-portfolio/webportfolio/3.12/lib/python3.12/site-packages/django/urls/resolvers.py", line 711, in urlconf_module
    return import_module(self.urlconf_name)
           ^^^^^^^^^^^^^^^^^^^^^^^^^^^^^^^^
  File "/opt/alt/python312/lib64/python3.12/importlib/__init__.py", line 90, in import_module
    return _bootstrap._gcd_import(name[level:], package, level)
           ^^^^^^^^^^^^^^^^^^^^^^^^^^^^^^^^^^^^^^^^^^^^^^^^^^^^
  File "<frozen importlib._bootstrap>", line 1387, in _gcd_import
  File "<frozen importlib._bootstrap>", line 1360, in _find_and_load
  File "<frozen importlib._bootstrap>", line 1331, in _find_and_load_unlocked
  File "<frozen importlib._bootstrap>", line 935, in _load_unlocked
  File "<frozen importlib._bootstrap_external>", line 999, in exec_module
  File "<frozen importlib._bootstrap>", line 488, in _call_with_frames_removed
  File "/home3/sambegkhatiwada/Django-portfolio/webportfolio/webportfolio/urls.py", line 5, in <module>
    urlpatterns += static(settings.MEDIA_URL, document_root=settings.MEDIA_ROOT)
    ^^^^^^^^^^^
NameError: name 'urlpatterns' is not defined

During handling of the above exception, another exception occurred:

Traceback (most recent call last):
  File "/home3/sambegkhatiwada/virtualenv/Django-portfolio/webportfolio/3.12/lib/python3.12/site-packages/django/core/handlers/exception.py", line 55, in inner
    response = get_response(request)
               ^^^^^^^^^^^^^^^^^^^^^
  File "/home3/sambegkhatiwada/virtualenv/Django-portfolio/webportfolio/3.12/lib/python3.12/site-packages/django/utils/deprecation.py", line 120, in __call__
    response = response or self.get_response(request)
                           ^^^^^^^^^^^^^^^^^^^^^^^^^^
  File "/home3/sambegkhatiwada/virtualenv/Django-portfolio/webportfolio/3.12/lib/python3.12/site-packages/django/core/handlers/exception.py", line 57, in inner
    response = response_for_exception(request, exc)
               ^^^^^^^^^^^^^^^^^^^^^^^^^^^^^^^^^^^^
  File "/home3/sambegkhatiwada/virtualenv/Django-portfolio/webportfolio/3.12/lib/python3.12/site-packages/django/core/handlers/exception.py", line 140, in response_for_exception
    response = handle_uncaught_exception(
               ^^^^^^^^^^^^^^^^^^^^^^^^^^
  File "/home3/sambegkhatiwada/virtualenv/Django-portfolio/webportfolio/3.12/lib/python3.12/site-packages/django/core/handlers/exception.py", line 181, in handle_uncaught_exception
    return debug.technical_500_response(request, *exc_info)
           ^^^^^^^^^^^^^^^^^^^^^^^^^^^^^^^^^^^^^^^^^^^^^^^^
  File "/home3/sambegkhatiwada/virtualenv/Django-portfolio/webportfolio/3.12/lib/python3.12/site-packages/django/views/debug.py", line 69, in technical_500_response
    html = reporter.get_traceback_html()
           ^^^^^^^^^^^^^^^^^^^^^^^^^^^^^
  File "/home3/sambegkhatiwada/virtualenv/Django-portfolio/webportfolio/3.12/lib/python3.12/site-packages/django/views/debug.py", line 428, in get_traceback_html
    c = Context(self.get_traceback_data(), use_l10n=False)
                ^^^^^^^^^^^^^^^^^^^^^^^^^
  File "/home3/sambegkhatiwada/virtualenv/Django-portfolio/webportfolio/3.12/lib/python3.12/site-packages/django/views/debug.py", line 411, in get_traceback_data
    c["raising_view_name"] = get_caller(self.request)
                             ^^^^^^^^^^^^^^^^^^^^^^^^
  File "/home3/sambegkhatiwada/virtualenv/Django-portfolio/webportfolio/3.12/lib/python3.12/site-packages/django/views/debug.py", line 102, in get_caller
    resolver_match = resolve(request.path)
                     ^^^^^^^^^^^^^^^^^^^^^
  File "/home3/sambegkhatiwada/virtualenv/Django-portfolio/webportfolio/3.12/lib/python3.12/site-packages/django/urls/base.py", line 25, in resolve
    return get_resolver(urlconf).resolve(path)
           ^^^^^^^^^^^^^^^^^^^^^^^^^^^^^^^^^^^
  File "/home3/sambegkhatiwada/virtualenv/Django-portfolio/webportfolio/3.12/lib/python3.12/site-packages/django/urls/resolvers.py", line 666, in resolve
    for pattern in self.url_patterns:
                   ^^^^^^^^^^^^^^^^^
  File "/home3/sambegkhatiwada/virtualenv/Django-portfolio/webportfolio/3.12/lib/python3.12/site-packages/django/utils/functional.py", line 47, in __get__
    res = instance.__dict__[self.name] = self.func(instance)
                                         ^^^^^^^^^^^^^^^^^^^
  File "/home3/sambegkhatiwada/virtualenv/Django-portfolio/webportfolio/3.12/lib/python3.12/site-packages/django/urls/resolvers.py", line 718, in url_patterns
    patterns = getattr(self.urlconf_module, "urlpatterns", self.urlconf_module)
                       ^^^^^^^^^^^^^^^^^^^
  File "/home3/sambegkhatiwada/virtualenv/Django-portfolio/webportfolio/3.12/lib/python3.12/site-packages/django/utils/functional.py", line 47, in __get__
    res = instance.__dict__[self.name] = self.func(instance)
                                         ^^^^^^^^^^^^^^^^^^^
  File "/home3/sambegkhatiwada/virtualenv/Django-portfolio/webportfolio/3.12/lib/python3.12/site-packages/django/urls/resolvers.py", line 711, in urlconf_module
    return import_module(self.urlconf_name)
           ^^^^^^^^^^^^^^^^^^^^^^^^^^^^^^^^
  File "/opt/alt/python312/lib64/python3.12/importlib/__init__.py", line 90, in import_module
    return _bootstrap._gcd_import(name[level:], package, level)
           ^^^^^^^^^^^^^^^^^^^^^^^^^^^^^^^^^^^^^^^^^^^^^^^^^^^^
  File "<frozen importlib._bootstrap>", line 1387, in _gcd_import
  File "<frozen importlib._bootstrap>", line 1360, in _find_and_load
  File "<frozen importlib._bootstrap>", line 1331, in _find_and_load_unlocked
  File "<frozen importlib._bootstrap>", line 935, in _load_unlocked
  File "<frozen importlib._bootstrap_external>", line 999, in exec_module
  File "<frozen importlib._bootstrap>", line 488, in _call_with_frames_removed
  File "/home3/sambegkhatiwada/Django-portfolio/webportfolio/webportfolio/urls.py", line 5, in <module>
    urlpatterns += static(settings.MEDIA_URL, document_root=settings.MEDIA_ROOT)
    ^^^^^^^^^^^
NameError: name 'urlpatterns' is not defined

During handling of the above exception, another exception occurred:

Traceback (most recent call last):
  File "/home3/sambegkhatiwada/virtualenv/Django-portfolio/webportfolio/3.12/lib/python3.12/site-packages/django/core/handlers/exception.py", line 55, in inner
    response = get_response(request)
               ^^^^^^^^^^^^^^^^^^^^^
  File "/home3/sambegkhatiwada/virtualenv/Django-portfolio/webportfolio/3.12/lib/python3.12/site-packages/django/utils/deprecation.py", line 120, in __call__
    response = response or self.get_response(request)
                           ^^^^^^^^^^^^^^^^^^^^^^^^^^
  File "/home3/sambegkhatiwada/virtualenv/Django-portfolio/webportfolio/3.12/lib/python3.12/site-packages/django/core/handlers/exception.py", line 57, in inner
    response = response_for_exception(request, exc)
               ^^^^^^^^^^^^^^^^^^^^^^^^^^^^^^^^^^^^
  File "/home3/sambegkhatiwada/virtualenv/Django-portfolio/webportfolio/3.12/lib/python3.12/site-packages/django/core/handlers/exception.py", line 140, in response_for_exception
    response = handle_uncaught_exception(
               ^^^^^^^^^^^^^^^^^^^^^^^^^^
  File "/home3/sambegkhatiwada/virtualenv/Django-portfolio/webportfolio/3.12/lib/python3.12/site-packages/django/core/handlers/exception.py", line 181, in handle_uncaught_exception
    return debug.technical_500_response(request, *exc_info)
           ^^^^^^^^^^^^^^^^^^^^^^^^^^^^^^^^^^^^^^^^^^^^^^^^
  File "/home3/sambegkhatiwada/virtualenv/Django-portfolio/webportfolio/3.12/lib/python3.12/site-packages/django/views/debug.py", line 69, in technical_500_response
    html = reporter.get_traceback_html()
           ^^^^^^^^^^^^^^^^^^^^^^^^^^^^^
  File "/home3/sambegkhatiwada/virtualenv/Django-portfolio/webportfolio/3.12/lib/python3.12/site-packages/django/views/debug.py", line 428, in get_traceback_html
    c = Context(self.get_traceback_data(), use_l10n=False)
                ^^^^^^^^^^^^^^^^^^^^^^^^^
  File "/home3/sambegkhatiwada/virtualenv/Django-portfolio/webportfolio/3.12/lib/python3.12/site-packages/django/views/debug.py", line 411, in get_traceback_data
    c["raising_view_name"] = get_caller(self.request)
                             ^^^^^^^^^^^^^^^^^^^^^^^^
  File "/home3/sambegkhatiwada/virtualenv/Django-portfolio/webportfolio/3.12/lib/python3.12/site-packages/django/views/debug.py", line 102, in get_caller
    resolver_match = resolve(request.path)
                     ^^^^^^^^^^^^^^^^^^^^^
  File "/home3/sambegkhatiwada/virtualenv/Django-portfolio/webportfolio/3.12/lib/python3.12/site-packages/django/urls/base.py", line 25, in resolve
    return get_resolver(urlconf).resolve(path)
           ^^^^^^^^^^^^^^^^^^^^^^^^^^^^^^^^^^^
  File "/home3/sambegkhatiwada/virtualenv/Django-portfolio/webportfolio/3.12/lib/python3.12/site-packages/django/urls/resolvers.py", line 666, in resolve
    for pattern in self.url_patterns:
                   ^^^^^^^^^^^^^^^^^
  File "/home3/sambegkhatiwada/virtualenv/Django-portfolio/webportfolio/3.12/lib/python3.12/site-packages/django/utils/functional.py", line 47, in __get__
    res = instance.__dict__[self.name] = self.func(instance)
                                         ^^^^^^^^^^^^^^^^^^^
  File "/home3/sambegkhatiwada/virtualenv/Django-portfolio/webportfolio/3.12/lib/python3.12/site-packages/django/urls/resolvers.py", line 718, in url_patterns
    patterns = getattr(self.urlconf_module, "urlpatterns", self.urlconf_module)
                       ^^^^^^^^^^^^^^^^^^^
  File "/home3/sambegkhatiwada/virtualenv/Django-portfolio/webportfolio/3.12/lib/python3.12/site-packages/django/utils/functional.py", line 47, in __get__
    res = instance.__dict__[self.name] = self.func(instance)
                                         ^^^^^^^^^^^^^^^^^^^
  File "/home3/sambegkhatiwada/virtualenv/Django-portfolio/webportfolio/3.12/lib/python3.12/site-packages/django/urls/resolvers.py", line 711, in urlconf_module
    return import_module(self.urlconf_name)
           ^^^^^^^^^^^^^^^^^^^^^^^^^^^^^^^^
  File "/opt/alt/python312/lib64/python3.12/importlib/__init__.py", line 90, in import_module
    return _bootstrap._gcd_import(name[level:], package, level)
           ^^^^^^^^^^^^^^^^^^^^^^^^^^^^^^^^^^^^^^^^^^^^^^^^^^^^
  File "<frozen importlib._bootstrap>", line 1387, in _gcd_import
  File "<frozen importlib._bootstrap>", line 1360, in _find_and_load
  File "<frozen importlib._bootstrap>", line 1331, in _find_and_load_unlocked
  File "<frozen importlib._bootstrap>", line 935, in _load_unlocked
  File "<frozen importlib._bootstrap_external>", line 999, in exec_module
  File "<frozen importlib._bootstrap>", line 488, in _call_with_frames_removed
  File "/home3/sambegkhatiwada/Django-portfolio/webportfolio/webportfolio/urls.py", line 5, in <module>
    urlpatterns += static(settings.MEDIA_URL, document_root=settings.MEDIA_ROOT)
    ^^^^^^^^^^^
NameError: name 'urlpatterns' is not defined

During handling of the above exception, another exception occurred:

Traceback (most recent call last):
  File "/home3/sambegkhatiwada/virtualenv/Django-portfolio/webportfolio/3.12/lib/python3.12/site-packages/django/core/handlers/exception.py", line 55, in inner
    response = get_response(request)
               ^^^^^^^^^^^^^^^^^^^^^
  File "/home3/sambegkhatiwada/virtualenv/Django-portfolio/webportfolio/3.12/lib/python3.12/site-packages/django/utils/deprecation.py", line 120, in __call__
    response = response or self.get_response(request)
                           ^^^^^^^^^^^^^^^^^^^^^^^^^^
  File "/home3/sambegkhatiwada/virtualenv/Django-portfolio/webportfolio/3.12/lib/python3.12/site-packages/django/core/handlers/exception.py", line 57, in inner
    response = response_for_exception(request, exc)
               ^^^^^^^^^^^^^^^^^^^^^^^^^^^^^^^^^^^^
  File "/home3/sambegkhatiwada/virtualenv/Django-portfolio/webportfolio/3.12/lib/python3.12/site-packages/django/core/handlers/exception.py", line 140, in response_for_exception
    response = handle_uncaught_exception(
               ^^^^^^^^^^^^^^^^^^^^^^^^^^
  File "/home3/sambegkhatiwada/virtualenv/Django-portfolio/webportfolio/3.12/lib/python3.12/site-packages/django/core/handlers/exception.py", line 181, in handle_uncaught_exception
    return debug.technical_500_response(request, *exc_info)
           ^^^^^^^^^^^^^^^^^^^^^^^^^^^^^^^^^^^^^^^^^^^^^^^^
  File "/home3/sambegkhatiwada/virtualenv/Django-portfolio/webportfolio/3.12/lib/python3.12/site-packages/django/views/debug.py", line 69, in technical_500_response
    html = reporter.get_traceback_html()
           ^^^^^^^^^^^^^^^^^^^^^^^^^^^^^
  File "/home3/sambegkhatiwada/virtualenv/Django-portfolio/webportfolio/3.12/lib/python3.12/site-packages/django/views/debug.py", line 428, in get_traceback_html
    c = Context(self.get_traceback_data(), use_l10n=False)
                ^^^^^^^^^^^^^^^^^^^^^^^^^
  File "/home3/sambegkhatiwada/virtualenv/Django-portfolio/webportfolio/3.12/lib/python3.12/site-packages/django/views/debug.py", line 411, in get_traceback_data
    c["raising_view_name"] = get_caller(self.request)
                             ^^^^^^^^^^^^^^^^^^^^^^^^
  File "/home3/sambegkhatiwada/virtualenv/Django-portfolio/webportfolio/3.12/lib/python3.12/site-packages/django/views/debug.py", line 102, in get_caller
    resolver_match = resolve(request.path)
                     ^^^^^^^^^^^^^^^^^^^^^
  File "/home3/sambegkhatiwada/virtualenv/Django-portfolio/webportfolio/3.12/lib/python3.12/site-packages/django/urls/base.py", line 25, in resolve
    return get_resolver(urlconf).resolve(path)
           ^^^^^^^^^^^^^^^^^^^^^^^^^^^^^^^^^^^
  File "/home3/sambegkhatiwada/virtualenv/Django-portfolio/webportfolio/3.12/lib/python3.12/site-packages/django/urls/resolvers.py", line 666, in resolve
    for pattern in self.url_patterns:
                   ^^^^^^^^^^^^^^^^^
  File "/home3/sambegkhatiwada/virtualenv/Django-portfolio/webportfolio/3.12/lib/python3.12/site-packages/django/utils/functional.py", line 47, in __get__
    res = instance.__dict__[self.name] = self.func(instance)
                                         ^^^^^^^^^^^^^^^^^^^
  File "/home3/sambegkhatiwada/virtualenv/Django-portfolio/webportfolio/3.12/lib/python3.12/site-packages/django/urls/resolvers.py", line 718, in url_patterns
    patterns = getattr(self.urlconf_module, "urlpatterns", self.urlconf_module)
                       ^^^^^^^^^^^^^^^^^^^
  File "/home3/sambegkhatiwada/virtualenv/Django-portfolio/webportfolio/3.12/lib/python3.12/site-packages/django/utils/functional.py", line 47, in __get__
    res = instance.__dict__[self.name] = self.func(instance)
                                         ^^^^^^^^^^^^^^^^^^^
  File "/home3/sambegkhatiwada/virtualenv/Django-portfolio/webportfolio/3.12/lib/python3.12/site-packages/django/urls/resolvers.py", line 711, in urlconf_module
    return import_module(self.urlconf_name)
           ^^^^^^^^^^^^^^^^^^^^^^^^^^^^^^^^
  File "/opt/alt/python312/lib64/python3.12/importlib/__init__.py", line 90, in import_module
    return _bootstrap._gcd_import(name[level:], package, level)
           ^^^^^^^^^^^^^^^^^^^^^^^^^^^^^^^^^^^^^^^^^^^^^^^^^^^^
  File "<frozen importlib._bootstrap>", line 1387, in _gcd_import
  File "<frozen importlib._bootstrap>", line 1360, in _find_and_load
  File "<frozen importlib._bootstrap>", line 1331, in _find_and_load_unlocked
  File "<frozen importlib._bootstrap>", line 935, in _load_unlocked
  File "<frozen importlib._bootstrap_external>", line 999, in exec_module
  File "<frozen importlib._bootstrap>", line 488, in _call_with_frames_removed
  File "/home3/sambegkhatiwada/Django-portfolio/webportfolio/webportfolio/urls.py", line 5, in <module>
    urlpatterns += static(settings.MEDIA_URL, document_root=settings.MEDIA_ROOT)
    ^^^^^^^^^^^
NameError: name 'urlpatterns' is not defined

During handling of the above exception, another exception occurred:

Traceback (most recent call last):
  File "/home3/sambegkhatiwada/virtualenv/Django-portfolio/webportfolio/3.12/lib/python3.12/site-packages/django/core/handlers/exception.py", line 55, in inner
    response = get_response(request)
               ^^^^^^^^^^^^^^^^^^^^^
  File "/home3/sambegkhatiwada/virtualenv/Django-portfolio/webportfolio/3.12/lib/python3.12/site-packages/django/utils/deprecation.py", line 120, in __call__
    response = response or self.get_response(request)
                           ^^^^^^^^^^^^^^^^^^^^^^^^^^
  File "/home3/sambegkhatiwada/virtualenv/Django-portfolio/webportfolio/3.12/lib/python3.12/site-packages/django/core/handlers/exception.py", line 57, in inner
    response = response_for_exception(request, exc)
               ^^^^^^^^^^^^^^^^^^^^^^^^^^^^^^^^^^^^
  File "/home3/sambegkhatiwada/virtualenv/Django-portfolio/webportfolio/3.12/lib/python3.12/site-packages/django/core/handlers/exception.py", line 140, in response_for_exception
    response = handle_uncaught_exception(
               ^^^^^^^^^^^^^^^^^^^^^^^^^^
  File "/home3/sambegkhatiwada/virtualenv/Django-portfolio/webportfolio/3.12/lib/python3.12/site-packages/django/core/handlers/exception.py", line 181, in handle_uncaught_exception
    return debug.technical_500_response(request, *exc_info)
           ^^^^^^^^^^^^^^^^^^^^^^^^^^^^^^^^^^^^^^^^^^^^^^^^
  File "/home3/sambegkhatiwada/virtualenv/Django-portfolio/webportfolio/3.12/lib/python3.12/site-packages/django/views/debug.py", line 69, in technical_500_response
    html = reporter.get_traceback_html()
           ^^^^^^^^^^^^^^^^^^^^^^^^^^^^^
  File "/home3/sambegkhatiwada/virtualenv/Django-portfolio/webportfolio/3.12/lib/python3.12/site-packages/django/views/debug.py", line 428, in get_traceback_html
    c = Context(self.get_traceback_data(), use_l10n=False)
                ^^^^^^^^^^^^^^^^^^^^^^^^^
  File "/home3/sambegkhatiwada/virtualenv/Django-portfolio/webportfolio/3.12/lib/python3.12/site-packages/django/views/debug.py", line 411, in get_traceback_data
    c["raising_view_name"] = get_caller(self.request)
                             ^^^^^^^^^^^^^^^^^^^^^^^^
  File "/home3/sambegkhatiwada/virtualenv/Django-portfolio/webportfolio/3.12/lib/python3.12/site-packages/django/views/debug.py", line 102, in get_caller
    resolver_match = resolve(request.path)
                     ^^^^^^^^^^^^^^^^^^^^^
  File "/home3/sambegkhatiwada/virtualenv/Django-portfolio/webportfolio/3.12/lib/python3.12/site-packages/django/urls/base.py", line 25, in resolve
    return get_resolver(urlconf).resolve(path)
           ^^^^^^^^^^^^^^^^^^^^^^^^^^^^^^^^^^^
  File "/home3/sambegkhatiwada/virtualenv/Django-portfolio/webportfolio/3.12/lib/python3.12/site-packages/django/urls/resolvers.py", line 666, in resolve
    for pattern in self.url_patterns:
                   ^^^^^^^^^^^^^^^^^
  File "/home3/sambegkhatiwada/virtualenv/Django-portfolio/webportfolio/3.12/lib/python3.12/site-packages/django/utils/functional.py", line 47, in __get__
    res = instance.__dict__[self.name] = self.func(instance)
                                         ^^^^^^^^^^^^^^^^^^^
  File "/home3/sambegkhatiwada/virtualenv/Django-portfolio/webportfolio/3.12/lib/python3.12/site-packages/django/urls/resolvers.py", line 718, in url_patterns
    patterns = getattr(self.urlconf_module, "urlpatterns", self.urlconf_module)
                       ^^^^^^^^^^^^^^^^^^^
  File "/home3/sambegkhatiwada/virtualenv/Django-portfolio/webportfolio/3.12/lib/python3.12/site-packages/django/utils/functional.py", line 47, in __get__
    res = instance.__dict__[self.name] = self.func(instance)
                                         ^^^^^^^^^^^^^^^^^^^
  File "/home3/sambegkhatiwada/virtualenv/Django-portfolio/webportfolio/3.12/lib/python3.12/site-packages/django/urls/resolvers.py", line 711, in urlconf_module
    return import_module(self.urlconf_name)
           ^^^^^^^^^^^^^^^^^^^^^^^^^^^^^^^^
  File "/opt/alt/python312/lib64/python3.12/importlib/__init__.py", line 90, in import_module
    return _bootstrap._gcd_import(name[level:], package, level)
           ^^^^^^^^^^^^^^^^^^^^^^^^^^^^^^^^^^^^^^^^^^^^^^^^^^^^
  File "<frozen importlib._bootstrap>", line 1387, in _gcd_import
  File "<frozen importlib._bootstrap>", line 1360, in _find_and_load
  File "<frozen importlib._bootstrap>", line 1331, in _find_and_load_unlocked
  File "<frozen importlib._bootstrap>", line 935, in _load_unlocked
  File "<frozen importlib._bootstrap_external>", line 999, in exec_module
  File "<frozen importlib._bootstrap>", line 488, in _call_with_frames_removed
  File "/home3/sambegkhatiwada/Django-portfolio/webportfolio/webportfolio/urls.py", line 5, in <module>
    urlpatterns += static(settings.MEDIA_URL, document_root=settings.MEDIA_ROOT)
    ^^^^^^^^^^^
NameError: name 'urlpatterns' is not defined

During handling of the above exception, another exception occurred:

Traceback (most recent call last):
  File "/home3/sambegkhatiwada/virtualenv/Django-portfolio/webportfolio/3.12/lib/python3.12/site-packages/django/core/handlers/wsgi.py", line 124, in __call__
    response = self.get_response(request)
               ^^^^^^^^^^^^^^^^^^^^^^^^^^
  File "/home3/sambegkhatiwada/virtualenv/Django-portfolio/webportfolio/3.12/lib/python3.12/site-packages/django/core/handlers/base.py", line 140, in get_response
    response = self._middleware_chain(request)
               ^^^^^^^^^^^^^^^^^^^^^^^^^^^^^^^
  File "/home3/sambegkhatiwada/virtualenv/Django-portfolio/webportfolio/3.12/lib/python3.12/site-packages/django/core/handlers/exception.py", line 57, in inner
    response = response_for_exception(request, exc)
               ^^^^^^^^^^^^^^^^^^^^^^^^^^^^^^^^^^^^
  File "/home3/sambegkhatiwada/virtualenv/Django-portfolio/webportfolio/3.12/lib/python3.12/site-packages/django/core/handlers/exception.py", line 140, in response_for_exception
    response = handle_uncaught_exception(
               ^^^^^^^^^^^^^^^^^^^^^^^^^^
  File "/home3/sambegkhatiwada/virtualenv/Django-portfolio/webportfolio/3.12/lib/python3.12/site-packages/django/core/handlers/exception.py", line 181, in handle_uncaught_exception
    return debug.technical_500_response(request, *exc_info)
           ^^^^^^^^^^^^^^^^^^^^^^^^^^^^^^^^^^^^^^^^^^^^^^^^
  File "/home3/sambegkhatiwada/virtualenv/Django-portfolio/webportfolio/3.12/lib/python3.12/site-packages/django/views/debug.py", line 69, in technical_500_response
    html = reporter.get_traceback_html()
           ^^^^^^^^^^^^^^^^^^^^^^^^^^^^^
  File "/home3/sambegkhatiwada/virtualenv/Django-portfolio/webportfolio/3.12/lib/python3.12/site-packages/django/views/debug.py", line 428, in get_traceback_html
    c = Context(self.get_traceback_data(), use_l10n=False)
                ^^^^^^^^^^^^^^^^^^^^^^^^^
  File "/home3/sambegkhatiwada/virtualenv/Django-portfolio/webportfolio/3.12/lib/python3.12/site-packages/django/views/debug.py", line 411, in get_traceback_data
    c["raising_view_name"] = get_caller(self.request)
                             ^^^^^^^^^^^^^^^^^^^^^^^^
  File "/home3/sambegkhatiwada/virtualenv/Django-portfolio/webportfolio/3.12/lib/python3.12/site-packages/django/views/debug.py", line 102, in get_caller
    resolver_match = resolve(request.path)
                     ^^^^^^^^^^^^^^^^^^^^^
  File "/home3/sambegkhatiwada/virtualenv/Django-portfolio/webportfolio/3.12/lib/python3.12/site-packages/django/urls/base.py", line 25, in resolve
    return get_resolver(urlconf).resolve(path)
           ^^^^^^^^^^^^^^^^^^^^^^^^^^^^^^^^^^^
  File "/home3/sambegkhatiwada/virtualenv/Django-portfolio/webportfolio/3.12/lib/python3.12/site-packages/django/urls/resolvers.py", line 666, in resolve
    for pattern in self.url_patterns:
                   ^^^^^^^^^^^^^^^^^
  File "/home3/sambegkhatiwada/virtualenv/Django-portfolio/webportfolio/3.12/lib/python3.12/site-packages/django/utils/functional.py", line 47, in __get__
    res = instance.__dict__[self.name] = self.func(instance)
                                         ^^^^^^^^^^^^^^^^^^^
  File "/home3/sambegkhatiwada/virtualenv/Django-portfolio/webportfolio/3.12/lib/python3.12/site-packages/django/urls/resolvers.py", line 718, in url_patterns
    patterns = getattr(self.urlconf_module, "urlpatterns", self.urlconf_module)
                       ^^^^^^^^^^^^^^^^^^^
  File "/home3/sambegkhatiwada/virtualenv/Django-portfolio/webportfolio/3.12/lib/python3.12/site-packages/django/utils/functional.py", line 47, in __get__
    res = instance.__dict__[self.name] = self.func(instance)
                                         ^^^^^^^^^^^^^^^^^^^
  File "/home3/sambegkhatiwada/virtualenv/Django-portfolio/webportfolio/3.12/lib/python3.12/site-packages/django/urls/resolvers.py", line 711, in urlconf_module
    return import_module(self.urlconf_name)
           ^^^^^^^^^^^^^^^^^^^^^^^^^^^^^^^^
  File "/opt/alt/python312/lib64/python3.12/importlib/__init__.py", line 90, in import_module
    return _bootstrap._gcd_import(name[level:], package, level)
           ^^^^^^^^^^^^^^^^^^^^^^^^^^^^^^^^^^^^^^^^^^^^^^^^^^^^
  File "<frozen importlib._bootstrap>", line 1387, in _gcd_import
  File "<frozen importlib._bootstrap>", line 1360, in _find_and_load
  File "<frozen importlib._bootstrap>", line 1331, in _find_and_load_unlocked
  File "<frozen importlib._bootstrap>", line 935, in _load_unlocked
  File "<frozen importlib._bootstrap_external>", line 999, in exec_module
  File "<frozen importlib._bootstrap>", line 488, in _call_with_frames_removed
  File "/home3/sambegkhatiwada/Django-portfolio/webportfolio/webportfolio/urls.py", line 5, in <module>
    urlpatterns += static(settings.MEDIA_URL, document_root=settings.MEDIA_ROOT)
    ^^^^^^^^^^^
NameError: name 'urlpatterns' is not defined
[ERROR] [UID:1370][1234422] wsgiAppHandler pApp->start_response() return NULL.
Traceback (most recent call last):
  File "/home3/sambegkhatiwada/virtualenv/Django-portfolio/webportfolio/3.12/lib/python3.12/site-packages/django/core/handlers/exception.py", line 55, in inner
    response = get_response(request)
               ^^^^^^^^^^^^^^^^^^^^^
  File "/home3/sambegkhatiwada/virtualenv/Django-portfolio/webportfolio/3.12/lib/python3.12/site-packages/django/core/handlers/base.py", line 181, in _get_response
    callback, callback_args, callback_kwargs = self.resolve_request(request)
                                               ^^^^^^^^^^^^^^^^^^^^^^^^^^^^^
  File "/home3/sambegkhatiwada/virtualenv/Django-portfolio/webportfolio/3.12/lib/python3.12/site-packages/django/core/handlers/base.py", line 313, in resolve_request
    resolver_match = resolver.resolve(request.path_info)
                     ^^^^^^^^^^^^^^^^^^^^^^^^^^^^^^^^^^^
  File "/home3/sambegkhatiwada/virtualenv/Django-portfolio/webportfolio/3.12/lib/python3.12/site-packages/django/urls/resolvers.py", line 666, in resolve
    for pattern in self.url_patterns:
                   ^^^^^^^^^^^^^^^^^
  File "/home3/sambegkhatiwada/virtualenv/Django-portfolio/webportfolio/3.12/lib/python3.12/site-packages/django/utils/functional.py", line 47, in __get__
    res = instance.__dict__[self.name] = self.func(instance)
                                         ^^^^^^^^^^^^^^^^^^^
  File "/home3/sambegkhatiwada/virtualenv/Django-portfolio/webportfolio/3.12/lib/python3.12/site-packages/django/urls/resolvers.py", line 718, in url_patterns
    patterns = getattr(self.urlconf_module, "urlpatterns", self.urlconf_module)
                       ^^^^^^^^^^^^^^^^^^^
  File "/home3/sambegkhatiwada/virtualenv/Django-portfolio/webportfolio/3.12/lib/python3.12/site-packages/django/utils/functional.py", line 47, in __get__
    res = instance.__dict__[self.name] = self.func(instance)
                                         ^^^^^^^^^^^^^^^^^^^
  File "/home3/sambegkhatiwada/virtualenv/Django-portfolio/webportfolio/3.12/lib/python3.12/site-packages/django/urls/resolvers.py", line 711, in urlconf_module
    return import_module(self.urlconf_name)
           ^^^^^^^^^^^^^^^^^^^^^^^^^^^^^^^^
  File "/opt/alt/python312/lib64/python3.12/importlib/__init__.py", line 90, in import_module
    return _bootstrap._gcd_import(name[level:], package, level)
           ^^^^^^^^^^^^^^^^^^^^^^^^^^^^^^^^^^^^^^^^^^^^^^^^^^^^
  File "<frozen importlib._bootstrap>", line 1387, in _gcd_import
  File "<frozen importlib._bootstrap>", line 1360, in _find_and_load
  File "<frozen importlib._bootstrap>", line 1331, in _find_and_load_unlocked
  File "<frozen importlib._bootstrap>", line 935, in _load_unlocked
  File "<frozen importlib._bootstrap_external>", line 999, in exec_module
  File "<frozen importlib._bootstrap>", line 488, in _call_with_frames_removed
  File "/home3/sambegkhatiwada/Django-portfolio/webportfolio/webportfolio/urls.py", line 5, in <module>
    urlpatterns += static(settings.MEDIA_URL, document_root=settings.MEDIA_ROOT)
    ^^^^^^^^^^^
NameError: name 'urlpatterns' is not defined

During handling of the above exception, another exception occurred:

Traceback (most recent call last):
  File "/home3/sambegkhatiwada/virtualenv/Django-portfolio/webportfolio/3.12/lib/python3.12/site-packages/django/core/handlers/exception.py", line 55, in inner
    response = get_response(request)
               ^^^^^^^^^^^^^^^^^^^^^
  File "/home3/sambegkhatiwada/virtualenv/Django-portfolio/webportfolio/3.12/lib/python3.12/site-packages/django/utils/deprecation.py", line 120, in __call__
    response = response or self.get_response(request)
                           ^^^^^^^^^^^^^^^^^^^^^^^^^^
  File "/home3/sambegkhatiwada/virtualenv/Django-portfolio/webportfolio/3.12/lib/python3.12/site-packages/django/core/handlers/exception.py", line 57, in inner
    response = response_for_exception(request, exc)
               ^^^^^^^^^^^^^^^^^^^^^^^^^^^^^^^^^^^^
  File "/home3/sambegkhatiwada/virtualenv/Django-portfolio/webportfolio/3.12/lib/python3.12/site-packages/django/core/handlers/exception.py", line 140, in response_for_exception
    response = handle_uncaught_exception(
               ^^^^^^^^^^^^^^^^^^^^^^^^^^
  File "/home3/sambegkhatiwada/virtualenv/Django-portfolio/webportfolio/3.12/lib/python3.12/site-packages/django/core/handlers/exception.py", line 181, in handle_uncaught_exception
    return debug.technical_500_response(request, *exc_info)
           ^^^^^^^^^^^^^^^^^^^^^^^^^^^^^^^^^^^^^^^^^^^^^^^^
  File "/home3/sambegkhatiwada/virtualenv/Django-portfolio/webportfolio/3.12/lib/python3.12/site-packages/django/views/debug.py", line 69, in technical_500_response
    html = reporter.get_traceback_html()
           ^^^^^^^^^^^^^^^^^^^^^^^^^^^^^
  File "/home3/sambegkhatiwada/virtualenv/Django-portfolio/webportfolio/3.12/lib/python3.12/site-packages/django/views/debug.py", line 428, in get_traceback_html
    c = Context(self.get_traceback_data(), use_l10n=False)
                ^^^^^^^^^^^^^^^^^^^^^^^^^
  File "/home3/sambegkhatiwada/virtualenv/Django-portfolio/webportfolio/3.12/lib/python3.12/site-packages/django/views/debug.py", line 411, in get_traceback_data
    c["raising_view_name"] = get_caller(self.request)
                             ^^^^^^^^^^^^^^^^^^^^^^^^
  File "/home3/sambegkhatiwada/virtualenv/Django-portfolio/webportfolio/3.12/lib/python3.12/site-packages/django/views/debug.py", line 102, in get_caller
    resolver_match = resolve(request.path)
                     ^^^^^^^^^^^^^^^^^^^^^
  File "/home3/sambegkhatiwada/virtualenv/Django-portfolio/webportfolio/3.12/lib/python3.12/site-packages/django/urls/base.py", line 25, in resolve
    return get_resolver(urlconf).resolve(path)
           ^^^^^^^^^^^^^^^^^^^^^^^^^^^^^^^^^^^
  File "/home3/sambegkhatiwada/virtualenv/Django-portfolio/webportfolio/3.12/lib/python3.12/site-packages/django/urls/resolvers.py", line 666, in resolve
    for pattern in self.url_patterns:
                   ^^^^^^^^^^^^^^^^^
  File "/home3/sambegkhatiwada/virtualenv/Django-portfolio/webportfolio/3.12/lib/python3.12/site-packages/django/utils/functional.py", line 47, in __get__
    res = instance.__dict__[self.name] = self.func(instance)
                                         ^^^^^^^^^^^^^^^^^^^
  File "/home3/sambegkhatiwada/virtualenv/Django-portfolio/webportfolio/3.12/lib/python3.12/site-packages/django/urls/resolvers.py", line 718, in url_patterns
    patterns = getattr(self.urlconf_module, "urlpatterns", self.urlconf_module)
                       ^^^^^^^^^^^^^^^^^^^
  File "/home3/sambegkhatiwada/virtualenv/Django-portfolio/webportfolio/3.12/lib/python3.12/site-packages/django/utils/functional.py", line 47, in __get__
    res = instance.__dict__[self.name] = self.func(instance)
                                         ^^^^^^^^^^^^^^^^^^^
  File "/home3/sambegkhatiwada/virtualenv/Django-portfolio/webportfolio/3.12/lib/python3.12/site-packages/django/urls/resolvers.py", line 711, in urlconf_module
    return import_module(self.urlconf_name)
           ^^^^^^^^^^^^^^^^^^^^^^^^^^^^^^^^
  File "/opt/alt/python312/lib64/python3.12/importlib/__init__.py", line 90, in import_module
    return _bootstrap._gcd_import(name[level:], package, level)
           ^^^^^^^^^^^^^^^^^^^^^^^^^^^^^^^^^^^^^^^^^^^^^^^^^^^^
  File "<frozen importlib._bootstrap>", line 1387, in _gcd_import
  File "<frozen importlib._bootstrap>", line 1360, in _find_and_load
  File "<frozen importlib._bootstrap>", line 1331, in _find_and_load_unlocked
  File "<frozen importlib._bootstrap>", line 935, in _load_unlocked
  File "<frozen importlib._bootstrap_external>", line 999, in exec_module
  File "<frozen importlib._bootstrap>", line 488, in _call_with_frames_removed
  File "/home3/sambegkhatiwada/Django-portfolio/webportfolio/webportfolio/urls.py", line 5, in <module>
    urlpatterns += static(settings.MEDIA_URL, document_root=settings.MEDIA_ROOT)
    ^^^^^^^^^^^
NameError: name 'urlpatterns' is not defined

During handling of the above exception, another exception occurred:

Traceback (most recent call last):
  File "/home3/sambegkhatiwada/virtualenv/Django-portfolio/webportfolio/3.12/lib/python3.12/site-packages/django/core/handlers/exception.py", line 55, in inner
    response = get_response(request)
               ^^^^^^^^^^^^^^^^^^^^^
  File "/home3/sambegkhatiwada/virtualenv/Django-portfolio/webportfolio/3.12/lib/python3.12/site-packages/django/utils/deprecation.py", line 120, in __call__
    response = response or self.get_response(request)
                           ^^^^^^^^^^^^^^^^^^^^^^^^^^
  File "/home3/sambegkhatiwada/virtualenv/Django-portfolio/webportfolio/3.12/lib/python3.12/site-packages/django/core/handlers/exception.py", line 57, in inner
    response = response_for_exception(request, exc)
               ^^^^^^^^^^^^^^^^^^^^^^^^^^^^^^^^^^^^
  File "/home3/sambegkhatiwada/virtualenv/Django-portfolio/webportfolio/3.12/lib/python3.12/site-packages/django/core/handlers/exception.py", line 140, in response_for_exception
    response = handle_uncaught_exception(
               ^^^^^^^^^^^^^^^^^^^^^^^^^^
  File "/home3/sambegkhatiwada/virtualenv/Django-portfolio/webportfolio/3.12/lib/python3.12/site-packages/django/core/handlers/exception.py", line 181, in handle_uncaught_exception
    return debug.technical_500_response(request, *exc_info)
           ^^^^^^^^^^^^^^^^^^^^^^^^^^^^^^^^^^^^^^^^^^^^^^^^
  File "/home3/sambegkhatiwada/virtualenv/Django-portfolio/webportfolio/3.12/lib/python3.12/site-packages/django/views/debug.py", line 69, in technical_500_response
    html = reporter.get_traceback_html()
           ^^^^^^^^^^^^^^^^^^^^^^^^^^^^^
  File "/home3/sambegkhatiwada/virtualenv/Django-portfolio/webportfolio/3.12/lib/python3.12/site-packages/django/views/debug.py", line 428, in get_traceback_html
    c = Context(self.get_traceback_data(), use_l10n=False)
                ^^^^^^^^^^^^^^^^^^^^^^^^^
  File "/home3/sambegkhatiwada/virtualenv/Django-portfolio/webportfolio/3.12/lib/python3.12/site-packages/django/views/debug.py", line 411, in get_traceback_data
    c["raising_view_name"] = get_caller(self.request)
                             ^^^^^^^^^^^^^^^^^^^^^^^^
  File "/home3/sambegkhatiwada/virtualenv/Django-portfolio/webportfolio/3.12/lib/python3.12/site-packages/django/views/debug.py", line 102, in get_caller
    resolver_match = resolve(request.path)
                     ^^^^^^^^^^^^^^^^^^^^^
  File "/home3/sambegkhatiwada/virtualenv/Django-portfolio/webportfolio/3.12/lib/python3.12/site-packages/django/urls/base.py", line 25, in resolve
    return get_resolver(urlconf).resolve(path)
           ^^^^^^^^^^^^^^^^^^^^^^^^^^^^^^^^^^^
  File "/home3/sambegkhatiwada/virtualenv/Django-portfolio/webportfolio/3.12/lib/python3.12/site-packages/django/urls/resolvers.py", line 666, in resolve
    for pattern in self.url_patterns:
                   ^^^^^^^^^^^^^^^^^
  File "/home3/sambegkhatiwada/virtualenv/Django-portfolio/webportfolio/3.12/lib/python3.12/site-packages/django/utils/functional.py", line 47, in __get__
    res = instance.__dict__[self.name] = self.func(instance)
                                         ^^^^^^^^^^^^^^^^^^^
  File "/home3/sambegkhatiwada/virtualenv/Django-portfolio/webportfolio/3.12/lib/python3.12/site-packages/django/urls/resolvers.py", line 718, in url_patterns
    patterns = getattr(self.urlconf_module, "urlpatterns", self.urlconf_module)
                       ^^^^^^^^^^^^^^^^^^^
  File "/home3/sambegkhatiwada/virtualenv/Django-portfolio/webportfolio/3.12/lib/python3.12/site-packages/django/utils/functional.py", line 47, in __get__
    res = instance.__dict__[self.name] = self.func(instance)
                                         ^^^^^^^^^^^^^^^^^^^
  File "/home3/sambegkhatiwada/virtualenv/Django-portfolio/webportfolio/3.12/lib/python3.12/site-packages/django/urls/resolvers.py", line 711, in urlconf_module
    return import_module(self.urlconf_name)
           ^^^^^^^^^^^^^^^^^^^^^^^^^^^^^^^^
  File "/opt/alt/python312/lib64/python3.12/importlib/__init__.py", line 90, in import_module
    return _bootstrap._gcd_import(name[level:], package, level)
           ^^^^^^^^^^^^^^^^^^^^^^^^^^^^^^^^^^^^^^^^^^^^^^^^^^^^
  File "<frozen importlib._bootstrap>", line 1387, in _gcd_import
  File "<frozen importlib._bootstrap>", line 1360, in _find_and_load
  File "<frozen importlib._bootstrap>", line 1331, in _find_and_load_unlocked
  File "<frozen importlib._bootstrap>", line 935, in _load_unlocked
  File "<frozen importlib._bootstrap_external>", line 999, in exec_module
  File "<frozen importlib._bootstrap>", line 488, in _call_with_frames_removed
  File "/home3/sambegkhatiwada/Django-portfolio/webportfolio/webportfolio/urls.py", line 5, in <module>
    urlpatterns += static(settings.MEDIA_URL, document_root=settings.MEDIA_ROOT)
    ^^^^^^^^^^^
NameError: name 'urlpatterns' is not defined

During handling of the above exception, another exception occurred:

Traceback (most recent call last):
  File "/home3/sambegkhatiwada/virtualenv/Django-portfolio/webportfolio/3.12/lib/python3.12/site-packages/django/core/handlers/exception.py", line 55, in inner
    response = get_response(request)
               ^^^^^^^^^^^^^^^^^^^^^
  File "/home3/sambegkhatiwada/virtualenv/Django-portfolio/webportfolio/3.12/lib/python3.12/site-packages/django/utils/deprecation.py", line 120, in __call__
    response = response or self.get_response(request)
                           ^^^^^^^^^^^^^^^^^^^^^^^^^^
  File "/home3/sambegkhatiwada/virtualenv/Django-portfolio/webportfolio/3.12/lib/python3.12/site-packages/django/core/handlers/exception.py", line 57, in inner
    response = response_for_exception(request, exc)
               ^^^^^^^^^^^^^^^^^^^^^^^^^^^^^^^^^^^^
  File "/home3/sambegkhatiwada/virtualenv/Django-portfolio/webportfolio/3.12/lib/python3.12/site-packages/django/core/handlers/exception.py", line 140, in response_for_exception
    response = handle_uncaught_exception(
               ^^^^^^^^^^^^^^^^^^^^^^^^^^
  File "/home3/sambegkhatiwada/virtualenv/Django-portfolio/webportfolio/3.12/lib/python3.12/site-packages/django/core/handlers/exception.py", line 181, in handle_uncaught_exception
    return debug.technical_500_response(request, *exc_info)
           ^^^^^^^^^^^^^^^^^^^^^^^^^^^^^^^^^^^^^^^^^^^^^^^^
  File "/home3/sambegkhatiwada/virtualenv/Django-portfolio/webportfolio/3.12/lib/python3.12/site-packages/django/views/debug.py", line 69, in technical_500_response
    html = reporter.get_traceback_html()
           ^^^^^^^^^^^^^^^^^^^^^^^^^^^^^
  File "/home3/sambegkhatiwada/virtualenv/Django-portfolio/webportfolio/3.12/lib/python3.12/site-packages/django/views/debug.py", line 428, in get_traceback_html
    c = Context(self.get_traceback_data(), use_l10n=False)
                ^^^^^^^^^^^^^^^^^^^^^^^^^
  File "/home3/sambegkhatiwada/virtualenv/Django-portfolio/webportfolio/3.12/lib/python3.12/site-packages/django/views/debug.py", line 411, in get_traceback_data
    c["raising_view_name"] = get_caller(self.request)
                             ^^^^^^^^^^^^^^^^^^^^^^^^
  File "/home3/sambegkhatiwada/virtualenv/Django-portfolio/webportfolio/3.12/lib/python3.12/site-packages/django/views/debug.py", line 102, in get_caller
    resolver_match = resolve(request.path)
                     ^^^^^^^^^^^^^^^^^^^^^
  File "/home3/sambegkhatiwada/virtualenv/Django-portfolio/webportfolio/3.12/lib/python3.12/site-packages/django/urls/base.py", line 25, in resolve
    return get_resolver(urlconf).resolve(path)
           ^^^^^^^^^^^^^^^^^^^^^^^^^^^^^^^^^^^
  File "/home3/sambegkhatiwada/virtualenv/Django-portfolio/webportfolio/3.12/lib/python3.12/site-packages/django/urls/resolvers.py", line 666, in resolve
    for pattern in self.url_patterns:
                   ^^^^^^^^^^^^^^^^^
  File "/home3/sambegkhatiwada/virtualenv/Django-portfolio/webportfolio/3.12/lib/python3.12/site-packages/django/utils/functional.py", line 47, in __get__
    res = instance.__dict__[self.name] = self.func(instance)
                                         ^^^^^^^^^^^^^^^^^^^
  File "/home3/sambegkhatiwada/virtualenv/Django-portfolio/webportfolio/3.12/lib/python3.12/site-packages/django/urls/resolvers.py", line 718, in url_patterns
    patterns = getattr(self.urlconf_module, "urlpatterns", self.urlconf_module)
                       ^^^^^^^^^^^^^^^^^^^
  File "/home3/sambegkhatiwada/virtualenv/Django-portfolio/webportfolio/3.12/lib/python3.12/site-packages/django/utils/functional.py", line 47, in __get__
    res = instance.__dict__[self.name] = self.func(instance)
                                         ^^^^^^^^^^^^^^^^^^^
  File "/home3/sambegkhatiwada/virtualenv/Django-portfolio/webportfolio/3.12/lib/python3.12/site-packages/django/urls/resolvers.py", line 711, in urlconf_module
    return import_module(self.urlconf_name)
           ^^^^^^^^^^^^^^^^^^^^^^^^^^^^^^^^
  File "/opt/alt/python312/lib64/python3.12/importlib/__init__.py", line 90, in import_module
    return _bootstrap._gcd_import(name[level:], package, level)
           ^^^^^^^^^^^^^^^^^^^^^^^^^^^^^^^^^^^^^^^^^^^^^^^^^^^^
  File "<frozen importlib._bootstrap>", line 1387, in _gcd_import
  File "<frozen importlib._bootstrap>", line 1360, in _find_and_load
  File "<frozen importlib._bootstrap>", line 1331, in _find_and_load_unlocked
  File "<frozen importlib._bootstrap>", line 935, in _load_unlocked
  File "<frozen importlib._bootstrap_external>", line 999, in exec_module
  File "<frozen importlib._bootstrap>", line 488, in _call_with_frames_removed
  File "/home3/sambegkhatiwada/Django-portfolio/webportfolio/webportfolio/urls.py", line 5, in <module>
    urlpatterns += static(settings.MEDIA_URL, document_root=settings.MEDIA_ROOT)
    ^^^^^^^^^^^
NameError: name 'urlpatterns' is not defined

During handling of the above exception, another exception occurred:

Traceback (most recent call last):
  File "/home3/sambegkhatiwada/virtualenv/Django-portfolio/webportfolio/3.12/lib/python3.12/site-packages/django/core/handlers/exception.py", line 55, in inner
    response = get_response(request)
               ^^^^^^^^^^^^^^^^^^^^^
  File "/home3/sambegkhatiwada/virtualenv/Django-portfolio/webportfolio/3.12/lib/python3.12/site-packages/django/utils/deprecation.py", line 120, in __call__
    response = response or self.get_response(request)
                           ^^^^^^^^^^^^^^^^^^^^^^^^^^
  File "/home3/sambegkhatiwada/virtualenv/Django-portfolio/webportfolio/3.12/lib/python3.12/site-packages/django/core/handlers/exception.py", line 57, in inner
    response = response_for_exception(request, exc)
               ^^^^^^^^^^^^^^^^^^^^^^^^^^^^^^^^^^^^
  File "/home3/sambegkhatiwada/virtualenv/Django-portfolio/webportfolio/3.12/lib/python3.12/site-packages/django/core/handlers/exception.py", line 140, in response_for_exception
    response = handle_uncaught_exception(
               ^^^^^^^^^^^^^^^^^^^^^^^^^^
  File "/home3/sambegkhatiwada/virtualenv/Django-portfolio/webportfolio/3.12/lib/python3.12/site-packages/django/core/handlers/exception.py", line 181, in handle_uncaught_exception
    return debug.technical_500_response(request, *exc_info)
           ^^^^^^^^^^^^^^^^^^^^^^^^^^^^^^^^^^^^^^^^^^^^^^^^
  File "/home3/sambegkhatiwada/virtualenv/Django-portfolio/webportfolio/3.12/lib/python3.12/site-packages/django/views/debug.py", line 69, in technical_500_response
    html = reporter.get_traceback_html()
           ^^^^^^^^^^^^^^^^^^^^^^^^^^^^^
  File "/home3/sambegkhatiwada/virtualenv/Django-portfolio/webportfolio/3.12/lib/python3.12/site-packages/django/views/debug.py", line 428, in get_traceback_html
    c = Context(self.get_traceback_data(), use_l10n=False)
                ^^^^^^^^^^^^^^^^^^^^^^^^^
  File "/home3/sambegkhatiwada/virtualenv/Django-portfolio/webportfolio/3.12/lib/python3.12/site-packages/django/views/debug.py", line 411, in get_traceback_data
    c["raising_view_name"] = get_caller(self.request)
                             ^^^^^^^^^^^^^^^^^^^^^^^^
  File "/home3/sambegkhatiwada/virtualenv/Django-portfolio/webportfolio/3.12/lib/python3.12/site-packages/django/views/debug.py", line 102, in get_caller
    resolver_match = resolve(request.path)
                     ^^^^^^^^^^^^^^^^^^^^^
  File "/home3/sambegkhatiwada/virtualenv/Django-portfolio/webportfolio/3.12/lib/python3.12/site-packages/django/urls/base.py", line 25, in resolve
    return get_resolver(urlconf).resolve(path)
           ^^^^^^^^^^^^^^^^^^^^^^^^^^^^^^^^^^^
  File "/home3/sambegkhatiwada/virtualenv/Django-portfolio/webportfolio/3.12/lib/python3.12/site-packages/django/urls/resolvers.py", line 666, in resolve
    for pattern in self.url_patterns:
                   ^^^^^^^^^^^^^^^^^
  File "/home3/sambegkhatiwada/virtualenv/Django-portfolio/webportfolio/3.12/lib/python3.12/site-packages/django/utils/functional.py", line 47, in __get__
    res = instance.__dict__[self.name] = self.func(instance)
                                         ^^^^^^^^^^^^^^^^^^^
  File "/home3/sambegkhatiwada/virtualenv/Django-portfolio/webportfolio/3.12/lib/python3.12/site-packages/django/urls/resolvers.py", line 718, in url_patterns
    patterns = getattr(self.urlconf_module, "urlpatterns", self.urlconf_module)
                       ^^^^^^^^^^^^^^^^^^^
  File "/home3/sambegkhatiwada/virtualenv/Django-portfolio/webportfolio/3.12/lib/python3.12/site-packages/django/utils/functional.py", line 47, in __get__
    res = instance.__dict__[self.name] = self.func(instance)
                                         ^^^^^^^^^^^^^^^^^^^
  File "/home3/sambegkhatiwada/virtualenv/Django-portfolio/webportfolio/3.12/lib/python3.12/site-packages/django/urls/resolvers.py", line 711, in urlconf_module
    return import_module(self.urlconf_name)
           ^^^^^^^^^^^^^^^^^^^^^^^^^^^^^^^^
  File "/opt/alt/python312/lib64/python3.12/importlib/__init__.py", line 90, in import_module
    return _bootstrap._gcd_import(name[level:], package, level)
           ^^^^^^^^^^^^^^^^^^^^^^^^^^^^^^^^^^^^^^^^^^^^^^^^^^^^
  File "<frozen importlib._bootstrap>", line 1387, in _gcd_import
  File "<frozen importlib._bootstrap>", line 1360, in _find_and_load
  File "<frozen importlib._bootstrap>", line 1331, in _find_and_load_unlocked
  File "<frozen importlib._bootstrap>", line 935, in _load_unlocked
  File "<frozen importlib._bootstrap_external>", line 999, in exec_module
  File "<frozen importlib._bootstrap>", line 488, in _call_with_frames_removed
  File "/home3/sambegkhatiwada/Django-portfolio/webportfolio/webportfolio/urls.py", line 5, in <module>
    urlpatterns += static(settings.MEDIA_URL, document_root=settings.MEDIA_ROOT)
    ^^^^^^^^^^^
NameError: name 'urlpatterns' is not defined

During handling of the above exception, another exception occurred:

Traceback (most recent call last):
  File "/home3/sambegkhatiwada/virtualenv/Django-portfolio/webportfolio/3.12/lib/python3.12/site-packages/django/core/handlers/exception.py", line 55, in inner
    response = get_response(request)
               ^^^^^^^^^^^^^^^^^^^^^
  File "/home3/sambegkhatiwada/virtualenv/Django-portfolio/webportfolio/3.12/lib/python3.12/site-packages/django/utils/deprecation.py", line 120, in __call__
    response = response or self.get_response(request)
                           ^^^^^^^^^^^^^^^^^^^^^^^^^^
  File "/home3/sambegkhatiwada/virtualenv/Django-portfolio/webportfolio/3.12/lib/python3.12/site-packages/django/core/handlers/exception.py", line 57, in inner
    response = response_for_exception(request, exc)
               ^^^^^^^^^^^^^^^^^^^^^^^^^^^^^^^^^^^^
  File "/home3/sambegkhatiwada/virtualenv/Django-portfolio/webportfolio/3.12/lib/python3.12/site-packages/django/core/handlers/exception.py", line 140, in response_for_exception
    response = handle_uncaught_exception(
               ^^^^^^^^^^^^^^^^^^^^^^^^^^
  File "/home3/sambegkhatiwada/virtualenv/Django-portfolio/webportfolio/3.12/lib/python3.12/site-packages/django/core/handlers/exception.py", line 181, in handle_uncaught_exception
    return debug.technical_500_response(request, *exc_info)
           ^^^^^^^^^^^^^^^^^^^^^^^^^^^^^^^^^^^^^^^^^^^^^^^^
  File "/home3/sambegkhatiwada/virtualenv/Django-portfolio/webportfolio/3.12/lib/python3.12/site-packages/django/views/debug.py", line 69, in technical_500_response
    html = reporter.get_traceback_html()
           ^^^^^^^^^^^^^^^^^^^^^^^^^^^^^
  File "/home3/sambegkhatiwada/virtualenv/Django-portfolio/webportfolio/3.12/lib/python3.12/site-packages/django/views/debug.py", line 428, in get_traceback_html
    c = Context(self.get_traceback_data(), use_l10n=False)
                ^^^^^^^^^^^^^^^^^^^^^^^^^
  File "/home3/sambegkhatiwada/virtualenv/Django-portfolio/webportfolio/3.12/lib/python3.12/site-packages/django/views/debug.py", line 411, in get_traceback_data
    c["raising_view_name"] = get_caller(self.request)
                             ^^^^^^^^^^^^^^^^^^^^^^^^
  File "/home3/sambegkhatiwada/virtualenv/Django-portfolio/webportfolio/3.12/lib/python3.12/site-packages/django/views/debug.py", line 102, in get_caller
    resolver_match = resolve(request.path)
                     ^^^^^^^^^^^^^^^^^^^^^
  File "/home3/sambegkhatiwada/virtualenv/Django-portfolio/webportfolio/3.12/lib/python3.12/site-packages/django/urls/base.py", line 25, in resolve
    return get_resolver(urlconf).resolve(path)
           ^^^^^^^^^^^^^^^^^^^^^^^^^^^^^^^^^^^
  File "/home3/sambegkhatiwada/virtualenv/Django-portfolio/webportfolio/3.12/lib/python3.12/site-packages/django/urls/resolvers.py", line 666, in resolve
    for pattern in self.url_patterns:
                   ^^^^^^^^^^^^^^^^^
  File "/home3/sambegkhatiwada/virtualenv/Django-portfolio/webportfolio/3.12/lib/python3.12/site-packages/django/utils/functional.py", line 47, in __get__
    res = instance.__dict__[self.name] = self.func(instance)
                                         ^^^^^^^^^^^^^^^^^^^
  File "/home3/sambegkhatiwada/virtualenv/Django-portfolio/webportfolio/3.12/lib/python3.12/site-packages/django/urls/resolvers.py", line 718, in url_patterns
    patterns = getattr(self.urlconf_module, "urlpatterns", self.urlconf_module)
                       ^^^^^^^^^^^^^^^^^^^
  File "/home3/sambegkhatiwada/virtualenv/Django-portfolio/webportfolio/3.12/lib/python3.12/site-packages/django/utils/functional.py", line 47, in __get__
    res = instance.__dict__[self.name] = self.func(instance)
                                         ^^^^^^^^^^^^^^^^^^^
  File "/home3/sambegkhatiwada/virtualenv/Django-portfolio/webportfolio/3.12/lib/python3.12/site-packages/django/urls/resolvers.py", line 711, in urlconf_module
    return import_module(self.urlconf_name)
           ^^^^^^^^^^^^^^^^^^^^^^^^^^^^^^^^
  File "/opt/alt/python312/lib64/python3.12/importlib/__init__.py", line 90, in import_module
    return _bootstrap._gcd_import(name[level:], package, level)
           ^^^^^^^^^^^^^^^^^^^^^^^^^^^^^^^^^^^^^^^^^^^^^^^^^^^^
  File "<frozen importlib._bootstrap>", line 1387, in _gcd_import
  File "<frozen importlib._bootstrap>", line 1360, in _find_and_load
  File "<frozen importlib._bootstrap>", line 1331, in _find_and_load_unlocked
  File "<frozen importlib._bootstrap>", line 935, in _load_unlocked
  File "<frozen importlib._bootstrap_external>", line 999, in exec_module
  File "<frozen importlib._bootstrap>", line 488, in _call_with_frames_removed
  File "/home3/sambegkhatiwada/Django-portfolio/webportfolio/webportfolio/urls.py", line 5, in <module>
    urlpatterns += static(settings.MEDIA_URL, document_root=settings.MEDIA_ROOT)
    ^^^^^^^^^^^
NameError: name 'urlpatterns' is not defined

During handling of the above exception, another exception occurred:

Traceback (most recent call last):
  File "/home3/sambegkhatiwada/virtualenv/Django-portfolio/webportfolio/3.12/lib/python3.12/site-packages/django/core/handlers/exception.py", line 55, in inner
    response = get_response(request)
               ^^^^^^^^^^^^^^^^^^^^^
  File "/home3/sambegkhatiwada/virtualenv/Django-portfolio/webportfolio/3.12/lib/python3.12/site-packages/django/utils/deprecation.py", line 120, in __call__
    response = response or self.get_response(request)
                           ^^^^^^^^^^^^^^^^^^^^^^^^^^
  File "/home3/sambegkhatiwada/virtualenv/Django-portfolio/webportfolio/3.12/lib/python3.12/site-packages/django/core/handlers/exception.py", line 57, in inner
    response = response_for_exception(request, exc)
               ^^^^^^^^^^^^^^^^^^^^^^^^^^^^^^^^^^^^
  File "/home3/sambegkhatiwada/virtualenv/Django-portfolio/webportfolio/3.12/lib/python3.12/site-packages/django/core/handlers/exception.py", line 140, in response_for_exception
    response = handle_uncaught_exception(
               ^^^^^^^^^^^^^^^^^^^^^^^^^^
  File "/home3/sambegkhatiwada/virtualenv/Django-portfolio/webportfolio/3.12/lib/python3.12/site-packages/django/core/handlers/exception.py", line 181, in handle_uncaught_exception
    return debug.technical_500_response(request, *exc_info)
           ^^^^^^^^^^^^^^^^^^^^^^^^^^^^^^^^^^^^^^^^^^^^^^^^
  File "/home3/sambegkhatiwada/virtualenv/Django-portfolio/webportfolio/3.12/lib/python3.12/site-packages/django/views/debug.py", line 69, in technical_500_response
    html = reporter.get_traceback_html()
           ^^^^^^^^^^^^^^^^^^^^^^^^^^^^^
  File "/home3/sambegkhatiwada/virtualenv/Django-portfolio/webportfolio/3.12/lib/python3.12/site-packages/django/views/debug.py", line 428, in get_traceback_html
    c = Context(self.get_traceback_data(), use_l10n=False)
                ^^^^^^^^^^^^^^^^^^^^^^^^^
  File "/home3/sambegkhatiwada/virtualenv/Django-portfolio/webportfolio/3.12/lib/python3.12/site-packages/django/views/debug.py", line 411, in get_traceback_data
    c["raising_view_name"] = get_caller(self.request)
                             ^^^^^^^^^^^^^^^^^^^^^^^^
  File "/home3/sambegkhatiwada/virtualenv/Django-portfolio/webportfolio/3.12/lib/python3.12/site-packages/django/views/debug.py", line 102, in get_caller
    resolver_match = resolve(request.path)
                     ^^^^^^^^^^^^^^^^^^^^^
  File "/home3/sambegkhatiwada/virtualenv/Django-portfolio/webportfolio/3.12/lib/python3.12/site-packages/django/urls/base.py", line 25, in resolve
    return get_resolver(urlconf).resolve(path)
           ^^^^^^^^^^^^^^^^^^^^^^^^^^^^^^^^^^^
  File "/home3/sambegkhatiwada/virtualenv/Django-portfolio/webportfolio/3.12/lib/python3.12/site-packages/django/urls/resolvers.py", line 666, in resolve
    for pattern in self.url_patterns:
                   ^^^^^^^^^^^^^^^^^
  File "/home3/sambegkhatiwada/virtualenv/Django-portfolio/webportfolio/3.12/lib/python3.12/site-packages/django/utils/functional.py", line 47, in __get__
    res = instance.__dict__[self.name] = self.func(instance)
                                         ^^^^^^^^^^^^^^^^^^^
  File "/home3/sambegkhatiwada/virtualenv/Django-portfolio/webportfolio/3.12/lib/python3.12/site-packages/django/urls/resolvers.py", line 718, in url_patterns
    patterns = getattr(self.urlconf_module, "urlpatterns", self.urlconf_module)
                       ^^^^^^^^^^^^^^^^^^^
  File "/home3/sambegkhatiwada/virtualenv/Django-portfolio/webportfolio/3.12/lib/python3.12/site-packages/django/utils/functional.py", line 47, in __get__
    res = instance.__dict__[self.name] = self.func(instance)
                                         ^^^^^^^^^^^^^^^^^^^
  File "/home3/sambegkhatiwada/virtualenv/Django-portfolio/webportfolio/3.12/lib/python3.12/site-packages/django/urls/resolvers.py", line 711, in urlconf_module
    return import_module(self.urlconf_name)
           ^^^^^^^^^^^^^^^^^^^^^^^^^^^^^^^^
  File "/opt/alt/python312/lib64/python3.12/importlib/__init__.py", line 90, in import_module
    return _bootstrap._gcd_import(name[level:], package, level)
           ^^^^^^^^^^^^^^^^^^^^^^^^^^^^^^^^^^^^^^^^^^^^^^^^^^^^
  File "<frozen importlib._bootstrap>", line 1387, in _gcd_import
  File "<frozen importlib._bootstrap>", line 1360, in _find_and_load
  File "<frozen importlib._bootstrap>", line 1331, in _find_and_load_unlocked
  File "<frozen importlib._bootstrap>", line 935, in _load_unlocked
  File "<frozen importlib._bootstrap_external>", line 999, in exec_module
  File "<frozen importlib._bootstrap>", line 488, in _call_with_frames_removed
  File "/home3/sambegkhatiwada/Django-portfolio/webportfolio/webportfolio/urls.py", line 5, in <module>
    urlpatterns += static(settings.MEDIA_URL, document_root=settings.MEDIA_ROOT)
    ^^^^^^^^^^^
NameError: name 'urlpatterns' is not defined

During handling of the above exception, another exception occurred:

Traceback (most recent call last):
  File "/home3/sambegkhatiwada/virtualenv/Django-portfolio/webportfolio/3.12/lib/python3.12/site-packages/django/core/handlers/exception.py", line 55, in inner
    response = get_response(request)
               ^^^^^^^^^^^^^^^^^^^^^
  File "/home3/sambegkhatiwada/virtualenv/Django-portfolio/webportfolio/3.12/lib/python3.12/site-packages/django/utils/deprecation.py", line 120, in __call__
    response = response or self.get_response(request)
                           ^^^^^^^^^^^^^^^^^^^^^^^^^^
  File "/home3/sambegkhatiwada/virtualenv/Django-portfolio/webportfolio/3.12/lib/python3.12/site-packages/django/core/handlers/exception.py", line 57, in inner
    response = response_for_exception(request, exc)
               ^^^^^^^^^^^^^^^^^^^^^^^^^^^^^^^^^^^^
  File "/home3/sambegkhatiwada/virtualenv/Django-portfolio/webportfolio/3.12/lib/python3.12/site-packages/django/core/handlers/exception.py", line 140, in response_for_exception
    response = handle_uncaught_exception(
               ^^^^^^^^^^^^^^^^^^^^^^^^^^
  File "/home3/sambegkhatiwada/virtualenv/Django-portfolio/webportfolio/3.12/lib/python3.12/site-packages/django/core/handlers/exception.py", line 181, in handle_uncaught_exception
    return debug.technical_500_response(request, *exc_info)
           ^^^^^^^^^^^^^^^^^^^^^^^^^^^^^^^^^^^^^^^^^^^^^^^^
  File "/home3/sambegkhatiwada/virtualenv/Django-portfolio/webportfolio/3.12/lib/python3.12/site-packages/django/views/debug.py", line 69, in technical_500_response
    html = reporter.get_traceback_html()
           ^^^^^^^^^^^^^^^^^^^^^^^^^^^^^
  File "/home3/sambegkhatiwada/virtualenv/Django-portfolio/webportfolio/3.12/lib/python3.12/site-packages/django/views/debug.py", line 428, in get_traceback_html
    c = Context(self.get_traceback_data(), use_l10n=False)
                ^^^^^^^^^^^^^^^^^^^^^^^^^
  File "/home3/sambegkhatiwada/virtualenv/Django-portfolio/webportfolio/3.12/lib/python3.12/site-packages/django/views/debug.py", line 411, in get_traceback_data
    c["raising_view_name"] = get_caller(self.request)
                             ^^^^^^^^^^^^^^^^^^^^^^^^
  File "/home3/sambegkhatiwada/virtualenv/Django-portfolio/webportfolio/3.12/lib/python3.12/site-packages/django/views/debug.py", line 102, in get_caller
    resolver_match = resolve(request.path)
                     ^^^^^^^^^^^^^^^^^^^^^
  File "/home3/sambegkhatiwada/virtualenv/Django-portfolio/webportfolio/3.12/lib/python3.12/site-packages/django/urls/base.py", line 25, in resolve
    return get_resolver(urlconf).resolve(path)
           ^^^^^^^^^^^^^^^^^^^^^^^^^^^^^^^^^^^
  File "/home3/sambegkhatiwada/virtualenv/Django-portfolio/webportfolio/3.12/lib/python3.12/site-packages/django/urls/resolvers.py", line 666, in resolve
    for pattern in self.url_patterns:
                   ^^^^^^^^^^^^^^^^^
  File "/home3/sambegkhatiwada/virtualenv/Django-portfolio/webportfolio/3.12/lib/python3.12/site-packages/django/utils/functional.py", line 47, in __get__
    res = instance.__dict__[self.name] = self.func(instance)
                                         ^^^^^^^^^^^^^^^^^^^
  File "/home3/sambegkhatiwada/virtualenv/Django-portfolio/webportfolio/3.12/lib/python3.12/site-packages/django/urls/resolvers.py", line 718, in url_patterns
    patterns = getattr(self.urlconf_module, "urlpatterns", self.urlconf_module)
                       ^^^^^^^^^^^^^^^^^^^
  File "/home3/sambegkhatiwada/virtualenv/Django-portfolio/webportfolio/3.12/lib/python3.12/site-packages/django/utils/functional.py", line 47, in __get__
    res = instance.__dict__[self.name] = self.func(instance)
                                         ^^^^^^^^^^^^^^^^^^^
  File "/home3/sambegkhatiwada/virtualenv/Django-portfolio/webportfolio/3.12/lib/python3.12/site-packages/django/urls/resolvers.py", line 711, in urlconf_module
    return import_module(self.urlconf_name)
           ^^^^^^^^^^^^^^^^^^^^^^^^^^^^^^^^
  File "/opt/alt/python312/lib64/python3.12/importlib/__init__.py", line 90, in import_module
    return _bootstrap._gcd_import(name[level:], package, level)
           ^^^^^^^^^^^^^^^^^^^^^^^^^^^^^^^^^^^^^^^^^^^^^^^^^^^^
  File "<frozen importlib._bootstrap>", line 1387, in _gcd_import
  File "<frozen importlib._bootstrap>", line 1360, in _find_and_load
  File "<frozen importlib._bootstrap>", line 1331, in _find_and_load_unlocked
  File "<frozen importlib._bootstrap>", line 935, in _load_unlocked
  File "<frozen importlib._bootstrap_external>", line 999, in exec_module
  File "<frozen importlib._bootstrap>", line 488, in _call_with_frames_removed
  File "/home3/sambegkhatiwada/Django-portfolio/webportfolio/webportfolio/urls.py", line 5, in <module>
    urlpatterns += static(settings.MEDIA_URL, document_root=settings.MEDIA_ROOT)
    ^^^^^^^^^^^
NameError: name 'urlpatterns' is not defined

During handling of the above exception, another exception occurred:

Traceback (most recent call last):
  File "/home3/sambegkhatiwada/virtualenv/Django-portfolio/webportfolio/3.12/lib/python3.12/site-packages/django/core/handlers/wsgi.py", line 124, in __call__
    response = self.get_response(request)
               ^^^^^^^^^^^^^^^^^^^^^^^^^^
  File "/home3/sambegkhatiwada/virtualenv/Django-portfolio/webportfolio/3.12/lib/python3.12/site-packages/django/core/handlers/base.py", line 140, in get_response
    response = self._middleware_chain(request)
               ^^^^^^^^^^^^^^^^^^^^^^^^^^^^^^^
  File "/home3/sambegkhatiwada/virtualenv/Django-portfolio/webportfolio/3.12/lib/python3.12/site-packages/django/core/handlers/exception.py", line 57, in inner
    response = response_for_exception(request, exc)
               ^^^^^^^^^^^^^^^^^^^^^^^^^^^^^^^^^^^^
  File "/home3/sambegkhatiwada/virtualenv/Django-portfolio/webportfolio/3.12/lib/python3.12/site-packages/django/core/handlers/exception.py", line 140, in response_for_exception
    response = handle_uncaught_exception(
               ^^^^^^^^^^^^^^^^^^^^^^^^^^
  File "/home3/sambegkhatiwada/virtualenv/Django-portfolio/webportfolio/3.12/lib/python3.12/site-packages/django/core/handlers/exception.py", line 181, in handle_uncaught_exception
    return debug.technical_500_response(request, *exc_info)
           ^^^^^^^^^^^^^^^^^^^^^^^^^^^^^^^^^^^^^^^^^^^^^^^^
  File "/home3/sambegkhatiwada/virtualenv/Django-portfolio/webportfolio/3.12/lib/python3.12/site-packages/django/views/debug.py", line 69, in technical_500_response
    html = reporter.get_traceback_html()
           ^^^^^^^^^^^^^^^^^^^^^^^^^^^^^
  File "/home3/sambegkhatiwada/virtualenv/Django-portfolio/webportfolio/3.12/lib/python3.12/site-packages/django/views/debug.py", line 428, in get_traceback_html
    c = Context(self.get_traceback_data(), use_l10n=False)
                ^^^^^^^^^^^^^^^^^^^^^^^^^
  File "/home3/sambegkhatiwada/virtualenv/Django-portfolio/webportfolio/3.12/lib/python3.12/site-packages/django/views/debug.py", line 411, in get_traceback_data
    c["raising_view_name"] = get_caller(self.request)
                             ^^^^^^^^^^^^^^^^^^^^^^^^
  File "/home3/sambegkhatiwada/virtualenv/Django-portfolio/webportfolio/3.12/lib/python3.12/site-packages/django/views/debug.py", line 102, in get_caller
    resolver_match = resolve(request.path)
                     ^^^^^^^^^^^^^^^^^^^^^
  File "/home3/sambegkhatiwada/virtualenv/Django-portfolio/webportfolio/3.12/lib/python3.12/site-packages/django/urls/base.py", line 25, in resolve
    return get_resolver(urlconf).resolve(path)
           ^^^^^^^^^^^^^^^^^^^^^^^^^^^^^^^^^^^
  File "/home3/sambegkhatiwada/virtualenv/Django-portfolio/webportfolio/3.12/lib/python3.12/site-packages/django/urls/resolvers.py", line 666, in resolve
    for pattern in self.url_patterns:
                   ^^^^^^^^^^^^^^^^^
  File "/home3/sambegkhatiwada/virtualenv/Django-portfolio/webportfolio/3.12/lib/python3.12/site-packages/django/utils/functional.py", line 47, in __get__
    res = instance.__dict__[self.name] = self.func(instance)
                                         ^^^^^^^^^^^^^^^^^^^
  File "/home3/sambegkhatiwada/virtualenv/Django-portfolio/webportfolio/3.12/lib/python3.12/site-packages/django/urls/resolvers.py", line 718, in url_patterns
    patterns = getattr(self.urlconf_module, "urlpatterns", self.urlconf_module)
                       ^^^^^^^^^^^^^^^^^^^
  File "/home3/sambegkhatiwada/virtualenv/Django-portfolio/webportfolio/3.12/lib/python3.12/site-packages/django/utils/functional.py", line 47, in __get__
    res = instance.__dict__[self.name] = self.func(instance)
                                         ^^^^^^^^^^^^^^^^^^^
  File "/home3/sambegkhatiwada/virtualenv/Django-portfolio/webportfolio/3.12/lib/python3.12/site-packages/django/urls/resolvers.py", line 711, in urlconf_module
    return import_module(self.urlconf_name)
           ^^^^^^^^^^^^^^^^^^^^^^^^^^^^^^^^
  File "/opt/alt/python312/lib64/python3.12/importlib/__init__.py", line 90, in import_module
    return _bootstrap._gcd_import(name[level:], package, level)
           ^^^^^^^^^^^^^^^^^^^^^^^^^^^^^^^^^^^^^^^^^^^^^^^^^^^^
  File "<frozen importlib._bootstrap>", line 1387, in _gcd_import
  File "<frozen importlib._bootstrap>", line 1360, in _find_and_load
  File "<frozen importlib._bootstrap>", line 1331, in _find_and_load_unlocked
  File "<frozen importlib._bootstrap>", line 935, in _load_unlocked
  File "<frozen importlib._bootstrap_external>", line 999, in exec_module
  File "<frozen importlib._bootstrap>", line 488, in _call_with_frames_removed
  File "/home3/sambegkhatiwada/Django-portfolio/webportfolio/webportfolio/urls.py", line 5, in <module>
    urlpatterns += static(settings.MEDIA_URL, document_root=settings.MEDIA_ROOT)
    ^^^^^^^^^^^
NameError: name 'urlpatterns' is not defined
[ERROR] [UID:1370][1246403] wsgiAppHandler pApp->start_response() return NULL.
Traceback (most recent call last):
  File "/home3/sambegkhatiwada/virtualenv/Django-portfolio/webportfolio/3.12/lib/python3.12/site-packages/django/core/handlers/exception.py", line 55, in inner
    response = get_response(request)
               ^^^^^^^^^^^^^^^^^^^^^
  File "/home3/sambegkhatiwada/virtualenv/Django-portfolio/webportfolio/3.12/lib/python3.12/site-packages/django/core/handlers/base.py", line 181, in _get_response
    callback, callback_args, callback_kwargs = self.resolve_request(request)
                                               ^^^^^^^^^^^^^^^^^^^^^^^^^^^^^
  File "/home3/sambegkhatiwada/virtualenv/Django-portfolio/webportfolio/3.12/lib/python3.12/site-packages/django/core/handlers/base.py", line 313, in resolve_request
    resolver_match = resolver.resolve(request.path_info)
                     ^^^^^^^^^^^^^^^^^^^^^^^^^^^^^^^^^^^
  File "/home3/sambegkhatiwada/virtualenv/Django-portfolio/webportfolio/3.12/lib/python3.12/site-packages/django/urls/resolvers.py", line 666, in resolve
    for pattern in self.url_patterns:
                   ^^^^^^^^^^^^^^^^^
  File "/home3/sambegkhatiwada/virtualenv/Django-portfolio/webportfolio/3.12/lib/python3.12/site-packages/django/utils/functional.py", line 47, in __get__
    res = instance.__dict__[self.name] = self.func(instance)
                                         ^^^^^^^^^^^^^^^^^^^
  File "/home3/sambegkhatiwada/virtualenv/Django-portfolio/webportfolio/3.12/lib/python3.12/site-packages/django/urls/resolvers.py", line 718, in url_patterns
    patterns = getattr(self.urlconf_module, "urlpatterns", self.urlconf_module)
                       ^^^^^^^^^^^^^^^^^^^
  File "/home3/sambegkhatiwada/virtualenv/Django-portfolio/webportfolio/3.12/lib/python3.12/site-packages/django/utils/functional.py", line 47, in __get__
    res = instance.__dict__[self.name] = self.func(instance)
                                         ^^^^^^^^^^^^^^^^^^^
  File "/home3/sambegkhatiwada/virtualenv/Django-portfolio/webportfolio/3.12/lib/python3.12/site-packages/django/urls/resolvers.py", line 711, in urlconf_module
    return import_module(self.urlconf_name)
           ^^^^^^^^^^^^^^^^^^^^^^^^^^^^^^^^
  File "/opt/alt/python312/lib64/python3.12/importlib/__init__.py", line 90, in import_module
    return _bootstrap._gcd_import(name[level:], package, level)
           ^^^^^^^^^^^^^^^^^^^^^^^^^^^^^^^^^^^^^^^^^^^^^^^^^^^^
  File "<frozen importlib._bootstrap>", line 1387, in _gcd_import
  File "<frozen importlib._bootstrap>", line 1360, in _find_and_load
  File "<frozen importlib._bootstrap>", line 1331, in _find_and_load_unlocked
  File "<frozen importlib._bootstrap>", line 935, in _load_unlocked
  File "<frozen importlib._bootstrap_external>", line 999, in exec_module
  File "<frozen importlib._bootstrap>", line 488, in _call_with_frames_removed
  File "/home3/sambegkhatiwada/Django-portfolio/webportfolio/webportfolio/urls.py", line 5, in <module>
    urlpatterns += static(settings.MEDIA_URL, document_root=settings.MEDIA_ROOT)
    ^^^^^^^^^^^
NameError: name 'urlpatterns' is not defined

During handling of the above exception, another exception occurred:

Traceback (most recent call last):
  File "/home3/sambegkhatiwada/virtualenv/Django-portfolio/webportfolio/3.12/lib/python3.12/site-packages/django/core/handlers/exception.py", line 55, in inner
    response = get_response(request)
               ^^^^^^^^^^^^^^^^^^^^^
  File "/home3/sambegkhatiwada/virtualenv/Django-portfolio/webportfolio/3.12/lib/python3.12/site-packages/django/utils/deprecation.py", line 120, in __call__
    response = response or self.get_response(request)
                           ^^^^^^^^^^^^^^^^^^^^^^^^^^
  File "/home3/sambegkhatiwada/virtualenv/Django-portfolio/webportfolio/3.12/lib/python3.12/site-packages/django/core/handlers/exception.py", line 57, in inner
    response = response_for_exception(request, exc)
               ^^^^^^^^^^^^^^^^^^^^^^^^^^^^^^^^^^^^
  File "/home3/sambegkhatiwada/virtualenv/Django-portfolio/webportfolio/3.12/lib/python3.12/site-packages/django/core/handlers/exception.py", line 140, in response_for_exception
    response = handle_uncaught_exception(
               ^^^^^^^^^^^^^^^^^^^^^^^^^^
  File "/home3/sambegkhatiwada/virtualenv/Django-portfolio/webportfolio/3.12/lib/python3.12/site-packages/django/core/handlers/exception.py", line 181, in handle_uncaught_exception
    return debug.technical_500_response(request, *exc_info)
           ^^^^^^^^^^^^^^^^^^^^^^^^^^^^^^^^^^^^^^^^^^^^^^^^
  File "/home3/sambegkhatiwada/virtualenv/Django-portfolio/webportfolio/3.12/lib/python3.12/site-packages/django/views/debug.py", line 69, in technical_500_response
    html = reporter.get_traceback_html()
           ^^^^^^^^^^^^^^^^^^^^^^^^^^^^^
  File "/home3/sambegkhatiwada/virtualenv/Django-portfolio/webportfolio/3.12/lib/python3.12/site-packages/django/views/debug.py", line 428, in get_traceback_html
    c = Context(self.get_traceback_data(), use_l10n=False)
                ^^^^^^^^^^^^^^^^^^^^^^^^^
  File "/home3/sambegkhatiwada/virtualenv/Django-portfolio/webportfolio/3.12/lib/python3.12/site-packages/django/views/debug.py", line 411, in get_traceback_data
    c["raising_view_name"] = get_caller(self.request)
                             ^^^^^^^^^^^^^^^^^^^^^^^^
  File "/home3/sambegkhatiwada/virtualenv/Django-portfolio/webportfolio/3.12/lib/python3.12/site-packages/django/views/debug.py", line 102, in get_caller
    resolver_match = resolve(request.path)
                     ^^^^^^^^^^^^^^^^^^^^^
  File "/home3/sambegkhatiwada/virtualenv/Django-portfolio/webportfolio/3.12/lib/python3.12/site-packages/django/urls/base.py", line 25, in resolve
    return get_resolver(urlconf).resolve(path)
           ^^^^^^^^^^^^^^^^^^^^^^^^^^^^^^^^^^^
  File "/home3/sambegkhatiwada/virtualenv/Django-portfolio/webportfolio/3.12/lib/python3.12/site-packages/django/urls/resolvers.py", line 666, in resolve
    for pattern in self.url_patterns:
                   ^^^^^^^^^^^^^^^^^
  File "/home3/sambegkhatiwada/virtualenv/Django-portfolio/webportfolio/3.12/lib/python3.12/site-packages/django/utils/functional.py", line 47, in __get__
    res = instance.__dict__[self.name] = self.func(instance)
                                         ^^^^^^^^^^^^^^^^^^^
  File "/home3/sambegkhatiwada/virtualenv/Django-portfolio/webportfolio/3.12/lib/python3.12/site-packages/django/urls/resolvers.py", line 718, in url_patterns
    patterns = getattr(self.urlconf_module, "urlpatterns", self.urlconf_module)
                       ^^^^^^^^^^^^^^^^^^^
  File "/home3/sambegkhatiwada/virtualenv/Django-portfolio/webportfolio/3.12/lib/python3.12/site-packages/django/utils/functional.py", line 47, in __get__
    res = instance.__dict__[self.name] = self.func(instance)
                                         ^^^^^^^^^^^^^^^^^^^
  File "/home3/sambegkhatiwada/virtualenv/Django-portfolio/webportfolio/3.12/lib/python3.12/site-packages/django/urls/resolvers.py", line 711, in urlconf_module
    return import_module(self.urlconf_name)
           ^^^^^^^^^^^^^^^^^^^^^^^^^^^^^^^^
  File "/opt/alt/python312/lib64/python3.12/importlib/__init__.py", line 90, in import_module
    return _bootstrap._gcd_import(name[level:], package, level)
           ^^^^^^^^^^^^^^^^^^^^^^^^^^^^^^^^^^^^^^^^^^^^^^^^^^^^
  File "<frozen importlib._bootstrap>", line 1387, in _gcd_import
  File "<frozen importlib._bootstrap>", line 1360, in _find_and_load
  File "<frozen importlib._bootstrap>", line 1331, in _find_and_load_unlocked
  File "<frozen importlib._bootstrap>", line 935, in _load_unlocked
  File "<frozen importlib._bootstrap_external>", line 999, in exec_module
  File "<frozen importlib._bootstrap>", line 488, in _call_with_frames_removed
  File "/home3/sambegkhatiwada/Django-portfolio/webportfolio/webportfolio/urls.py", line 5, in <module>
    urlpatterns += static(settings.MEDIA_URL, document_root=settings.MEDIA_ROOT)
    ^^^^^^^^^^^
NameError: name 'urlpatterns' is not defined

During handling of the above exception, another exception occurred:

Traceback (most recent call last):
  File "/home3/sambegkhatiwada/virtualenv/Django-portfolio/webportfolio/3.12/lib/python3.12/site-packages/django/core/handlers/exception.py", line 55, in inner
    response = get_response(request)
               ^^^^^^^^^^^^^^^^^^^^^
  File "/home3/sambegkhatiwada/virtualenv/Django-portfolio/webportfolio/3.12/lib/python3.12/site-packages/django/utils/deprecation.py", line 120, in __call__
    response = response or self.get_response(request)
                           ^^^^^^^^^^^^^^^^^^^^^^^^^^
  File "/home3/sambegkhatiwada/virtualenv/Django-portfolio/webportfolio/3.12/lib/python3.12/site-packages/django/core/handlers/exception.py", line 57, in inner
    response = response_for_exception(request, exc)
               ^^^^^^^^^^^^^^^^^^^^^^^^^^^^^^^^^^^^
  File "/home3/sambegkhatiwada/virtualenv/Django-portfolio/webportfolio/3.12/lib/python3.12/site-packages/django/core/handlers/exception.py", line 140, in response_for_exception
    response = handle_uncaught_exception(
               ^^^^^^^^^^^^^^^^^^^^^^^^^^
  File "/home3/sambegkhatiwada/virtualenv/Django-portfolio/webportfolio/3.12/lib/python3.12/site-packages/django/core/handlers/exception.py", line 181, in handle_uncaught_exception
    return debug.technical_500_response(request, *exc_info)
           ^^^^^^^^^^^^^^^^^^^^^^^^^^^^^^^^^^^^^^^^^^^^^^^^
  File "/home3/sambegkhatiwada/virtualenv/Django-portfolio/webportfolio/3.12/lib/python3.12/site-packages/django/views/debug.py", line 69, in technical_500_response
    html = reporter.get_traceback_html()
           ^^^^^^^^^^^^^^^^^^^^^^^^^^^^^
  File "/home3/sambegkhatiwada/virtualenv/Django-portfolio/webportfolio/3.12/lib/python3.12/site-packages/django/views/debug.py", line 428, in get_traceback_html
    c = Context(self.get_traceback_data(), use_l10n=False)
                ^^^^^^^^^^^^^^^^^^^^^^^^^
  File "/home3/sambegkhatiwada/virtualenv/Django-portfolio/webportfolio/3.12/lib/python3.12/site-packages/django/views/debug.py", line 411, in get_traceback_data
    c["raising_view_name"] = get_caller(self.request)
                             ^^^^^^^^^^^^^^^^^^^^^^^^
  File "/home3/sambegkhatiwada/virtualenv/Django-portfolio/webportfolio/3.12/lib/python3.12/site-packages/django/views/debug.py", line 102, in get_caller
    resolver_match = resolve(request.path)
                     ^^^^^^^^^^^^^^^^^^^^^
  File "/home3/sambegkhatiwada/virtualenv/Django-portfolio/webportfolio/3.12/lib/python3.12/site-packages/django/urls/base.py", line 25, in resolve
    return get_resolver(urlconf).resolve(path)
           ^^^^^^^^^^^^^^^^^^^^^^^^^^^^^^^^^^^
  File "/home3/sambegkhatiwada/virtualenv/Django-portfolio/webportfolio/3.12/lib/python3.12/site-packages/django/urls/resolvers.py", line 666, in resolve
    for pattern in self.url_patterns:
                   ^^^^^^^^^^^^^^^^^
  File "/home3/sambegkhatiwada/virtualenv/Django-portfolio/webportfolio/3.12/lib/python3.12/site-packages/django/utils/functional.py", line 47, in __get__
    res = instance.__dict__[self.name] = self.func(instance)
                                         ^^^^^^^^^^^^^^^^^^^
  File "/home3/sambegkhatiwada/virtualenv/Django-portfolio/webportfolio/3.12/lib/python3.12/site-packages/django/urls/resolvers.py", line 718, in url_patterns
    patterns = getattr(self.urlconf_module, "urlpatterns", self.urlconf_module)
                       ^^^^^^^^^^^^^^^^^^^
  File "/home3/sambegkhatiwada/virtualenv/Django-portfolio/webportfolio/3.12/lib/python3.12/site-packages/django/utils/functional.py", line 47, in __get__
    res = instance.__dict__[self.name] = self.func(instance)
                                         ^^^^^^^^^^^^^^^^^^^
  File "/home3/sambegkhatiwada/virtualenv/Django-portfolio/webportfolio/3.12/lib/python3.12/site-packages/django/urls/resolvers.py", line 711, in urlconf_module
    return import_module(self.urlconf_name)
           ^^^^^^^^^^^^^^^^^^^^^^^^^^^^^^^^
  File "/opt/alt/python312/lib64/python3.12/importlib/__init__.py", line 90, in import_module
    return _bootstrap._gcd_import(name[level:], package, level)
           ^^^^^^^^^^^^^^^^^^^^^^^^^^^^^^^^^^^^^^^^^^^^^^^^^^^^
  File "<frozen importlib._bootstrap>", line 1387, in _gcd_import
  File "<frozen importlib._bootstrap>", line 1360, in _find_and_load
  File "<frozen importlib._bootstrap>", line 1331, in _find_and_load_unlocked
  File "<frozen importlib._bootstrap>", line 935, in _load_unlocked
  File "<frozen importlib._bootstrap_external>", line 999, in exec_module
  File "<frozen importlib._bootstrap>", line 488, in _call_with_frames_removed
  File "/home3/sambegkhatiwada/Django-portfolio/webportfolio/webportfolio/urls.py", line 5, in <module>
    urlpatterns += static(settings.MEDIA_URL, document_root=settings.MEDIA_ROOT)
    ^^^^^^^^^^^
NameError: name 'urlpatterns' is not defined

During handling of the above exception, another exception occurred:

Traceback (most recent call last):
  File "/home3/sambegkhatiwada/virtualenv/Django-portfolio/webportfolio/3.12/lib/python3.12/site-packages/django/core/handlers/exception.py", line 55, in inner
    response = get_response(request)
               ^^^^^^^^^^^^^^^^^^^^^
  File "/home3/sambegkhatiwada/virtualenv/Django-portfolio/webportfolio/3.12/lib/python3.12/site-packages/django/utils/deprecation.py", line 120, in __call__
    response = response or self.get_response(request)
                           ^^^^^^^^^^^^^^^^^^^^^^^^^^
  File "/home3/sambegkhatiwada/virtualenv/Django-portfolio/webportfolio/3.12/lib/python3.12/site-packages/django/core/handlers/exception.py", line 57, in inner
    response = response_for_exception(request, exc)
               ^^^^^^^^^^^^^^^^^^^^^^^^^^^^^^^^^^^^
  File "/home3/sambegkhatiwada/virtualenv/Django-portfolio/webportfolio/3.12/lib/python3.12/site-packages/django/core/handlers/exception.py", line 140, in response_for_exception
    response = handle_uncaught_exception(
               ^^^^^^^^^^^^^^^^^^^^^^^^^^
  File "/home3/sambegkhatiwada/virtualenv/Django-portfolio/webportfolio/3.12/lib/python3.12/site-packages/django/core/handlers/exception.py", line 181, in handle_uncaught_exception
    return debug.technical_500_response(request, *exc_info)
           ^^^^^^^^^^^^^^^^^^^^^^^^^^^^^^^^^^^^^^^^^^^^^^^^
  File "/home3/sambegkhatiwada/virtualenv/Django-portfolio/webportfolio/3.12/lib/python3.12/site-packages/django/views/debug.py", line 69, in technical_500_response
    html = reporter.get_traceback_html()
           ^^^^^^^^^^^^^^^^^^^^^^^^^^^^^
  File "/home3/sambegkhatiwada/virtualenv/Django-portfolio/webportfolio/3.12/lib/python3.12/site-packages/django/views/debug.py", line 428, in get_traceback_html
    c = Context(self.get_traceback_data(), use_l10n=False)
                ^^^^^^^^^^^^^^^^^^^^^^^^^
  File "/home3/sambegkhatiwada/virtualenv/Django-portfolio/webportfolio/3.12/lib/python3.12/site-packages/django/views/debug.py", line 411, in get_traceback_data
    c["raising_view_name"] = get_caller(self.request)
                             ^^^^^^^^^^^^^^^^^^^^^^^^
  File "/home3/sambegkhatiwada/virtualenv/Django-portfolio/webportfolio/3.12/lib/python3.12/site-packages/django/views/debug.py", line 102, in get_caller
    resolver_match = resolve(request.path)
                     ^^^^^^^^^^^^^^^^^^^^^
  File "/home3/sambegkhatiwada/virtualenv/Django-portfolio/webportfolio/3.12/lib/python3.12/site-packages/django/urls/base.py", line 25, in resolve
    return get_resolver(urlconf).resolve(path)
           ^^^^^^^^^^^^^^^^^^^^^^^^^^^^^^^^^^^
  File "/home3/sambegkhatiwada/virtualenv/Django-portfolio/webportfolio/3.12/lib/python3.12/site-packages/django/urls/resolvers.py", line 666, in resolve
    for pattern in self.url_patterns:
                   ^^^^^^^^^^^^^^^^^
  File "/home3/sambegkhatiwada/virtualenv/Django-portfolio/webportfolio/3.12/lib/python3.12/site-packages/django/utils/functional.py", line 47, in __get__
    res = instance.__dict__[self.name] = self.func(instance)
                                         ^^^^^^^^^^^^^^^^^^^
  File "/home3/sambegkhatiwada/virtualenv/Django-portfolio/webportfolio/3.12/lib/python3.12/site-packages/django/urls/resolvers.py", line 718, in url_patterns
    patterns = getattr(self.urlconf_module, "urlpatterns", self.urlconf_module)
                       ^^^^^^^^^^^^^^^^^^^
  File "/home3/sambegkhatiwada/virtualenv/Django-portfolio/webportfolio/3.12/lib/python3.12/site-packages/django/utils/functional.py", line 47, in __get__
    res = instance.__dict__[self.name] = self.func(instance)
                                         ^^^^^^^^^^^^^^^^^^^
  File "/home3/sambegkhatiwada/virtualenv/Django-portfolio/webportfolio/3.12/lib/python3.12/site-packages/django/urls/resolvers.py", line 711, in urlconf_module
    return import_module(self.urlconf_name)
           ^^^^^^^^^^^^^^^^^^^^^^^^^^^^^^^^
  File "/opt/alt/python312/lib64/python3.12/importlib/__init__.py", line 90, in import_module
    return _bootstrap._gcd_import(name[level:], package, level)
           ^^^^^^^^^^^^^^^^^^^^^^^^^^^^^^^^^^^^^^^^^^^^^^^^^^^^
  File "<frozen importlib._bootstrap>", line 1387, in _gcd_import
  File "<frozen importlib._bootstrap>", line 1360, in _find_and_load
  File "<frozen importlib._bootstrap>", line 1331, in _find_and_load_unlocked
  File "<frozen importlib._bootstrap>", line 935, in _load_unlocked
  File "<frozen importlib._bootstrap_external>", line 999, in exec_module
  File "<frozen importlib._bootstrap>", line 488, in _call_with_frames_removed
  File "/home3/sambegkhatiwada/Django-portfolio/webportfolio/webportfolio/urls.py", line 5, in <module>
    urlpatterns += static(settings.MEDIA_URL, document_root=settings.MEDIA_ROOT)
    ^^^^^^^^^^^
NameError: name 'urlpatterns' is not defined

During handling of the above exception, another exception occurred:

Traceback (most recent call last):
  File "/home3/sambegkhatiwada/virtualenv/Django-portfolio/webportfolio/3.12/lib/python3.12/site-packages/django/core/handlers/exception.py", line 55, in inner
    response = get_response(request)
               ^^^^^^^^^^^^^^^^^^^^^
  File "/home3/sambegkhatiwada/virtualenv/Django-portfolio/webportfolio/3.12/lib/python3.12/site-packages/django/utils/deprecation.py", line 120, in __call__
    response = response or self.get_response(request)
                           ^^^^^^^^^^^^^^^^^^^^^^^^^^
  File "/home3/sambegkhatiwada/virtualenv/Django-portfolio/webportfolio/3.12/lib/python3.12/site-packages/django/core/handlers/exception.py", line 57, in inner
    response = response_for_exception(request, exc)
               ^^^^^^^^^^^^^^^^^^^^^^^^^^^^^^^^^^^^
  File "/home3/sambegkhatiwada/virtualenv/Django-portfolio/webportfolio/3.12/lib/python3.12/site-packages/django/core/handlers/exception.py", line 140, in response_for_exception
    response = handle_uncaught_exception(
               ^^^^^^^^^^^^^^^^^^^^^^^^^^
  File "/home3/sambegkhatiwada/virtualenv/Django-portfolio/webportfolio/3.12/lib/python3.12/site-packages/django/core/handlers/exception.py", line 181, in handle_uncaught_exception
    return debug.technical_500_response(request, *exc_info)
           ^^^^^^^^^^^^^^^^^^^^^^^^^^^^^^^^^^^^^^^^^^^^^^^^
  File "/home3/sambegkhatiwada/virtualenv/Django-portfolio/webportfolio/3.12/lib/python3.12/site-packages/django/views/debug.py", line 69, in technical_500_response
    html = reporter.get_traceback_html()
           ^^^^^^^^^^^^^^^^^^^^^^^^^^^^^
  File "/home3/sambegkhatiwada/virtualenv/Django-portfolio/webportfolio/3.12/lib/python3.12/site-packages/django/views/debug.py", line 428, in get_traceback_html
    c = Context(self.get_traceback_data(), use_l10n=False)
                ^^^^^^^^^^^^^^^^^^^^^^^^^
  File "/home3/sambegkhatiwada/virtualenv/Django-portfolio/webportfolio/3.12/lib/python3.12/site-packages/django/views/debug.py", line 411, in get_traceback_data
    c["raising_view_name"] = get_caller(self.request)
                             ^^^^^^^^^^^^^^^^^^^^^^^^
  File "/home3/sambegkhatiwada/virtualenv/Django-portfolio/webportfolio/3.12/lib/python3.12/site-packages/django/views/debug.py", line 102, in get_caller
    resolver_match = resolve(request.path)
                     ^^^^^^^^^^^^^^^^^^^^^
  File "/home3/sambegkhatiwada/virtualenv/Django-portfolio/webportfolio/3.12/lib/python3.12/site-packages/django/urls/base.py", line 25, in resolve
    return get_resolver(urlconf).resolve(path)
           ^^^^^^^^^^^^^^^^^^^^^^^^^^^^^^^^^^^
  File "/home3/sambegkhatiwada/virtualenv/Django-portfolio/webportfolio/3.12/lib/python3.12/site-packages/django/urls/resolvers.py", line 666, in resolve
    for pattern in self.url_patterns:
                   ^^^^^^^^^^^^^^^^^
  File "/home3/sambegkhatiwada/virtualenv/Django-portfolio/webportfolio/3.12/lib/python3.12/site-packages/django/utils/functional.py", line 47, in __get__
    res = instance.__dict__[self.name] = self.func(instance)
                                         ^^^^^^^^^^^^^^^^^^^
  File "/home3/sambegkhatiwada/virtualenv/Django-portfolio/webportfolio/3.12/lib/python3.12/site-packages/django/urls/resolvers.py", line 718, in url_patterns
    patterns = getattr(self.urlconf_module, "urlpatterns", self.urlconf_module)
                       ^^^^^^^^^^^^^^^^^^^
  File "/home3/sambegkhatiwada/virtualenv/Django-portfolio/webportfolio/3.12/lib/python3.12/site-packages/django/utils/functional.py", line 47, in __get__
    res = instance.__dict__[self.name] = self.func(instance)
                                         ^^^^^^^^^^^^^^^^^^^
  File "/home3/sambegkhatiwada/virtualenv/Django-portfolio/webportfolio/3.12/lib/python3.12/site-packages/django/urls/resolvers.py", line 711, in urlconf_module
    return import_module(self.urlconf_name)
           ^^^^^^^^^^^^^^^^^^^^^^^^^^^^^^^^
  File "/opt/alt/python312/lib64/python3.12/importlib/__init__.py", line 90, in import_module
    return _bootstrap._gcd_import(name[level:], package, level)
           ^^^^^^^^^^^^^^^^^^^^^^^^^^^^^^^^^^^^^^^^^^^^^^^^^^^^
  File "<frozen importlib._bootstrap>", line 1387, in _gcd_import
  File "<frozen importlib._bootstrap>", line 1360, in _find_and_load
  File "<frozen importlib._bootstrap>", line 1331, in _find_and_load_unlocked
  File "<frozen importlib._bootstrap>", line 935, in _load_unlocked
  File "<frozen importlib._bootstrap_external>", line 999, in exec_module
  File "<frozen importlib._bootstrap>", line 488, in _call_with_frames_removed
  File "/home3/sambegkhatiwada/Django-portfolio/webportfolio/webportfolio/urls.py", line 5, in <module>
    urlpatterns += static(settings.MEDIA_URL, document_root=settings.MEDIA_ROOT)
    ^^^^^^^^^^^
NameError: name 'urlpatterns' is not defined

During handling of the above exception, another exception occurred:

Traceback (most recent call last):
  File "/home3/sambegkhatiwada/virtualenv/Django-portfolio/webportfolio/3.12/lib/python3.12/site-packages/django/core/handlers/exception.py", line 55, in inner
    response = get_response(request)
               ^^^^^^^^^^^^^^^^^^^^^
  File "/home3/sambegkhatiwada/virtualenv/Django-portfolio/webportfolio/3.12/lib/python3.12/site-packages/django/utils/deprecation.py", line 120, in __call__
    response = response or self.get_response(request)
                           ^^^^^^^^^^^^^^^^^^^^^^^^^^
  File "/home3/sambegkhatiwada/virtualenv/Django-portfolio/webportfolio/3.12/lib/python3.12/site-packages/django/core/handlers/exception.py", line 57, in inner
    response = response_for_exception(request, exc)
               ^^^^^^^^^^^^^^^^^^^^^^^^^^^^^^^^^^^^
  File "/home3/sambegkhatiwada/virtualenv/Django-portfolio/webportfolio/3.12/lib/python3.12/site-packages/django/core/handlers/exception.py", line 140, in response_for_exception
    response = handle_uncaught_exception(
               ^^^^^^^^^^^^^^^^^^^^^^^^^^
  File "/home3/sambegkhatiwada/virtualenv/Django-portfolio/webportfolio/3.12/lib/python3.12/site-packages/django/core/handlers/exception.py", line 181, in handle_uncaught_exception
    return debug.technical_500_response(request, *exc_info)
           ^^^^^^^^^^^^^^^^^^^^^^^^^^^^^^^^^^^^^^^^^^^^^^^^
  File "/home3/sambegkhatiwada/virtualenv/Django-portfolio/webportfolio/3.12/lib/python3.12/site-packages/django/views/debug.py", line 69, in technical_500_response
    html = reporter.get_traceback_html()
           ^^^^^^^^^^^^^^^^^^^^^^^^^^^^^
  File "/home3/sambegkhatiwada/virtualenv/Django-portfolio/webportfolio/3.12/lib/python3.12/site-packages/django/views/debug.py", line 428, in get_traceback_html
    c = Context(self.get_traceback_data(), use_l10n=False)
                ^^^^^^^^^^^^^^^^^^^^^^^^^
  File "/home3/sambegkhatiwada/virtualenv/Django-portfolio/webportfolio/3.12/lib/python3.12/site-packages/django/views/debug.py", line 411, in get_traceback_data
    c["raising_view_name"] = get_caller(self.request)
                             ^^^^^^^^^^^^^^^^^^^^^^^^
  File "/home3/sambegkhatiwada/virtualenv/Django-portfolio/webportfolio/3.12/lib/python3.12/site-packages/django/views/debug.py", line 102, in get_caller
    resolver_match = resolve(request.path)
                     ^^^^^^^^^^^^^^^^^^^^^
  File "/home3/sambegkhatiwada/virtualenv/Django-portfolio/webportfolio/3.12/lib/python3.12/site-packages/django/urls/base.py", line 25, in resolve
    return get_resolver(urlconf).resolve(path)
           ^^^^^^^^^^^^^^^^^^^^^^^^^^^^^^^^^^^
  File "/home3/sambegkhatiwada/virtualenv/Django-portfolio/webportfolio/3.12/lib/python3.12/site-packages/django/urls/resolvers.py", line 666, in resolve
    for pattern in self.url_patterns:
                   ^^^^^^^^^^^^^^^^^
  File "/home3/sambegkhatiwada/virtualenv/Django-portfolio/webportfolio/3.12/lib/python3.12/site-packages/django/utils/functional.py", line 47, in __get__
    res = instance.__dict__[self.name] = self.func(instance)
                                         ^^^^^^^^^^^^^^^^^^^
  File "/home3/sambegkhatiwada/virtualenv/Django-portfolio/webportfolio/3.12/lib/python3.12/site-packages/django/urls/resolvers.py", line 718, in url_patterns
    patterns = getattr(self.urlconf_module, "urlpatterns", self.urlconf_module)
                       ^^^^^^^^^^^^^^^^^^^
  File "/home3/sambegkhatiwada/virtualenv/Django-portfolio/webportfolio/3.12/lib/python3.12/site-packages/django/utils/functional.py", line 47, in __get__
    res = instance.__dict__[self.name] = self.func(instance)
                                         ^^^^^^^^^^^^^^^^^^^
  File "/home3/sambegkhatiwada/virtualenv/Django-portfolio/webportfolio/3.12/lib/python3.12/site-packages/django/urls/resolvers.py", line 711, in urlconf_module
    return import_module(self.urlconf_name)
           ^^^^^^^^^^^^^^^^^^^^^^^^^^^^^^^^
  File "/opt/alt/python312/lib64/python3.12/importlib/__init__.py", line 90, in import_module
    return _bootstrap._gcd_import(name[level:], package, level)
           ^^^^^^^^^^^^^^^^^^^^^^^^^^^^^^^^^^^^^^^^^^^^^^^^^^^^
  File "<frozen importlib._bootstrap>", line 1387, in _gcd_import
  File "<frozen importlib._bootstrap>", line 1360, in _find_and_load
  File "<frozen importlib._bootstrap>", line 1331, in _find_and_load_unlocked
  File "<frozen importlib._bootstrap>", line 935, in _load_unlocked
  File "<frozen importlib._bootstrap_external>", line 999, in exec_module
  File "<frozen importlib._bootstrap>", line 488, in _call_with_frames_removed
  File "/home3/sambegkhatiwada/Django-portfolio/webportfolio/webportfolio/urls.py", line 5, in <module>
    urlpatterns += static(settings.MEDIA_URL, document_root=settings.MEDIA_ROOT)
    ^^^^^^^^^^^
NameError: name 'urlpatterns' is not defined

During handling of the above exception, another exception occurred:

Traceback (most recent call last):
  File "/home3/sambegkhatiwada/virtualenv/Django-portfolio/webportfolio/3.12/lib/python3.12/site-packages/django/core/handlers/exception.py", line 55, in inner
    response = get_response(request)
               ^^^^^^^^^^^^^^^^^^^^^
  File "/home3/sambegkhatiwada/virtualenv/Django-portfolio/webportfolio/3.12/lib/python3.12/site-packages/django/utils/deprecation.py", line 120, in __call__
    response = response or self.get_response(request)
                           ^^^^^^^^^^^^^^^^^^^^^^^^^^
  File "/home3/sambegkhatiwada/virtualenv/Django-portfolio/webportfolio/3.12/lib/python3.12/site-packages/django/core/handlers/exception.py", line 57, in inner
    response = response_for_exception(request, exc)
               ^^^^^^^^^^^^^^^^^^^^^^^^^^^^^^^^^^^^
  File "/home3/sambegkhatiwada/virtualenv/Django-portfolio/webportfolio/3.12/lib/python3.12/site-packages/django/core/handlers/exception.py", line 140, in response_for_exception
    response = handle_uncaught_exception(
               ^^^^^^^^^^^^^^^^^^^^^^^^^^
  File "/home3/sambegkhatiwada/virtualenv/Django-portfolio/webportfolio/3.12/lib/python3.12/site-packages/django/core/handlers/exception.py", line 181, in handle_uncaught_exception
    return debug.technical_500_response(request, *exc_info)
           ^^^^^^^^^^^^^^^^^^^^^^^^^^^^^^^^^^^^^^^^^^^^^^^^
  File "/home3/sambegkhatiwada/virtualenv/Django-portfolio/webportfolio/3.12/lib/python3.12/site-packages/django/views/debug.py", line 69, in technical_500_response
    html = reporter.get_traceback_html()
           ^^^^^^^^^^^^^^^^^^^^^^^^^^^^^
  File "/home3/sambegkhatiwada/virtualenv/Django-portfolio/webportfolio/3.12/lib/python3.12/site-packages/django/views/debug.py", line 428, in get_traceback_html
    c = Context(self.get_traceback_data(), use_l10n=False)
                ^^^^^^^^^^^^^^^^^^^^^^^^^
  File "/home3/sambegkhatiwada/virtualenv/Django-portfolio/webportfolio/3.12/lib/python3.12/site-packages/django/views/debug.py", line 411, in get_traceback_data
    c["raising_view_name"] = get_caller(self.request)
                             ^^^^^^^^^^^^^^^^^^^^^^^^
  File "/home3/sambegkhatiwada/virtualenv/Django-portfolio/webportfolio/3.12/lib/python3.12/site-packages/django/views/debug.py", line 102, in get_caller
    resolver_match = resolve(request.path)
                     ^^^^^^^^^^^^^^^^^^^^^
  File "/home3/sambegkhatiwada/virtualenv/Django-portfolio/webportfolio/3.12/lib/python3.12/site-packages/django/urls/base.py", line 25, in resolve
    return get_resolver(urlconf).resolve(path)
           ^^^^^^^^^^^^^^^^^^^^^^^^^^^^^^^^^^^
  File "/home3/sambegkhatiwada/virtualenv/Django-portfolio/webportfolio/3.12/lib/python3.12/site-packages/django/urls/resolvers.py", line 666, in resolve
    for pattern in self.url_patterns:
                   ^^^^^^^^^^^^^^^^^
  File "/home3/sambegkhatiwada/virtualenv/Django-portfolio/webportfolio/3.12/lib/python3.12/site-packages/django/utils/functional.py", line 47, in __get__
    res = instance.__dict__[self.name] = self.func(instance)
                                         ^^^^^^^^^^^^^^^^^^^
  File "/home3/sambegkhatiwada/virtualenv/Django-portfolio/webportfolio/3.12/lib/python3.12/site-packages/django/urls/resolvers.py", line 718, in url_patterns
    patterns = getattr(self.urlconf_module, "urlpatterns", self.urlconf_module)
                       ^^^^^^^^^^^^^^^^^^^
  File "/home3/sambegkhatiwada/virtualenv/Django-portfolio/webportfolio/3.12/lib/python3.12/site-packages/django/utils/functional.py", line 47, in __get__
    res = instance.__dict__[self.name] = self.func(instance)
                                         ^^^^^^^^^^^^^^^^^^^
  File "/home3/sambegkhatiwada/virtualenv/Django-portfolio/webportfolio/3.12/lib/python3.12/site-packages/django/urls/resolvers.py", line 711, in urlconf_module
    return import_module(self.urlconf_name)
           ^^^^^^^^^^^^^^^^^^^^^^^^^^^^^^^^
  File "/opt/alt/python312/lib64/python3.12/importlib/__init__.py", line 90, in import_module
    return _bootstrap._gcd_import(name[level:], package, level)
           ^^^^^^^^^^^^^^^^^^^^^^^^^^^^^^^^^^^^^^^^^^^^^^^^^^^^
  File "<frozen importlib._bootstrap>", line 1387, in _gcd_import
  File "<frozen importlib._bootstrap>", line 1360, in _find_and_load
  File "<frozen importlib._bootstrap>", line 1331, in _find_and_load_unlocked
  File "<frozen importlib._bootstrap>", line 935, in _load_unlocked
  File "<frozen importlib._bootstrap_external>", line 999, in exec_module
  File "<frozen importlib._bootstrap>", line 488, in _call_with_frames_removed
  File "/home3/sambegkhatiwada/Django-portfolio/webportfolio/webportfolio/urls.py", line 5, in <module>
    urlpatterns += static(settings.MEDIA_URL, document_root=settings.MEDIA_ROOT)
    ^^^^^^^^^^^
NameError: name 'urlpatterns' is not defined

During handling of the above exception, another exception occurred:

Traceback (most recent call last):
  File "/home3/sambegkhatiwada/virtualenv/Django-portfolio/webportfolio/3.12/lib/python3.12/site-packages/django/core/handlers/exception.py", line 55, in inner
    response = get_response(request)
               ^^^^^^^^^^^^^^^^^^^^^
  File "/home3/sambegkhatiwada/virtualenv/Django-portfolio/webportfolio/3.12/lib/python3.12/site-packages/django/utils/deprecation.py", line 120, in __call__
    response = response or self.get_response(request)
                           ^^^^^^^^^^^^^^^^^^^^^^^^^^
  File "/home3/sambegkhatiwada/virtualenv/Django-portfolio/webportfolio/3.12/lib/python3.12/site-packages/django/core/handlers/exception.py", line 57, in inner
    response = response_for_exception(request, exc)
               ^^^^^^^^^^^^^^^^^^^^^^^^^^^^^^^^^^^^
  File "/home3/sambegkhatiwada/virtualenv/Django-portfolio/webportfolio/3.12/lib/python3.12/site-packages/django/core/handlers/exception.py", line 140, in response_for_exception
    response = handle_uncaught_exception(
               ^^^^^^^^^^^^^^^^^^^^^^^^^^
  File "/home3/sambegkhatiwada/virtualenv/Django-portfolio/webportfolio/3.12/lib/python3.12/site-packages/django/core/handlers/exception.py", line 181, in handle_uncaught_exception
    return debug.technical_500_response(request, *exc_info)
           ^^^^^^^^^^^^^^^^^^^^^^^^^^^^^^^^^^^^^^^^^^^^^^^^
  File "/home3/sambegkhatiwada/virtualenv/Django-portfolio/webportfolio/3.12/lib/python3.12/site-packages/django/views/debug.py", line 69, in technical_500_response
    html = reporter.get_traceback_html()
           ^^^^^^^^^^^^^^^^^^^^^^^^^^^^^
  File "/home3/sambegkhatiwada/virtualenv/Django-portfolio/webportfolio/3.12/lib/python3.12/site-packages/django/views/debug.py", line 428, in get_traceback_html
    c = Context(self.get_traceback_data(), use_l10n=False)
                ^^^^^^^^^^^^^^^^^^^^^^^^^
  File "/home3/sambegkhatiwada/virtualenv/Django-portfolio/webportfolio/3.12/lib/python3.12/site-packages/django/views/debug.py", line 411, in get_traceback_data
    c["raising_view_name"] = get_caller(self.request)
                             ^^^^^^^^^^^^^^^^^^^^^^^^
  File "/home3/sambegkhatiwada/virtualenv/Django-portfolio/webportfolio/3.12/lib/python3.12/site-packages/django/views/debug.py", line 102, in get_caller
    resolver_match = resolve(request.path)
                     ^^^^^^^^^^^^^^^^^^^^^
  File "/home3/sambegkhatiwada/virtualenv/Django-portfolio/webportfolio/3.12/lib/python3.12/site-packages/django/urls/base.py", line 25, in resolve
    return get_resolver(urlconf).resolve(path)
           ^^^^^^^^^^^^^^^^^^^^^^^^^^^^^^^^^^^
  File "/home3/sambegkhatiwada/virtualenv/Django-portfolio/webportfolio/3.12/lib/python3.12/site-packages/django/urls/resolvers.py", line 666, in resolve
    for pattern in self.url_patterns:
                   ^^^^^^^^^^^^^^^^^
  File "/home3/sambegkhatiwada/virtualenv/Django-portfolio/webportfolio/3.12/lib/python3.12/site-packages/django/utils/functional.py", line 47, in __get__
    res = instance.__dict__[self.name] = self.func(instance)
                                         ^^^^^^^^^^^^^^^^^^^
  File "/home3/sambegkhatiwada/virtualenv/Django-portfolio/webportfolio/3.12/lib/python3.12/site-packages/django/urls/resolvers.py", line 718, in url_patterns
    patterns = getattr(self.urlconf_module, "urlpatterns", self.urlconf_module)
                       ^^^^^^^^^^^^^^^^^^^
  File "/home3/sambegkhatiwada/virtualenv/Django-portfolio/webportfolio/3.12/lib/python3.12/site-packages/django/utils/functional.py", line 47, in __get__
    res = instance.__dict__[self.name] = self.func(instance)
                                         ^^^^^^^^^^^^^^^^^^^
  File "/home3/sambegkhatiwada/virtualenv/Django-portfolio/webportfolio/3.12/lib/python3.12/site-packages/django/urls/resolvers.py", line 711, in urlconf_module
    return import_module(self.urlconf_name)
           ^^^^^^^^^^^^^^^^^^^^^^^^^^^^^^^^
  File "/opt/alt/python312/lib64/python3.12/importlib/__init__.py", line 90, in import_module
    return _bootstrap._gcd_import(name[level:], package, level)
           ^^^^^^^^^^^^^^^^^^^^^^^^^^^^^^^^^^^^^^^^^^^^^^^^^^^^
  File "<frozen importlib._bootstrap>", line 1387, in _gcd_import
  File "<frozen importlib._bootstrap>", line 1360, in _find_and_load
  File "<frozen importlib._bootstrap>", line 1331, in _find_and_load_unlocked
  File "<frozen importlib._bootstrap>", line 935, in _load_unlocked
  File "<frozen importlib._bootstrap_external>", line 999, in exec_module
  File "<frozen importlib._bootstrap>", line 488, in _call_with_frames_removed
  File "/home3/sambegkhatiwada/Django-portfolio/webportfolio/webportfolio/urls.py", line 5, in <module>
    urlpatterns += static(settings.MEDIA_URL, document_root=settings.MEDIA_ROOT)
    ^^^^^^^^^^^
NameError: name 'urlpatterns' is not defined

During handling of the above exception, another exception occurred:

Traceback (most recent call last):
  File "/home3/sambegkhatiwada/virtualenv/Django-portfolio/webportfolio/3.12/lib/python3.12/site-packages/django/core/handlers/wsgi.py", line 124, in __call__
    response = self.get_response(request)
               ^^^^^^^^^^^^^^^^^^^^^^^^^^
  File "/home3/sambegkhatiwada/virtualenv/Django-portfolio/webportfolio/3.12/lib/python3.12/site-packages/django/core/handlers/base.py", line 140, in get_response
    response = self._middleware_chain(request)
               ^^^^^^^^^^^^^^^^^^^^^^^^^^^^^^^
  File "/home3/sambegkhatiwada/virtualenv/Django-portfolio/webportfolio/3.12/lib/python3.12/site-packages/django/core/handlers/exception.py", line 57, in inner
    response = response_for_exception(request, exc)
               ^^^^^^^^^^^^^^^^^^^^^^^^^^^^^^^^^^^^
  File "/home3/sambegkhatiwada/virtualenv/Django-portfolio/webportfolio/3.12/lib/python3.12/site-packages/django/core/handlers/exception.py", line 140, in response_for_exception
    response = handle_uncaught_exception(
               ^^^^^^^^^^^^^^^^^^^^^^^^^^
  File "/home3/sambegkhatiwada/virtualenv/Django-portfolio/webportfolio/3.12/lib/python3.12/site-packages/django/core/handlers/exception.py", line 181, in handle_uncaught_exception
    return debug.technical_500_response(request, *exc_info)
           ^^^^^^^^^^^^^^^^^^^^^^^^^^^^^^^^^^^^^^^^^^^^^^^^
  File "/home3/sambegkhatiwada/virtualenv/Django-portfolio/webportfolio/3.12/lib/python3.12/site-packages/django/views/debug.py", line 69, in technical_500_response
    html = reporter.get_traceback_html()
           ^^^^^^^^^^^^^^^^^^^^^^^^^^^^^
  File "/home3/sambegkhatiwada/virtualenv/Django-portfolio/webportfolio/3.12/lib/python3.12/site-packages/django/views/debug.py", line 428, in get_traceback_html
    c = Context(self.get_traceback_data(), use_l10n=False)
                ^^^^^^^^^^^^^^^^^^^^^^^^^
  File "/home3/sambegkhatiwada/virtualenv/Django-portfolio/webportfolio/3.12/lib/python3.12/site-packages/django/views/debug.py", line 411, in get_traceback_data
    c["raising_view_name"] = get_caller(self.request)
                             ^^^^^^^^^^^^^^^^^^^^^^^^
  File "/home3/sambegkhatiwada/virtualenv/Django-portfolio/webportfolio/3.12/lib/python3.12/site-packages/django/views/debug.py", line 102, in get_caller
    resolver_match = resolve(request.path)
                     ^^^^^^^^^^^^^^^^^^^^^
  File "/home3/sambegkhatiwada/virtualenv/Django-portfolio/webportfolio/3.12/lib/python3.12/site-packages/django/urls/base.py", line 25, in resolve
    return get_resolver(urlconf).resolve(path)
           ^^^^^^^^^^^^^^^^^^^^^^^^^^^^^^^^^^^
  File "/home3/sambegkhatiwada/virtualenv/Django-portfolio/webportfolio/3.12/lib/python3.12/site-packages/django/urls/resolvers.py", line 666, in resolve
    for pattern in self.url_patterns:
                   ^^^^^^^^^^^^^^^^^
  File "/home3/sambegkhatiwada/virtualenv/Django-portfolio/webportfolio/3.12/lib/python3.12/site-packages/django/utils/functional.py", line 47, in __get__
    res = instance.__dict__[self.name] = self.func(instance)
                                         ^^^^^^^^^^^^^^^^^^^
  File "/home3/sambegkhatiwada/virtualenv/Django-portfolio/webportfolio/3.12/lib/python3.12/site-packages/django/urls/resolvers.py", line 718, in url_patterns
    patterns = getattr(self.urlconf_module, "urlpatterns", self.urlconf_module)
                       ^^^^^^^^^^^^^^^^^^^
  File "/home3/sambegkhatiwada/virtualenv/Django-portfolio/webportfolio/3.12/lib/python3.12/site-packages/django/utils/functional.py", line 47, in __get__
    res = instance.__dict__[self.name] = self.func(instance)
                                         ^^^^^^^^^^^^^^^^^^^
  File "/home3/sambegkhatiwada/virtualenv/Django-portfolio/webportfolio/3.12/lib/python3.12/site-packages/django/urls/resolvers.py", line 711, in urlconf_module
    return import_module(self.urlconf_name)
           ^^^^^^^^^^^^^^^^^^^^^^^^^^^^^^^^
  File "/opt/alt/python312/lib64/python3.12/importlib/__init__.py", line 90, in import_module
    return _bootstrap._gcd_import(name[level:], package, level)
           ^^^^^^^^^^^^^^^^^^^^^^^^^^^^^^^^^^^^^^^^^^^^^^^^^^^^
  File "<frozen importlib._bootstrap>", line 1387, in _gcd_import
  File "<frozen importlib._bootstrap>", line 1360, in _find_and_load
  File "<frozen importlib._bootstrap>", line 1331, in _find_and_load_unlocked
  File "<frozen importlib._bootstrap>", line 935, in _load_unlocked
  File "<frozen importlib._bootstrap_external>", line 999, in exec_module
  File "<frozen importlib._bootstrap>", line 488, in _call_with_frames_removed
  File "/home3/sambegkhatiwada/Django-portfolio/webportfolio/webportfolio/urls.py", line 5, in <module>
    urlpatterns += static(settings.MEDIA_URL, document_root=settings.MEDIA_ROOT)
    ^^^^^^^^^^^
NameError: name 'urlpatterns' is not defined
Not Found: /favicon.ico
Not Found: /favicon.ico
Not Found: /favicon.ico
Not Found: /favicon.ico
Not Found: /wp-includes/ID3/license.txt
Not Found: /feed/
Not Found: /xmlrpc.php
Not Found: /blog/wp-includes/wlwmanifest.xml
Not Found: /web/wp-includes/wlwmanifest.xml
Not Found: /wordpress/wp-includes/wlwmanifest.xml
Not Found: /wp/wp-includes/wlwmanifest.xml
Not Found: /2020/wp-includes/wlwmanifest.xml
Not Found: /2019/wp-includes/wlwmanifest.xml
Not Found: /2021/wp-includes/wlwmanifest.xml
Not Found: /shop/wp-includes/wlwmanifest.xml
Not Found: /wp1/wp-includes/wlwmanifest.xml
Not Found: /test/wp-includes/wlwmanifest.xml
Not Found: /site/wp-includes/wlwmanifest.xml
Not Found: /cms/wp-includes/wlwmanifest.xml
Not Found: /wp-json/wp/v2/posts
Not Found: /robots.txt
Not Found: /js/lkk_ch.js
Not Found: /js/twint_ch.js
Not Found: /.env
Not Found: /.aws/credentials
Not Found: /.env.backup
Not Found: /.env.old
Not Found: /favicon.ico
Not Found: /favicon.ico
Not Found: /favicon.ico
Not Found: /old.zip
Not Found: /wp.zip
Not Found: /wp-includes/wlwmanifest.xml
Not Found: /xmlrpc.php
Not Found: /blog/wp-includes/wlwmanifest.xml
Not Found: /web/wp-includes/wlwmanifest.xml
Not Found: /wordpress/wp-includes/wlwmanifest.xml
Not Found: /website/wp-includes/wlwmanifest.xml
Not Found: /wp/wp-includes/wlwmanifest.xml
Not Found: /news/wp-includes/wlwmanifest.xml
Not Found: /2018/wp-includes/wlwmanifest.xml
Not Found: /2019/wp-includes/wlwmanifest.xml
Not Found: /shop/wp-includes/wlwmanifest.xml
Not Found: /wp1/wp-includes/wlwmanifest.xml
Not Found: /test/wp-includes/wlwmanifest.xml
Not Found: /media/wp-includes/wlwmanifest.xml
Not Found: /wp2/wp-includes/wlwmanifest.xml
Not Found: /site/wp-includes/wlwmanifest.xml
Not Found: /cms/wp-includes/wlwmanifest.xml
Not Found: /sito/wp-includes/wlwmanifest.xml
Not Found: /robots.txt
Not Found: /robots.txt
Not Found: /favicon.ico
Not Found: /favicon.ico
Not Found: /robots.txt
Not Found: /favicon.ico
Not Found: /favicon.ico
Not Found: /robots.txt
Not Found: /cgi-bin/
Not Found: /favicon.ico
Not Found: /robots.txt
Not Found: /config.json
Not Found: /sitemap.xml
Not Found: /config.json
Not Found: /favicon.ico
Not Found: /favicon.ico
Not Found: /favicon.ico
Not Found: /favicon.ico
[UID:1370][1757522] Reached max children process limit: 6, extra: 2, current: 8, busy: 7, please increase LSAPI_CHILDREN.
[UID:1370][1757522] Reached max children process limit: 6, extra: 2, current: 8, busy: 8, please increase LSAPI_CHILDREN.
[UID:1370][1757522] Reached max children process limit: 6, extra: 2, current: 8, busy: 8, please increase LSAPI_CHILDREN.
[UID:1370][1757522] Reached max children process limit: 6, extra: 2, current: 8, busy: 7, please increase LSAPI_CHILDREN.
[UID:1370][1757522] Reached max children process limit: 6, extra: 2, current: 8, busy: 8, please increase LSAPI_CHILDREN.
[UID:1370][1757522] Reached max children process limit: 6, extra: 2, current: 8, busy: 8, please increase LSAPI_CHILDREN.
[UID:1370][1757522] Reached max children process limit: 6, extra: 2, current: 8, busy: 8, please increase LSAPI_CHILDREN.
[UID:1370][1757522] Reached max children process limit: 6, extra: 2, current: 8, busy: 7, please increase LSAPI_CHILDREN.
[UID:1370][1757522] Reached max children process limit: 6, extra: 2, current: 8, busy: 7, please increase LSAPI_CHILDREN.
[UID:1370][1757522] Reached max children process limit: 6, extra: 2, current: 8, busy: 8, please increase LSAPI_CHILDREN.
[UID:1370][1757522] Reached max children process limit: 6, extra: 2, current: 8, busy: 8, please increase LSAPI_CHILDREN.
[UID:1370][1757522] Reached max children process limit: 6, extra: 2, current: 8, busy: 8, please increase LSAPI_CHILDREN.
[UID:1370][1757522] Reached max children process limit: 6, extra: 2, current: 8, busy: 8, please increase LSAPI_CHILDREN.
[UID:1370][1757522] Reached max children process limit: 6, extra: 2, current: 8, busy: 8, please increase LSAPI_CHILDREN.
Not Found: /favicon.ico
Not Found: /favicon.ico
Not Found: /favicon.ico
Not Found: /favicon.ico
Not Found: /favicon.ico
Not Found: /favicon.ico
Not Found: /favicon.ico
Not Found: /favicon.ico
Not Found: /favicon.ico
Not Found: /favicon.ico
Not Found: /favicon.ico
Not Found: /favicon.ico
Not Found: /favicon.ico
Not Found: /favicon.ico
Not Found: /favicon.ico
Not Found: /favicon.ico
Not Found: /favicon.ico
Not Found: /favicon.ico
Not Found: /favicon.ico
Not Found: /xmlrpc.php
Not Found: /favicon.ico
Not Found: /favicon.ico
Not Found: /favicon.ico
Not Found: /favicon.ico
Not Found: /favicon.ico
Not Found: /favicon.ico
Not Found: /favicon.ico
Not Found: /favicon.ico
Not Found: /favicon.ico
Not Found: /favicon.ico
Not Found: /favicon.ico
Not Found: /favicon.ico
Not Found: /favicon.ico
